Workbook
Name Construction_End_Date: Inputs!$E$19
Name Construction_Start_Date: Inputs!$E$18
Name Model_Start: Inputs!$E$7
Name Model_start: Inputs!$E$9
Name Operations_Start_Date: Inputs!$E$22
Name RM_BaseEventDays: Inputs!$E$302
Name RM_EventDaysScale: Inputs!$E$499
Name RM_ExitMultiple: Inputs!$E$483
Name RM_HourlyRate: Inputs!$E$397
Name RM_IO_Months: Inputs!$E$69
Name RM_OutgoingsPct: Inputs!$E$36
Name RM_ShiftHours: Inputs!$E$398
Name RM_StaffPerEvent: Inputs!$E$396
Name RM_SustCapexPct: Inputs!$E$462
Name RM_TerminalGrowth: Inputs!$E$487
Name RM_VHA_Cap: Inputs!$E$309
Name RM_VHA_GBO_Fee: Inputs!$E$308
Name Total_Initial_Capex: 'Construction Timeline'!$E$18

Sheet Readme
B1: THE BEND LIVE HOUSE — MODEL README
B2: Financial Model V4:Tab Index & Descriptions
A4: No. | B4: Tab Name | C4: Description
A5: 1 | B5: General Information | C5: Project overview describing the integrated entertainment precinct at 349 Bridge Street Melbourne — Live House music venue, URWLD active leisure, parking, Central Park, and employment impact.
A6: =A5+1 -> 2 | B6: Dynamic Dashboard | C6: Interactive investor dashboard showing KPIs (Project IRR, Equity IRR, MOIC, Enterprise Value, Equity Value, Payback Period), revenue/EBITDA charts, and financial summary linked to the active scenario.
A7: =A6+1 -> 3 | B7: Inputs for Dashboard | C7: Inputs for preparation of Dynamic Dashboards that are linked to the rest of the model
A8: =A7+1 -> 4 | B8: Dashboard | C8: Executive dashboard with annual summary (Revenue, EBITDA, Closing Cash, Total Debt) across FY25–FY36, model health status, and active scenario indicator.
A9: =A8+1 -> 5 | B9: Valuations | C9: Valuation architecture sheet with DCF and return metrics (IRR, NPV), WACC/Ke inputs, sensitivity framework, and terminal value calculations.
A10: =A9+1 -> 6 | B10: Scenarios | C10: Scenario manager with Base, Optimistic, Pessimistic, and Delayed Opening scenarios. Defines multipliers for revenue, costs, capex, inflation, interest rate deltas, and event days.
A11: =A10+1 -> 7 | B11: Inputs | C11: Master global inputs sheet (v35). Contains project timing, construction parameters, financing terms, WACC/Ke assumptions, escalation rates, and all key model drivers with source references.
A12: =A11+1 -> 8 | B12: Construction Timeline | C12: Initial capex breakdown (Consultants, Structure, Civil, ICT, FF&E) and construction phasing schedule across the build period.
A13: =A12+1 -> 9 | B13: PL_BS_CFS Summary | C13: A summarised view of the P&L, Balance Sheet and Cash Flow in one single tab, linked to respective tabs of P&L, BS and CashFlow.
A14: =A13+1 -> 10 | B14: P&L | C14: Profit & Loss statement (FY25–FY36) with operations and construction flags, revenue, operating expenses, EBITDA, depreciation, interest, and net income.
A15: =A14+1 -> 11 | B15: Balance Sheet | C15: Annual balance sheet (FY25–FY36) with Assets (Cash, Receivables, PP&E), Liabilities (Debt, Payables), and Equity sections.
A16: =A15+1 -> 12 | B16: Cashflow | C16: Annual cashflow waterfall (AUD) showing operating, investing, and financing cash flows with opening/closing cash balances across FY25–FY36.
A17: =A16+1 -> 13 | B17: Debt | C17: Debt schedule for Term Debt ($10.2M, 8%, 10yr amortising) and PE Loan facility. Tracks drawdowns, repayments, interest, and closing balances.
... A28: =A27+1 -> 24 | B28: Model Checks | C28: Automated integrity checks - BS balance (A–L–E), cash tie-out (BS vs CFS), PPE tie, debt continuity, sources ≥ uses, revenue tie, and DSCR covenant with PASS/FAIL status.

Sheet KEY OUTPUT >>

Sheet General Information
A1: Integrated Entertainment and Recreational Development
A2: 349 Bridge Street Melbourne
A3: Live House Music Venue - There is a need for a 4,000 to 5,000 live venue for the Melbourne market that is suitably located to avoid issues of noise and congestion for the local community. The location within our proposed precinct will provide a beneficial location for this development and allow for the improved development of access to culture, music, entertainment and activity.
A5: "URWLD" - is an active leisure concept that will house a Sports Climbing Centre of Excellence as well as a range of 15-18 active leisure activities including surfing, scuba, ice climbing, sports climbing, bouldering, canyoning, coasteering, ninja, junior climb academy, and a range of VR activities such as skiing, snowboarding, squirrel suit, tennis, golf and other immersive game concepts. There will also be an eSports arena and concept area and interactive video games concepts. These will be supported by 4 quality, chef curated F&B concepts and 2 event venues. URWLD addresses a key community and society issue of encouraging the entire populace to be active to support lifestyle mindset change and impact the alarming trend of obesity, diabetes and inactivity that threatens our future generations. By providing an accessible environment to help introduce a broad range of activities that encourage movement we will work to address this through our communications and positioning as well as with our event activities, TedTalks hosted and others to promote improving mobility for all age groups
A7: PARKING - we are in discussions with Wilson Parking to JV on a 900 space parking building connected to URWLD to service the precinct as well as to support the government policy on congestion reduction within the CBD. We will provide business day parking with shuttle service into the CBD area to Spencer St transport hub for trains, trams and buses. In the future when the Plummer St Light Rail/Tram is undertaken by state government the proximity will allow us to reduce shuttle services. The parking building will connect to both the live venue and URWLD buildings
A11: Central Park - in keeping with the need for green space and open areas for common use we have allocated space within the site for a central park which we plan to develop with native landscape focus and a central courtyard as a "FOOD TRUCK" park highlighting handheld foods from numerous cultures as part of our F&B offering. This area will also be used for day time and evening buskers for entertainment.
A13: Employment and Community - We believe that Fisherman's Bend precinct's combined development will create almost 1,000 FTE jobs and support the planned redevelopment of the Fishermans Bend Urban Renewal Framework by encouraging further state and federal investment in infrastructure of light rail, metro and roads as well as private investor development of the larger sites for increased residential and commercial use of the area.
A15: The zone we are developing is on a site of 37k square metres

Sheet Dynamic Dashboard
B2: THE BEND LIVE HOUSE
B3: Investor Dashboard | M3: Active Scenario: | N3: ='Inputs for Dashboard'!C9 -> Base
B5: SECTION 1 — KEY PERFORMANCE INDICATORS
B7: PROJECT IRR (UNLEVERED) | D7: EQUITY IRR (LEVERED) | F7: EQUITY MOIC | H7: ENTERPRISE VALUE (DCF) | J7: EQUITY VALUE | L7: PAYBACK PERIOD
B8: ='Inputs for Dashboard'!C18 -> 0.24794587 | D8: ='Inputs for Dashboard'!C20 -> 0.33284791 | F8: ='Inputs for Dashboard'!C22 -> 17.693182 | H8: ='Inputs for Dashboard'!C19 -> 62301607 | J8: ='Inputs for Dashboard'!C21 -> 50077920 | L8: ='Inputs for Dashboard'!C23 -> FY30
B10: Return on total capital | D10: Return to equity investors | F10: Multiple on invested capital | H10: NPV @ WACC | J10: EV less net debt | L10: Equity breakeven year
B12: AVG DSCR | D12: YIELD ON COST | F12: WACC | H12: EXIT MULTIPLE | J12: TOTAL CAPEX | L12: DEBT / TOTAL CAP
B13: =AVERAGEIF('Inputs for Dashboard'!F61:N61,">0") -> 4.0738366 | D13: ='Inputs for Dashboard'!C24 -> 0.70345496 | F13: ='Inputs for Dashboard'!C10 -> 0.1 | H13: ='Inputs for Dashboard'!C12 -> 7 | J13: ='Inputs for Dashboard'!C28 -> 19761525 | L13: ='Inputs for Dashboard'!C33 -> 0.58559274
B16: SECTION 2 — REVENUE & PROFITABILITY TREND
B17: FY (operations start FY28)
B30: SECTION 3 — DEBT REPAYMENT & COVERAGE
B31: Bank term debt amortises over 10 years at 8% — fully repaid by FY36
B44: SECTION 4 — CASH FLOWS & SHAREHOLDER RETURNS
B45: Unlevered vs Equity cash flows; dividends track stabilised operations
B58: SECTION 5 — CAPITAL STRUCTURE & EQUITY BUILD
B59: Funding sources and book equity growth trajectory
B72: SECTION 6 — SENSITIVITY ANALYSIS
B73: Stress test Enterprise Value and Equity IRR under changing WACC, exit multiple and EBITDA assumptions
B75: Enterprise Value ($) — WACC vs Exit Multiple | I75: Equity IRR — EBITDA Δ vs Exit Multiple
B76: WACC ↓ / Mult → | C76: 6.0x | D76: 7.0x | E76: 8.0x | F76: 9.0x | G76: 10.0x | I76: EBITDA Δ ↓ / Mult → | J76: 6.0x | K76: 7.0x | L76: 8.0x | M76: 9.0x | N76: 10.0x
B77: 0.08 | C77: ='Inputs for Dashboard'!C80 -> 63401162 | D77: ='Inputs for Dashboard'!D80 -> 70048481 | E77: ='Inputs for Dashboard'!E80 -> 76695801 | F77: ='Inputs for Dashboard'!F80 -> 83343120 | G77: ='Inputs for Dashboard'!G80 -> 89990440 | I77: -0.2 | J77: ='Inputs for Dashboard'!C88 -> 0.23284824 | K77: ='Inputs for Dashboard'!D88 -> 0.25283307 | L77: ='Inputs for Dashboard'!E88 -> 0.27040638 | M77: ='Inputs for Dashboard'!F88 -> 0.28611164 | N77: ='Inputs for Dashboard'!G88 -> 0.30032492
B78: 0.09 | C78: ='Inputs for Dashboard'!C81 -> 60028461 | D78: ='Inputs for Dashboard'!D81 -> 66113664 | E78: ='Inputs for Dashboard'!E81 -> 72198867 | F78: ='Inputs for Dashboard'!F81 -> 78284070 | G78: ='Inputs for Dashboard'!G81 -> 84369273 | I78: -0.1 | J78: ='Inputs for Dashboard'!C89 -> 0.24808919 | K78: ='Inputs for Dashboard'!D89 -> 0.26832108 | L78: ='Inputs for Dashboard'!E89 -> 0.28611164 | M78: ='Inputs for Dashboard'!F89 -> 0.30201105 | N78: ='Inputs for Dashboard'!G89 -> 0.31640004
B79: 0.1 | C79: ='Inputs for Dashboard'!C82 -> 56967947 | D79: ='Inputs for Dashboard'!D82 -> 62543064 | E79: ='Inputs for Dashboard'!E82 -> 68118181 | F79: ='Inputs for Dashboard'!F82 -> 73693298 | G79: ='Inputs for Dashboard'!G82 -> 79268415 | I79: 0% (Base) | J79: ='Inputs for Dashboard'!C90 -> 0.26188226 | K79: ='Inputs for Dashboard'!D90 -> 0.28233774 | L79: ='Inputs for Dashboard'!E90 -> 0.30032492 | M79: ='Inputs for Dashboard'!F90 -> 0.31640004 | N79: ='Inputs for Dashboard'!G90 -> 0.33094805
B80: 0.11 | C80: ='Inputs for Dashboard'!C83 -> 54188268 | D80: ='Inputs for Dashboard'!D83 -> 59300105 | E80: ='Inputs for Dashboard'!E83 -> 64411942 | F80: ='Inputs for Dashboard'!F83 -> 69523779 | G80: ='Inputs for Dashboard'!G83 -> 74635616 | I80: 0.1 | J80: ='Inputs for Dashboard'!C91 -> 0.27449089 | K80: ='Inputs for Dashboard'!D91 -> 0.29515076 | L80: ='Inputs for Dashboard'!E91 -> 0.31331766 | M80: ='Inputs for Dashboard'!F91 -> 0.32955341 | N80: ='Inputs for Dashboard'!G91 -> 0.34424677
B81: 0.12 | C81: ='Inputs for Dashboard'!C84 -> 51661463 | D81: ='Inputs for Dashboard'!D84 -> 56352166 | E81: ='Inputs for Dashboard'!E84 -> 61042870 | F81: ='Inputs for Dashboard'!F84 -> 65733573 | G81: ='Inputs for Dashboard'!G84 -> 70424276 | I81: 0.2 | J81: ='Inputs for Dashboard'!C92 -> 0.28611164 | K81: ='Inputs for Dashboard'!D92 -> 0.30695989 | L81: ='Inputs for Dashboard'!E92 -> 0.32529243 | M81: ='Inputs for Dashboard'!F92 -> 0.34167621 | N81: ='Inputs for Dashboard'!G92 -> 0.35650356
B84: SECTION 7 — OPERATIONAL KPIS
B85: Event day utilisation and revenue intensity underpin the financial forecast
B87: STABILISED EVENT DAYS (FY30+) | E87: REVENUE / EVENT DAY (FY30+) | H87: REVENUE CAGR (FY28-FY36) | K87: FY28 → FY36 REVENUE GROWTH
B88: ='Inputs for Dashboard'!H151 -> 162.342 | E88: ='Inputs for Dashboard'!H152 -> 126988.22 | H88: =('Inputs for Dashboard'!N40/'Inputs for Dashboard'!F40)^(1/8)-1 -> 0.033412769 | K88: ='Inputs for Dashboard'!N40-'Inputs for Dashboard'!F40 -> 5645596.8
B102: SECTION 8 — USE OF PROCEEDS (CAPEX BREAKDOWN)
B103: Where the construction capex is deployed
B117: SECTION 9 — SCENARIO COMPARISON
B118: Impact of alternate assumptions on returns — active scenario set via Scenarios!B4
B120: Scenario | C120: Rev Impact | D120: Cost Impact | E120: IRR Δ (pp) | F120: Risk Level
B121: ='Inputs for Dashboard'!B174 -> Base | C121: ='Inputs for Dashboard'!C174 -> 0 | D121: ='Inputs for Dashboard'!D174 -> 0 | E121: ='Inputs for Dashboard'!E174 -> Baseline | F121: ='Inputs for Dashboard'!F174 -> ●●○○○
B122: ='Inputs for Dashboard'!B175 -> Optimistic | C122: ='Inputs for Dashboard'!C175 -> 0.1 | D122: ='Inputs for Dashboard'!D175 -> -0.05 | E122: ='Inputs for Dashboard'!E175 -> 2.95 | F122: ='Inputs for Dashboard'!F175 -> ●○○○○
B123: ='Inputs for Dashboard'!B176 -> Pessimistic | C123: ='Inputs for Dashboard'!C176 -> -0.15 | D123: ='Inputs for Dashboard'!D176 -> 0.1 | E123: ='Inputs for Dashboard'!E176 -> -5.08 | F123: ='Inputs for Dashboard'!F176 -> ●●●●○
B124: ='Inputs for Dashboard'!B177 -> Delayed +3m | C124: ='Inputs for Dashboard'!C177 -> 0 | D124: ='Inputs for Dashboard'!D177 -> 0 | E124: ='Inputs for Dashboard'!E177 -> -1.02 | F124: ='Inputs for Dashboard'!F177 -> ●●●○○
B125: ='Inputs for Dashboard'!B178 -> Delayed +6m | C125: ='Inputs for Dashboard'!C178 -> 0 | D125: ='Inputs for Dashboard'!D178 -> 0 | E125: ='Inputs for Dashboard'!E178 -> -2.04 | F125: ='Inputs for Dashboard'!F178 -> ●●●●○
B126: ='Inputs for Dashboard'!B179 -> Capex +10% | C126: ='Inputs for Dashboard'!C179 -> 0 | D126: ='Inputs for Dashboard'!D179 -> 0.1 | E126: ='Inputs for Dashboard'!E179 -> -2.03 | F126: ='Inputs for Dashboard'!F179 -> ●●●○○
...

Sheet Dashboard
A1: THE BEND LIVE HOUSE — EXECUTIVE DASHBOARD
P2: Active Scenario | Q2: =Scenarios!$B$4 -> Base
P3: Model Health | Q3: =IF(#REF!=0,"OK","FAIL") -> #REF!
B5: Summary
B6: FY | C6: =IFERROR(Cashflow!D$7,"") -> FY25 | D6: =IFERROR(Cashflow!E$7,"") -> FY26 | E6: =IFERROR(Cashflow!F$7,"") -> FY27 | F6: =IFERROR(Cashflow!G$7,"") -> FY28 | G6: =IFERROR(Cashflow!H$7,"") -> FY29 | H6: =IFERROR(Cashflow!I$7,"") -> FY30 | I6: =IFERROR(Cashflow!J$7,"") -> FY31 | J6: =IFERROR(Cashflow!K$7,"") -> FY32 | ... P6: =IFERROR(Cashflow!Q$7,"") -> FY38
B7: Revenue | C7: =IFERROR(Cashflow!D$48,"") -> 0 | D7: =IFERROR(Cashflow!E$48,"") -> 0 | E7: =IFERROR(Cashflow!F$48,"") -> 0 | F7: =IFERROR(Cashflow!G$48,"") -> 18772333 | G7: =IFERROR(Cashflow!H$48,"") -> 19676502 | H7: =IFERROR(Cashflow!I$48,"") -> 20615522 | I7: =IFERROR(Cashflow!J$48,"") -> 21808635 | J7: =IFERROR(Cashflow!K$48,"") -> 22300757 | ... P7: =IFERROR(Cashflow!Q$48,"") -> 25571992
B8: EBITDA | C8: =IFERROR(Cashflow!D$64,"") -> 0 | D8: =IFERROR(Cashflow!E$64,"") -> 0 | E8: =IFERROR(Cashflow!F$64,"") -> 0 | F8: =IFERROR(Cashflow!G$64,"") -> 10240353 | G8: =IFERROR(Cashflow!H$64,"") -> 10221611 | H8: =IFERROR(Cashflow!I$64,"") -> 10726643 | I8: =IFERROR(Cashflow!J$64,"") -> 11603174 | J8: =IFERROR(Cashflow!K$64,"") -> 11825139 | ... P8: =IFERROR(Cashflow!Q$64,"") -> 13901343
B9: Closing Cash | C9: =IFERROR(Cashflow!D38,"") -> 0 | D9: =IFERROR(Cashflow!E38,"") -> 0 | E9: =IFERROR(Cashflow!F38,"") -> 452228.4 | F9: =IFERROR(Cashflow!G38,"") -> 1724785.6 | G9: =IFERROR(Cashflow!H38,"") -> 2184190 | H9: =IFERROR(Cashflow!I38,"") -> 2729888 | I9: =IFERROR(Cashflow!J38,"") -> 3408439 | J9: =IFERROR(Cashflow!K38,"") -> 4135811.4 | ... P9: =IFERROR(Cashflow!Q38,"") -> 12278575
B10: Total Debt | C10: =IFERROR(Debt!H48,0) -> 0 | D10: =IFERROR(Debt!I48,0) -> 0 | E10: =IFERROR(Debt!J48,0) -> 12675915 | F10: =IFERROR(Debt!K48,0) -> 12675915 | G10: =IFERROR(Debt!L48,0) -> 11091426 | H10: =IFERROR(Debt!M48,0) -> 9506936.2 | I10: =IFERROR(Debt!N48,0) -> 7922446.9 | J10: =IFERROR(Debt!O48,0) -> 6337957.5 | ... P10: =IFERROR(Debt!U48,0) -> 0
B11: DSCR | C11: =Cashflow!D67 | D11: =Cashflow!E67 | E11: =Cashflow!F67 | F11: =Cashflow!G67 -> 3.748065 | G11: =Cashflow!H67 -> 3.0466904 | H11: =Cashflow!I67 -> 3.3189554 | I11: =Cashflow!J67 -> 3.7480419 | J11: =Cashflow!K67 -> 4.0469539 | ... P11: =Cashflow!Q67
B12: ICR | C12: =IFERROR(IF(Debt!H$57=0,"",Cashflow!D$64/Debt!H$57),"") | D12: =IFERROR(IF(Debt!I$57=0,"",Cashflow!E$64/Debt!I$57),"") | E12: =IFERROR(IF(Debt!J$57=0,"",Cashflow!F$64/Debt!J$57),"") -> 0 | F12: =IFERROR(IF(Debt!K$57=0,"",Cashflow!G$64/Debt!K$57),"") -> 10.098239 | G12: =IFERROR(IF(Debt!L$57=0,"",Cashflow!H$64/Debt!L$57),"") -> 10.75174 | H12: =IFERROR(IF(Debt!M$57=0,"",Cashflow!I$64/Debt!M$57),"") -> 13.018806 | I12: =IFERROR(IF(Debt!N$57=0,"",Cashflow!J$64/Debt!N$57),"") -> 16.643121 | J12: =IFERROR(IF(Debt!O$57=0,"",Cashflow!K$64/Debt!O$57),"") -> 20.730722 | ... P12: =IFERROR(IF(Debt!U$57=0,"",Cashflow!Q$64/Debt!U$57),"")
B13: Net Leverage (Net Debt/EBITDA) | C13: =IFERROR(IF(Cashflow!D$64=0,"",((Cashflow!D$72+Cashflow!D$73)-Cashflow!D$39)/Cashflow!D$64),"") | D13: =IFERROR(IF(Cashflow!E$64=0,"",((Cashflow!E$72+Cashflow!E$73)-Cashflow!E$39)/Cashflow!E$64),"") | E13: =IFERROR(IF(Cashflow!F$64=0,"",((Cashflow!F$72+Cashflow!F$73)-Cashflow!F$39)/Cashflow!F$64),"") | F13: =IFERROR(IF(Cashflow!G$64=0,"",((Cashflow!G$72+Cashflow!G$73)-Cashflow!G$39)/Cashflow!G$64),"") -> 1.2378396 | G13: =IFERROR(IF(Cashflow!H$64=0,"",((Cashflow!H$72+Cashflow!H$73)-Cashflow!H$39)/Cashflow!H$64),"") -> 1.0850957 | H13: =IFERROR(IF(Cashflow!I$64=0,"",((Cashflow!I$72+Cashflow!I$73)-Cashflow!I$39)/Cashflow!I$64),"") -> 0.88629181 | I13: =IFERROR(IF(Cashflow!J$64=0,"",((Cashflow!J$72+Cashflow!J$73)-Cashflow!J$39)/Cashflow!J$64),"") -> 0.68278276 | J13: =IFERROR(IF(Cashflow!K$64=0,"",((Cashflow!K$72+Cashflow!K$73)-Cashflow!K$39)/Cashflow!K$64),"") -> 0.53597319 | ... P13: =IFERROR(IF(Cashflow!Q$64=0,"",((Cashflow!Q$72+Cashflow!Q$73)-Cashflow!Q$39)/Cashflow!Q$64),"") -> 0
P16: Active Scenario | Q16: =Scenarios!B4 -> Base
P17: Model Health | Q17: =Q3 -> #REF!
B19: FINANCIAL SUMMARY
C20: FY25 | D20: FY26 | E20: FY27 | F20: FY28 | G20: FY29 | H20: FY30 | I20: FY31 | J20: FY32 | K20: FY33 | L20: FY34 | M20: FY35 | N20: FY36 | O20: FY37 | P20: FY38
B21: Revenue | C21: ='P&L'!H28 -> 0 | D21: ='P&L'!I28 -> 0 | E21: ='P&L'!J28 -> 18772333 | F21: ='P&L'!K28 -> 19676502 | G21: ='P&L'!L28 -> 20615522 | H21: ='P&L'!M28 -> 21808635 | I21: ='P&L'!N28 -> 22300757 | J21: ='P&L'!O28 -> 22807316 | ... M21: ='P&L'!R28 -> 24417930 | N21: ='P&L'!R28 -> 24417930 | O21: ='P&L'!S28 -> 24986615 | P21: ='P&L'!T28 -> 25571992
B22: EBITDA | C22: ='P&L'!H79 -> 0 | D22: ='P&L'!I79 -> 0 | E22: ='P&L'!J79 -> 10240353 | F22: ='P&L'!K79 -> 10221611 | G22: ='P&L'!L79 -> 10726643 | H22: ='P&L'!M79 -> 11603174 | I22: ='P&L'!N79 -> 11825139 | J22: ='P&L'!O79 -> 11488417 | ... M22: ='P&L'!R79 -> 12008307 | N22: ='P&L'!R79 -> 12008307 | O22: ='P&L'!S79 -> 12146815 | P22: ='P&L'!T79 -> 13901343
B23: Closing Cash | C23: ='Balance Sheet'!G10 -> 0 | D23: ='Balance Sheet'!H10 -> 452228.4 | E23: ='Balance Sheet'!I10 -> 1724785.6 | F23: ='Balance Sheet'!J10 -> 2184190 | G23: ='Balance Sheet'!K10 -> 2729888 | H23: ='Balance Sheet'!L10 -> 3408439 | I23: ='Balance Sheet'!M10 -> 4135811.4 | J23: ='Balance Sheet'!N10 -> 4833789 | ... M23: ='Balance Sheet'!Q10 -> 7159432.3 | N23: ='Balance Sheet'!Q10 -> 7159432.3 | O23: ='Balance Sheet'!R10 -> 9596186.9 | P23: ='Balance Sheet'!S10 -> 12278575
B24: Total Debt | C24: =Debt!I24+Debt!I43 -> 0 | D24: =Debt!J24+Debt!J43 -> 12675915 | E24: =Debt!K24+Debt!K43 -> 12675915 | F24: =Debt!L24+Debt!L43 -> 11091426 | G24: =Debt!M24+Debt!M43 -> 9506936.2 | H24: =Debt!N24+Debt!N43 -> 7922446.9 | I24: =Debt!O24+Debt!O43 -> 6337957.5 | J24: =Debt!P24+Debt!P43 -> 4753468.1 | ... M24: =Debt!S24+Debt!S43 -> 0 | N24: =Debt!S24+Debt!S43 -> 0 | O24: =Debt!T24+Debt!T43 -> 0 | P24: =Debt!U24+Debt!U43 -> 0
B27: DEBT & LEVERAGE | F27: EVENT DAYS MIX (STABILIZED FY) | I27: EVENT INDUSTRY KPIs (STABILIZED FY)
B28: Metric | C28: Value | F28: Event Type | G28: Days | I28: Metric | J28: Value | K28: Units
B29: Total Debt Facility | C29: =Inputs!E66 -> 11856915 | F29: Music GA (all tiers) | G29: {=IFERROR((INDEX('Calendar Assumptions'!$F$5:$P$5,MATCH(Valuations!C128,'Calendar Assumptions'!$F$4:$P$4,0))+INDEX('Calendar Assumptions'!$F$6:$P$6,MATCH(Valuations!C128,'Calendar Assumptions'!$F$4:$P$4,0))+INDEX('Calendar Assumptions'!$F$7:$P$7,MATCH(Valuations!C128,'Calendar Assumptions'!$F$4:$P$4,0))),0)} -> 48.516 | I29: Annual Event Days | J29: ='Calendar Assumptions'!H16 -> 162.342 | K29: days
B30: Bank Debt | C30: =Inputs!E66 -> 11856915 | F30: EDM | G30: {=IFERROR(INDEX('Calendar Assumptions'!$F$8:$P$8, MATCH(Valuations!C128,'Calendar Assumptions'!$F$4:$P$4,0)),0)} -> 16.794 | I30: Total Revenue | J30: ='P&L'!L28 -> 20615522 | K30: A$
B31: PE Equity | C31: =Inputs!E118+Inputs!E114 -> 8970383.1 | F31: Seated Music | G31: {=IFERROR(INDEX('Calendar Assumptions'!$F$9:$P$9, MATCH(Valuations!C128,'Calendar Assumptions'!$F$4:$P$4,0)),0)} -> 13.995 | I31: Revenue per Event Day | J31: =J30/J29 -> 126988.22 | K31: A$/day
B32: Bank Term (years) | C32: =Inputs!E64 -> 10 | F32: Comedy | G32: {=IFERROR(INDEX('Calendar Assumptions'!$F$10:$P$10, MATCH(Valuations!C128,'Calendar Assumptions'!$F$4:$P$4,0)),0)} -> 13.995 | I32: EBITDA per Event Day | J32: ='P&L'!L79/J29 -> 66074.358 | K32: A$/day
B33: PE Equity Injection Year | C33: =Inputs!E131 -> FY27 | F33: Corporate | G33: {=IFERROR(INDEX('Calendar Assumptions'!$F$11:$P$11, MATCH(Valuations!C128,'Calendar Assumptions'!$F$4:$P$4,0)),0)} -> 2.799 | I33: Yield on Cost | J33: =Valuations!C130 -> 0.54280444 | K33: %
B34: Bank Interest Rate | C34: =Inputs!E63 -> 0.08 | F34: MICE | G34: {=IFERROR(INDEX('Calendar Assumptions'!$F$12:$P$12, MATCH(Valuations!C128,'Calendar Assumptions'!$F$4:$P$4,0)),0)} -> 27.057
B35: Shareholder Loan Toggle | C35: =IF(Inputs!E133=0,"OFF","ON") -> OFF | F35: Community | G35: {=IFERROR(INDEX('Calendar Assumptions'!$F$13:$P$13, MATCH(Valuations!C128,'Calendar Assumptions'!$F$4:$P$4,0)),0)} -> 11.196
B36: Debt/Total Capex | C36: =(Inputs!E66+Inputs!E75)/Inputs!E159 -> 0.6 | F36: Live Site | G36: {=IFERROR(INDEX('Calendar Assumptions'!$F$14:$P$14, MATCH(Valuations!C128,'Calendar Assumptions'!$F$4:$P$4,0)),0)} -> 3.732
B39: VALUATION SUMMARY | F39: PROFITABILITY METRICS (EXIT FY) | I39: KEY INVESTMENT METRICS | J39: Value | L39: REVENUE MIX (EXIT FY) | O39: DEBT & LEVERAGE
B40: Metric | C40: Value | D40: Notes | F40: Metric | G40: Value | I40: Metric | J40: Value | L40: Stream | M40: Value | O40: Metric | P40: Value
B41: WACC | C41: =Valuations!C9 -> 0.1 | D41: Discount rate | F41: Total Revenue | G41: ='P&L'!L28 -> 20615522 | I41: Total Capex | J41: =Inputs!E159 -> 19761525 | L41: VHA | M41: {=IFERROR(INDEX('P&L'!$G$14:$T$14, MATCH(Inputs!$E$488,'P&L'!$G$6:$T$6,0)),0)} -> 7723631.2 | O41: Total Debt Facility | P41: =Debt!C5+Debt!D5 -> 12675915
B42: Exit Multiple | C42: =Valuations!C15 -> 7 | D42: EBITDA multiple | F42: Gross Profit | G42: ='P&L'!L40 -> 18125573 | I42: Equity Required | J42: =SUM(Cashflow!D13:O14) -> 8970383.1 | L42: Premium Sales | M42: {=IFERROR(INDEX('P&L'!$G$15:$T$15, MATCH(Inputs!$E$488,'P&L'!$G$6:$T$6,0)),0)} -> 1084742.1 | O42: Bank Debt | P42: =Debt!C5 -> 12675915
B43: Exit EBITDA | C43: =Valuations!C72 -> 13901343 | D43: FY38 EBITDA | F43: Gross Margin % | G43: ='P&L'!L41 -> 0.87921971 | I43: Total Debt | J43: =Debt!C5+Debt!D5 -> 12675915 | L43: Premium F&B | M43: {=IFERROR(INDEX('P&L'!$G$16:$T$16, MATCH(Inputs!$E$488,'P&L'!$G$6:$T$6,0)),0)} -> 182520 | O43: PE Loan | P43: =Debt!D5 -> 0
B44: Terminal Value | C44: =Valuations!C74 -> 97309399 | D44: Exit value | F44: EBITDA | G44: ='P&L'!L79 -> 10726643 | I44: Debt/Equity Ratio | J44: =J43/J42 -> 1.4130851 | L44: F&B | M44: {=IFERROR(INDEX('P&L'!$G$17:$T$17, MATCH(Inputs!$E$488,'P&L'!$G$6:$T$6,0)),0)} -> 8690093.4 | O44: Bank Term (years) | P44: =Debt!C6 -> 10
B45: Enterprise Value | C45: =Valuations!C91 -> 62301607 | D45: DCF valuation | F45: EBITDA Margin % | G45: ='P&L'!L80 -> 0.52031879 | I45: Project IRR | J45: =Valuations!C109 -> 0.24794587 | L45: Merchandise | M45: {=IFERROR(INDEX('P&L'!$G$18:$T$18, MATCH(Inputs!$E$488,'P&L'!$G$6:$T$6,0)),0)} -> 832800 | O45: PE Term (years) | P45: =Debt!D6 -> 10
B46: Net Debt (Exit) | C46: =Valuations!C93+Valuations!C94 -> -12223687 | D46: Debt - Cash at exit | F46: NPAT | G46: ='P&L'!L95 -> 6240242.9 | I46: Equity IRR | J46: =Valuations!C123 -> 0.33284791 | L46: Equipment Hire | M46: {=IFERROR(INDEX('P&L'!$G$20:$T$20, MATCH(Inputs!$E$488,'P&L'!$G$6:$T$6,0)),0)} -> 2610000 | O46: Bank Interest Rate | P46: =Debt!C7 -> 0.08
B47: Equity Value | C47: =Valuations!C23 -> 50077920 | D47: EV less Net Debt | F47: Net Margin % | G47: =IF(G41=0,0,G46/G41) -> 0.30269634 | I47: MOIC | J47: =Valuations!C127 -> 17.693182 | L47: Sponsorship | M47: {=IFERROR(INDEX('P&L'!$G$24:$T$24, MATCH(Inputs!$E$488,'P&L'!$G$6:$T$6,0)),0)} -> 2368156.4 | O47: PE Interest Rate | P47: =Debt!D7 -> 0.12
I48: Payback Period | J48: FY30 | L48: Advertising | M48: {=IFERROR(INDEX('P&L'!$G$25:$T$25, MATCH(Inputs!$E$488,'P&L'!$G$6:$T$6,0)),0)} -> 736048.61 | O48: Debt Payoff Year | P48: FY32
...

Sheet Dashboard (backup)
A1: THE BEND LIVE HOUSE — EXECUTIVE DASHBOARD
A2: THE BEND LIVE HOUSE — EXECUTIVE DASHBOARD | P2: Active Scenario | Q2: =Scenarios!$B$4 -> Base
P3: Model Health | Q3: =IF(#REF!=0,"OK","FAIL") -> #REF!
B5: Summary
B6: FY | C6: =IFERROR(Cashflow!D$7,"") -> FY25 | D6: =IFERROR(Cashflow!E$7,"") -> FY26 | E6: =IFERROR(Cashflow!F$7,"") -> FY27 | F6: =IFERROR(Cashflow!G$7,"") -> FY28 | G6: =IFERROR(Cashflow!H$7,"") -> FY29 | H6: =IFERROR(Cashflow!I$7,"") -> FY30 | I6: =IFERROR(Cashflow!J$7,"") -> FY31 | J6: =IFERROR(Cashflow!K$7,"") -> FY32 | ... P6: =IFERROR(Cashflow!Q$7,"") -> FY38
B7: Revenue | C7: =IFERROR(Cashflow!D$48,"") -> 0 | D7: =IFERROR(Cashflow!E$48,"") -> 0 | E7: =IFERROR(Cashflow!F$48,"") -> 0 | F7: =IFERROR(Cashflow!G$48,"") -> 18772333 | G7: =IFERROR(Cashflow!H$48,"") -> 19676502 | H7: =IFERROR(Cashflow!I$48,"") -> 20615522 | I7: =IFERROR(Cashflow!J$48,"") -> 21808635 | J7: =IFERROR(Cashflow!K$48,"") -> 22300757 | ... P7: =IFERROR(Cashflow!Q$48,"") -> 25571992
B8: EBITDA | C8: =IFERROR(Cashflow!D$64,"") -> 0 | D8: =IFERROR(Cashflow!E$64,"") -> 0 | E8: =IFERROR(Cashflow!F$64,"") -> 0 | F8: =IFERROR(Cashflow!G$64,"") -> 10240353 | G8: =IFERROR(Cashflow!H$64,"") -> 10221611 | H8: =IFERROR(Cashflow!I$64,"") -> 10726643 | I8: =IFERROR(Cashflow!J$64,"") -> 11603174 | J8: =IFERROR(Cashflow!K$64,"") -> 11825139 | ... P8: =IFERROR(Cashflow!Q$64,"") -> 13901343
B9: Closing Cash | C9: =IFERROR(Cashflow!D38,"") -> 0 | D9: =IFERROR(Cashflow!E38,"") -> 0 | E9: =IFERROR(Cashflow!F38,"") -> 452228.4 | F9: =IFERROR(Cashflow!G38,"") -> 1724785.6 | G9: =IFERROR(Cashflow!H38,"") -> 2184190 | H9: =IFERROR(Cashflow!I38,"") -> 2729888 | I9: =IFERROR(Cashflow!J38,"") -> 3408439 | J9: =IFERROR(Cashflow!K38,"") -> 4135811.4 | ... P9: =IFERROR(Cashflow!Q38,"") -> 12278575
B10: Total Debt | C10: =IFERROR(Debt!H48,0) -> 0 | D10: =IFERROR(Debt!I48,0) -> 0 | E10: =IFERROR(Debt!J48,0) -> 12675915 | F10: =IFERROR(Debt!K48,0) -> 12675915 | G10: =IFERROR(Debt!L48,0) -> 11091426 | H10: =IFERROR(Debt!M48,0) -> 9506936.2 | I10: =IFERROR(Debt!N48,0) -> 7922446.9 | J10: =IFERROR(Debt!O48,0) -> 6337957.5 | ... P10: =IFERROR(Debt!U48,0) -> 0
B11: DSCR | C11: =Cashflow!D67 | D11: =Cashflow!E67 | E11: =Cashflow!F67 | F11: =Cashflow!G67 -> 3.748065 | G11: =Cashflow!H67 -> 3.0466904 | H11: =Cashflow!I67 -> 3.3189554 | I11: =Cashflow!J67 -> 3.7480419 | J11: =Cashflow!K67 -> 4.0469539 | ... P11: =Cashflow!Q67
B12: ICR | C12: =IFERROR(IF(Debt!H$57=0,"",Cashflow!D$64/Debt!H$57),"") | D12: =IFERROR(IF(Debt!I$57=0,"",Cashflow!E$64/Debt!I$57),"") | E12: =IFERROR(IF(Debt!J$57=0,"",Cashflow!F$64/Debt!J$57),"") -> 0 | F12: =IFERROR(IF(Debt!K$57=0,"",Cashflow!G$64/Debt!K$57),"") -> 10.098239 | G12: =IFERROR(IF(Debt!L$57=0,"",Cashflow!H$64/Debt!L$57),"") -> 10.75174 | H12: =IFERROR(IF(Debt!M$57=0,"",Cashflow!I$64/Debt!M$57),"") -> 13.018806 | I12: =IFERROR(IF(Debt!N$57=0,"",Cashflow!J$64/Debt!N$57),"") -> 16.643121 | J12: =IFERROR(IF(Debt!O$57=0,"",Cashflow!K$64/Debt!O$57),"") -> 20.730722 | ... P12: =IFERROR(IF(Debt!U$57=0,"",Cashflow!Q$64/Debt!U$57),"")
B13: Net Leverage (Net Debt/EBITDA) | C13: =IFERROR(IF(Cashflow!D$64=0,"",((Cashflow!D$72+Cashflow!D$73)-Cashflow!D$39)/Cashflow!D$64),"") | D13: =IFERROR(IF(Cashflow!E$64=0,"",((Cashflow!E$72+Cashflow!E$73)-Cashflow!E$39)/Cashflow!E$64),"") | E13: =IFERROR(IF(Cashflow!F$64=0,"",((Cashflow!F$72+Cashflow!F$73)-Cashflow!F$39)/Cashflow!F$64),"") | F13: =IFERROR(IF(Cashflow!G$64=0,"",((Cashflow!G$72+Cashflow!G$73)-Cashflow!G$39)/Cashflow!G$64),"") -> 1.2378396 | G13: =IFERROR(IF(Cashflow!H$64=0,"",((Cashflow!H$72+Cashflow!H$73)-Cashflow!H$39)/Cashflow!H$64),"") -> 1.0850957 | H13: =IFERROR(IF(Cashflow!I$64=0,"",((Cashflow!I$72+Cashflow!I$73)-Cashflow!I$39)/Cashflow!I$64),"") -> 0.88629181 | I13: =IFERROR(IF(Cashflow!J$64=0,"",((Cashflow!J$72+Cashflow!J$73)-Cashflow!J$39)/Cashflow!J$64),"") -> 0.68278276 | J13: =IFERROR(IF(Cashflow!K$64=0,"",((Cashflow!K$72+Cashflow!K$73)-Cashflow!K$39)/Cashflow!K$64),"") -> 0.53597319 | ... P13: =IFERROR(IF(Cashflow!Q$64=0,"",((Cashflow!Q$72+Cashflow!Q$73)-Cashflow!Q$39)/Cashflow!Q$64),"") -> 0
A15: THE BEND LIVE HOUSE — EXECUTIVE DASHBOARD
A16: THE BEND LIVE HOUSE — EXECUTIVE DASHBOARD | P16: Active Scenario | Q16: =Scenarios!B4 -> Base
P17: Model Health | Q17: =Q3 -> #REF!
B19: FINANCIAL SUMMARY
C20: FY25 | D20: FY26 | E20: FY27 | F20: FY28 | G20: FY29 | H20: FY30 | I20: FY31 | J20: FY32 | K20: FY33 | L20: FY34 | M20: FY35 | N20: FY36 | O20: FY37 | P20: FY38
B21: Revenue | C21: ='P&L'!H28 -> 0 | D21: ='P&L'!I28 -> 0 | E21: ='P&L'!J28 -> 18772333 | F21: ='P&L'!K28 -> 19676502 | G21: ='P&L'!L28 -> 20615522 | H21: ='P&L'!M28 -> 21808635 | I21: ='P&L'!N28 -> 22300757 | J21: ='P&L'!O28 -> 22807316 | ... M21: ='P&L'!R28 -> 24417930 | N21: ='P&L'!R28 -> 24417930 | O21: ='P&L'!S28 -> 24986615 | P21: ='P&L'!T28 -> 25571992
B22: EBITDA | C22: ='P&L'!H79 -> 0 | D22: ='P&L'!I79 -> 0 | E22: ='P&L'!J79 -> 10240353 | F22: ='P&L'!K79 -> 10221611 | G22: ='P&L'!L79 -> 10726643 | H22: ='P&L'!M79 -> 11603174 | I22: ='P&L'!N79 -> 11825139 | J22: ='P&L'!O79 -> 11488417 | ... M22: ='P&L'!R79 -> 12008307 | N22: ='P&L'!R79 -> 12008307 | O22: ='P&L'!S79 -> 12146815 | P22: ='P&L'!T79 -> 13901343
B23: Closing Cash | C23: ='Balance Sheet'!G10 -> 0 | D23: ='Balance Sheet'!H10 -> 452228.4 | E23: ='Balance Sheet'!I10 -> 1724785.6 | F23: ='Balance Sheet'!J10 -> 2184190 | G23: ='Balance Sheet'!K10 -> 2729888 | H23: ='Balance Sheet'!L10 -> 3408439 | I23: ='Balance Sheet'!M10 -> 4135811.4 | J23: ='Balance Sheet'!N10 -> 4833789 | ... M23: ='Balance Sheet'!Q10 -> 7159432.3 | N23: ='Balance Sheet'!Q10 -> 7159432.3 | O23: ='Balance Sheet'!R10 -> 9596186.9 | P23: ='Balance Sheet'!S10 -> 12278575
B24: Total Debt | C24: =Debt!I24+Debt!I43 -> 0 | D24: =Debt!J24+Debt!J43 -> 12675915 | E24: =Debt!K24+Debt!K43 -> 12675915 | F24: =Debt!L24+Debt!L43 -> 11091426 | G24: =Debt!M24+Debt!M43 -> 9506936.2 | H24: =Debt!N24+Debt!N43 -> 7922446.9 | I24: =Debt!O24+Debt!O43 -> 6337957.5 | J24: =Debt!P24+Debt!P43 -> 4753468.1 | ... M24: =Debt!S24+Debt!S43 -> 0 | N24: =Debt!S24+Debt!S43 -> 0 | O24: =Debt!T24+Debt!T43 -> 0 | P24: =Debt!U24+Debt!U43 -> 0
B27: DEBT & LEVERAGE | F27: EVENT DAYS MIX (STABILIZED FY) | I27: EVENT INDUSTRY KPIs (STABILIZED FY)
B28: Metric | C28: Value | F28: Event Type | G28: Days | I28: Metric | J28: Value | K28: Units
B29: Total Debt Facility | C29: =Inputs!E66 -> 11856915 | F29: Music GA (all tiers) | G29: {=IFERROR((INDEX('Calendar Assumptions'!$F$5:$P$5,MATCH(Valuations!C128,'Calendar Assumptions'!$F$4:$P$4,0))+INDEX('Calendar Assumptions'!$F$6:$P$6,MATCH(Valuations!C128,'Calendar Assumptions'!$F$4:$P$4,0))+INDEX('Calendar Assumptions'!$F$7:$P$7,MATCH(Valuations!C128,'Calendar Assumptions'!$F$4:$P$4,0))),0)} -> 48.516 | I29: Annual Event Days | J29: ='Calendar Assumptions'!H16 -> 162.342 | K29: days
B30: Bank Debt | C30: =Inputs!E66 -> 11856915 | F30: EDM | G30: {=IFERROR(INDEX('Calendar Assumptions'!$F$8:$P$8, MATCH(Valuations!C128,'Calendar Assumptions'!$F$4:$P$4,0)),0)} -> 16.794 | I30: Total Revenue | J30: ='P&L'!L28 -> 20615522 | K30: A$
B31: PE Equity | C31: =Inputs!E118+Inputs!E114 -> 8970383.1 | F31: Seated Music | G31: {=IFERROR(INDEX('Calendar Assumptions'!$F$9:$P$9, MATCH(Valuations!C128,'Calendar Assumptions'!$F$4:$P$4,0)),0)} -> 13.995 | I31: Revenue per Event Day | J31: =J30/J29 -> 126988.22 | K31: A$/day
B32: Bank Term (years) | C32: =Inputs!E64 -> 10 | F32: Comedy | G32: {=IFERROR(INDEX('Calendar Assumptions'!$F$10:$P$10, MATCH(Valuations!C128,'Calendar Assumptions'!$F$4:$P$4,0)),0)} -> 13.995 | I32: EBITDA per Event Day | J32: ='P&L'!L79/J29 -> 66074.358 | K32: A$/day
B33: PE Equity Injection Year | C33: =Inputs!E131 -> FY27 | F33: THE BEND LIVE HOUSE — EXECUTIVE DASHBOARD | G33: {=IFERROR(INDEX('Calendar Assumptions'!$F$11:$P$11, MATCH(Valuations!C128,'Calendar Assumptions'!$F$4:$P$4,0)),0)} -> 2.799 | I33: Yield on Cost | J33: =Valuations!C130 -> 0.54280444 | K33: %
B34: Bank Interest Rate | C34: =Inputs!E63 -> 0.08 | F34: MICE | G34: {=IFERROR(INDEX('Calendar Assumptions'!$F$12:$P$12, MATCH(Valuations!C128,'Calendar Assumptions'!$F$4:$P$4,0)),0)} -> 27.057
B35: Shareholder Loan Toggle | C35: =IF(Inputs!E133=0,"OFF","ON") -> OFF | F35: Community | G35: {=IFERROR(INDEX('Calendar Assumptions'!$F$13:$P$13, MATCH(Valuations!C128,'Calendar Assumptions'!$F$4:$P$4,0)),0)} -> 11.196
B36: Debt/Total Capex | C36: =(Inputs!E66+Inputs!E75)/Inputs!E159 -> 0.6 | F36: Live Site | G36: {=IFERROR(INDEX('Calendar Assumptions'!$F$14:$P$14, MATCH(Valuations!C128,'Calendar Assumptions'!$F$4:$P$4,0)),0)} -> 3.732
B39: VALUATION SUMMARY | F39: PROFITABILITY METRICS (EXIT FY) | I39: KEY INVESTMENT METRICS | J39: Value | L39: REVENUE MIX (EXIT FY) | O39: DEBT & LEVERAGE
B40: Metric | C40: Value | D40: Notes | F40: Metric | G40: Value | I40: Metric | J40: Value | L40: Stream | M40: Value | O40: Metric | P40: Value
B41: WACC | C41: =Valuations!C9 -> 0.1 | D41: Discount rate | F41: Total Revenue | G41: ='P&L'!L28 -> 20615522 | I41: Total Capex | J41: =Inputs!E159 -> 19761525 | L41: VHA | M41: {=IFERROR(INDEX('P&L'!$G$14:$T$14, MATCH(Inputs!$E$488,'P&L'!$G$6:$T$6,0)),0)} -> 7723631.2 | O41: Total Debt Facility | P41: =Debt!C5+Debt!D5 -> 12675915
B42: Exit Multiple | C42: =Valuations!C15 -> 7 | D42: EBITDA multiple | F42: Gross Profit | G42: ='P&L'!L40 -> 18125573 | I42: Equity Required | J42: =SUM(Cashflow!D13:O14) -> 8970383.1 | L42: Premium Sales | M42: {=IFERROR(INDEX('P&L'!$G$15:$T$15, MATCH(Inputs!$E$488,'P&L'!$G$6:$T$6,0)),0)} -> 1084742.1 | O42: Bank Debt | P42: =Debt!C5 -> 12675915
B43: Exit EBITDA | C43: =Valuations!C72 -> 13901343 | D43: FY38 EBITDA | F43: Gross Margin % | G43: ='P&L'!L41 -> 0.87921971 | I43: Total Debt | J43: =Debt!C5+Debt!D5 -> 12675915 | L43: Premium F&B | M43: {=IFERROR(INDEX('P&L'!$G$16:$T$16, MATCH(Inputs!$E$488,'P&L'!$G$6:$T$6,0)),0)} -> 182520 | O43: PE Loan | P43: =Debt!D5 -> 0
B44: Terminal Value | C44: =Valuations!C74 -> 97309399 | D44: Exit value | F44: EBITDA | G44: ='P&L'!L79 -> 10726643 | I44: Debt/Equity Ratio | J44: =J43/J42 -> 1.4130851 | L44: F&B | M44: {=IFERROR(INDEX('P&L'!$G$17:$T$17, MATCH(Inputs!$E$488,'P&L'!$G$6:$T$6,0)),0)} -> 8690093.4 | O44: Bank Term (years) | P44: =Debt!C6 -> 10
B45: Enterprise Value | C45: =Valuations!C91 -> 62301607 | D45: DCF valuation | F45: EBITDA Margin % | G45: ='P&L'!L80 -> 0.52031879 | I45: Project IRR | J45: =Valuations!C109 -> 0.24794587 | L45: Merchandise | M45: {=IFERROR(INDEX('P&L'!$G$18:$T$18, MATCH(Inputs!$E$488,'P&L'!$G$6:$T$6,0)),0)} -> 832800 | O45: PE Term (years) | P45: =Debt!D6 -> 10
B46: Net Debt (Exit) | C46: =Valuations!C93+Valuations!C94 -> -12223687 | D46: Debt - Cash at exit | F46: NPAT | G46: ='P&L'!L95 -> 6240242.9 | I46: Equity IRR | J46: =Valuations!C123 -> 0.33284791 | L46: Equipment Hire | M46: {=IFERROR(INDEX('P&L'!$G$20:$T$20, MATCH(Inputs!$E$488,'P&L'!$G$6:$T$6,0)),0)} -> 2610000 | O46: Bank Interest Rate | P46: =Debt!C7 -> 0.08
B47: Equity Value | C47: =Valuations!C23 -> 50077920 | D47: EV less Net Debt | F47: Net Margin % | G47: =IF(G41=0,0,G46/G41) -> 0.30269634 | I47: MOIC | J47: =Valuations!C127 -> 17.693182 | L47: Sponsorship | M47: {=IFERROR(INDEX('P&L'!$G$24:$T$24, MATCH(Inputs!$E$488,'P&L'!$G$6:$T$6,0)),0)} -> 2368156.4 | O47: PE Interest Rate | P47: =Debt!D7 -> 0.12
...

Sheet Cashflow
A1: Annual Cashflow Waterfall (AUD)
A2: THE BEND Live House
C4: Currency | E4: AUD
C5: FY Start | D5: ='P&L'!G4 -> 45689 | E5: ='P&L'!H4 -> 45839 | F5: ='P&L'!I4 -> 46204 | G5: ='P&L'!J4 -> 46569 | H5: ='P&L'!K4 -> 46935 | I5: ='P&L'!L4 -> 47300 | J5: ='P&L'!M4 -> 47665 | K5: ='P&L'!N4 -> 48030 | ... Q5: ='P&L'!T4 -> 50222
C6: FY End | D6: ='P&L'!G5 -> 45838 | E6: ='P&L'!H5 -> 46203 | F6: ='P&L'!I5 -> 46568 | G6: ='P&L'!J5 -> 46934 | H6: ='P&L'!K5 -> 47299 | I6: ='P&L'!L5 -> 47664 | J6: ='P&L'!M5 -> 48029 | K6: ='P&L'!N5 -> 48395 | ... Q6: ='P&L'!T5 -> 50586
C7: Year | D7: ='P&L'!G6 -> FY25 | E7: ='P&L'!H6 -> FY26 | F7: ='P&L'!I6 -> FY27 | G7: ='P&L'!J6 -> FY28 | H7: ='P&L'!K6 -> FY29 | I7: ='P&L'!L6 -> FY30 | J7: ='P&L'!M6 -> FY31 | K7: ='P&L'!N6 -> FY32 | ... Q7: ='P&L'!T6 -> FY38
A10: Opening Cash Balance | D10: 0 | E10: =Cashflow!D38 -> 0 | F10: =E38 -> 0 | G10: =F38 -> 452228.4 | H10: =G38 -> 1724785.6 | I10: =H38 -> 2184190 | J10: =I38 -> 2729888 | K10: =J38 -> 3408439 | L10: =K38 -> 4135811.4 | M10: =L38 -> 4833789 | ... Q10: =P38 -> 9596186.9
A12: INFLOWS
A13: Initial Cash Inflow through deposits via Partnerships | D13: =IF(D7=Inputs!$E$126,Inputs!$E$114,0) -> 0 | E13: =IF(E7=Inputs!$E$126,Inputs!$E$114,0) -> 0 | F13: =IF(F7=Inputs!$E$126,Inputs!$E$114,0) -> 1500000 | G13: =IF(G7=Inputs!$E$126,Inputs!$E$114,0) -> 0 | H13: =IF(H7=Inputs!$E$126,Inputs!$E$114,0) -> 0 | I13: =IF(I7=Inputs!$E$126,Inputs!$E$114,0) -> 0 | J13: =IF(J7=Inputs!$E$126,Inputs!$E$114,0) -> 0 | K13: =IF(K7=Inputs!$E$126,Inputs!$E$114,0) -> 0 | ... Q13: =IF(Q7=Inputs!$E$126,Inputs!$E$114,0) -> 0
A14: PE Equity Inflow | D14: =IF(AND(D7=Inputs!$E$131,Inputs!$E$133=0),Inputs!$E$118,0) -> 0 | E14: =IF(AND(E7=Inputs!$E$131,Inputs!$E$133=0),Inputs!$E$118,0) -> 0 | F14: =IF(AND(F7=Inputs!$E$131,Inputs!$E$133=0),Inputs!$E$118,0) -> 7470383.1 | G14: =IF(AND(G7=Inputs!$E$131,Inputs!$E$133=0),Inputs!$E$118,0) -> 0 | H14: =IF(AND(H7=Inputs!$E$131,Inputs!$E$133=0),Inputs!$E$118,0) -> 0 | I14: =IF(AND(I7=Inputs!$E$131,Inputs!$E$133=0),Inputs!$E$118,0) -> 0 | J14: =IF(AND(J7=Inputs!$E$131,Inputs!$E$133=0),Inputs!$E$118,0) -> 0 | K14: =IF(AND(K7=Inputs!$E$131,Inputs!$E$133=0),Inputs!$E$118,0) -> 0 | ... Q14: =IF(AND(Q7=Inputs!$E$131,Inputs!$E$133=0),Inputs!$E$118,0) -> 0
A15: Additional Equity Tranches | D15: =IF(D7=Inputs!$E$128,Inputs!$E$127,0)+IF(D7=Inputs!$E$130,Inputs!$E$129,0)+IF(D7=Inputs!$E$135,Inputs!$E$134,0) -> 0 | E15: =IF(E7=Inputs!$E$128,Inputs!$E$127,0)+IF(E7=Inputs!$E$130,Inputs!$E$129,0)+IF(E7=Inputs!$E$135,Inputs!$E$134,0) -> 0 | F15: =IF(F7=Inputs!$E$128,Inputs!$E$127,0)+IF(F7=Inputs!$E$130,Inputs!$E$129,0)+IF(F7=Inputs!$E$135,Inputs!$E$134,0) -> 0 | G15: =IF(G7=Inputs!$E$128,Inputs!$E$127,0)+IF(G7=Inputs!$E$130,Inputs!$E$129,0)+IF(G7=Inputs!$E$135,Inputs!$E$134,0) -> 0 | H15: =IF(H7=Inputs!$E$128,Inputs!$E$127,0)+IF(H7=Inputs!$E$130,Inputs!$E$129,0)+IF(H7=Inputs!$E$135,Inputs!$E$134,0) -> 0 | I15: =IF(I7=Inputs!$E$128,Inputs!$E$127,0)+IF(I7=Inputs!$E$130,Inputs!$E$129,0)+IF(I7=Inputs!$E$135,Inputs!$E$134,0) -> 0 | J15: =IF(J7=Inputs!$E$128,Inputs!$E$127,0)+IF(J7=Inputs!$E$130,Inputs!$E$129,0)+IF(J7=Inputs!$E$135,Inputs!$E$134,0) -> 0 | K15: =IF(K7=Inputs!$E$128,Inputs!$E$127,0)+IF(K7=Inputs!$E$130,Inputs!$E$129,0)+IF(K7=Inputs!$E$135,Inputs!$E$134,0) -> 0 | ... Q15: =IF(Q7=Inputs!$E$128,Inputs!$E$127,0)+IF(Q7=Inputs!$E$130,Inputs!$E$129,0)+IF(Q7=Inputs!$E$135,Inputs!$E$134,0) -> 0
A16: Total Equity Inflow | D16: =D13+D14+D15 -> 0 | E16: =E13+E14+E15 -> 0 | F16: =F13+F14+F15 -> 8970383.1 | G16: =G13+G14+G15 -> 0 | H16: =H13+H14+H15 -> 0 | I16: =I13+I14+I15 -> 0 | J16: =J13+J14+J15 -> 0 | K16: =K13+K14+K15 -> 0 | ... Q16: =Q13+Q14+Q15 -> 0
A18: Debt drawdowns – Bank (from Debt) | D18: =IFERROR(Debt!H20,0) -> 0 | E18: =IFERROR(Debt!I20,0) -> 0 | F18: =IFERROR(Debt!J20,0) -> 12675915 | G18: =IFERROR(Debt!K20,0) -> 0 | H18: =IFERROR(Debt!L20,0) -> 0 | I18: =IFERROR(Debt!M20,0) -> 0 | J18: =IFERROR(Debt!N20,0) -> 0 | K18: =IFERROR(Debt!O20,0) -> 0 | ... Q18: =IFERROR(Debt!U20,0) -> 0
A19: WC Facility drawdowns (from Debt) | D19: =IFERROR(Debt!H76,0) -> 0 | E19: =IFERROR(Debt!I76,0) -> 0 | F19: =IFERROR(Debt!J76,0) -> 850000 | G19: =IFERROR(Debt!K76,0) -> 0 | H19: =IFERROR(Debt!L76,0) -> 0 | I19: =IFERROR(Debt!M76,0) -> 0 | J19: =IFERROR(Debt!N76,0) -> 0 | K19: =IFERROR(Debt!O76,0) -> 0 | ... Q19: =IFERROR(Debt!U76,0) -> 0
A20: PE Loan drawdowns – LEGACY INACTIVE | D20: =0 -> 0 | E20: =0 -> 0 | F20: =0 -> 0 | G20: =0 -> 0 | H20: =0 -> 0 | I20: =0 -> 0 | J20: =0 -> 0 | K20: =0 -> 0 | ... Q20: =0 -> 0
A21: Pre-op revenue (from Cashflow) | D21: =SUMIF(Timing!$C$6:$Q$6,D7,Timing!$C$22:$Q$22) -> 0 | E21: =SUMIF(Timing!$C$6:$Q$6,E7,Timing!$C$22:$Q$22) -> 0 | F21: =SUMIF(Timing!$C$6:$Q$6,F7,Timing!$C$22:$Q$22) -> 0 | G21: =SUMIF(Timing!$C$6:$Q$6,G7,Timing!$C$22:$Q$22) -> 0 | H21: =SUMIF(Timing!$C$6:$Q$6,H7,Timing!$C$22:$Q$22) -> 0 | I21: =SUMIF(Timing!$C$6:$Q$6,I7,Timing!$C$22:$Q$22) -> 0 | J21: =SUMIF(Timing!$C$6:$Q$6,J7,Timing!$C$22:$Q$22) -> 0 | K21: =SUMIF(Timing!$C$6:$Q$6,K7,Timing!$C$22:$Q$22) -> 0 | ... Q21: =SUMIF(Timing!$C$6:$Q$6,Q7,Timing!$C$22:$Q$22) -> 0
A22: Operational revenue (from P&L) | D22: {=IFERROR(INDEX('P&L'!$G$28:$S$28,MATCH(D$7,'P&L'!$G$6:$S$6,0)),0)} -> 0 | E22: {=IFERROR(INDEX('P&L'!$G$28:$S$28,MATCH(E$7,'P&L'!$G$6:$S$6,0)),0)} -> 0 | F22: {=IFERROR(INDEX('P&L'!$G$28:$S$28,MATCH(F$7,'P&L'!$G$6:$S$6,0)),0)} -> 0 | G22: {=IFERROR(INDEX('P&L'!$G$28:$S$28,MATCH(G$7,'P&L'!$G$6:$S$6,0)),0)} -> 18772333 | H22: {=IFERROR(INDEX('P&L'!$G$28:$S$28,MATCH(H$7,'P&L'!$G$6:$S$6,0)),0)} -> 19676502 | I22: {=IFERROR(INDEX('P&L'!$G$28:$S$28,MATCH(I$7,'P&L'!$G$6:$S$6,0)),0)} -> 20615522 | J22: {=IFERROR(INDEX('P&L'!$G$28:$S$28,MATCH(J$7,'P&L'!$G$6:$S$6,0)),0)} -> 21808635 | K22: {=IFERROR(INDEX('P&L'!$G$28:$S$28,MATCH(K$7,'P&L'!$G$6:$S$6,0)),0)} -> 22300757 | ... O22: {=IFERROR(INDEX('P&L'!$G$28:$S$28,MATCH(O$7,'P&L'!$G$6:$S$6,0)),0)} -> 24417930 | P22: {=IFERROR(INDEX('P&L'!$G$28:$T$28,MATCH(P$7,'P&L'!$G$6:$T$6,0)),0)} -> 24986615 | Q22: {=IFERROR(INDEX('P&L'!$G$28:$T$28,MATCH(Q$7,'P&L'!$G$6:$T$6,0)),0)} -> 25571992
A23: Total inflows | D23: =D16+D18+D20+D21+D22 -> 0 | E23: =E16+E18+E20+E21+E22 -> 0 | F23: =F16+F18+F20+F21+F22+F19 -> 22496298 | G23: =G16+G18+G20+G21+G22 -> 18772333 | H23: =H16+H18+H20+H21+H22 -> 19676502 | I23: =I16+I18+I20+I21+I22 -> 20615522 | J23: =J16+J18+J20+J21+J22 -> 21808635 | K23: =K16+K18+K20+K21+K22 -> 22300757 | L23: =L16+L18+L20+L21+L22 -> 22807316 | M23: =M16+M18+M20+M21+M22 -> 23328738 | N23: =N16+N18+N20+N21+N22 -> 23865459 | ... Q23: =Q16+Q18+Q20+Q21+Q22 -> 25571992
A24: Terminal value + bond return | D24: =IF(D$7=Inputs!$E$488,D64*Valuations!$C$15,0) -> 0 | E24: =IF(E$7=Inputs!$E$488,E64*Valuations!$C$15,0) -> 0 | F24: =IF(F$7=Inputs!$E$488,F64*Valuations!$C$15,0) -> 0 | G24: =IF(G$7=Inputs!$E$488,G64*Valuations!$C$15,0) -> 0 | H24: =IF(H$7=Inputs!$E$488,H64*Valuations!$C$15,0) -> 0 | I24: =IF(I$7=Inputs!$E$488,I64*Valuations!$C$15,0) -> 0 | J24: =IF(J$7=Inputs!$E$488,J64*Valuations!$C$15,0) -> 0 | K24: =IF(K$7=Inputs!$E$488,K64*Valuations!$C$15,0) -> 0 | ... Q24: =IF(Q$7=Inputs!$E$488,Q64*Valuations!$C$15,0) -> 97309399
A26: OUTFLOWS (shown as negatives)
A27: Capex (from Construction Timeline) + Lease Deposit | D27: =-'Construction Timeline'!D227 -> 0 | E27: =-'Construction Timeline'!E227 -> 0 | F27: =-'Construction Timeline'!F227-'Construction Timeline'!F219 -> -20580525 | G27: =-'Construction Timeline'!G227 -> 0 | H27: =-'Construction Timeline'!H227 -> 0 | I27: =-'Construction Timeline'!I227 -> 0 | J27: =-'Construction Timeline'!J227 -> 0 | K27: =-'Construction Timeline'!K227 -> 0 | L27: =-'Construction Timeline'!L227 -> 0 | M27: =-'Construction Timeline'!M227 -> 0 | N27: =-'Construction Timeline'!N227 -> 0 | O27: =-'Construction Timeline'!O227 -> 0 | P27: =0 -> 0 | Q27: =0 -> 0
A28: Pre-op expenses excl. capex (from Cashflow) | D28: =-SUMIF(Timing!$C$6:$Q$6,D7,Timing!$C$23:$Q$23) -> 0 | E28: =-SUMIF(Timing!$C$6:$Q$6,E7,Timing!$C$23:$Q$23) -> 0 | F28: =-SUMIF(Timing!$C$6:$Q$6,F7,Timing!$C$23:$Q$23) -> 0 | G28: =-SUMIF(Timing!$C$6:$Q$6,G7,Timing!$C$23:$Q$23) -> 0 | H28: =-SUMIF(Timing!$C$6:$Q$6,H7,Timing!$C$23:$Q$23) -> 0 | I28: =-SUMIF(Timing!$C$6:$Q$6,I7,Timing!$C$23:$Q$23) -> 0 | J28: =-SUMIF(Timing!$C$6:$Q$6,J7,Timing!$C$23:$Q$23) -> 0 | K28: =-SUMIF(Timing!$C$6:$Q$6,K7,Timing!$C$23:$Q$23) -> 0 | ... Q28: =-SUMIF(Timing!$C$6:$Q$6,Q7,Timing!$C$23:$Q$23) -> 0
A29: COGS +Operating expenses (excl lease/outgoings) + Hold Co Fees – from P&L | D29: {=IFERROR(-(INDEX('P&L'!$G$74:$R$74,MATCH(D$7,'P&L'!$G$6:$R$6,0))-INDEX('P&L'!$G$58:$R$58,MATCH(D$7,'P&L'!$G$6:$R$6,0))-INDEX('P&L'!$G$59:$R$59,MATCH(D$7,'P&L'!$G$6:$R$6,0))+INDEX('P&L'!$G$35:$R$35,MATCH(D$7,'P&L'!$G$6:$R$6,0))+INDEX('P&L'!$G$77:$R$77,MATCH(D$7,'P&L'!$G$6:$R$6,0))),0)} -> 0 | E29: {=IFERROR(-(INDEX('P&L'!$G$74:$R$74,MATCH(E$7,'P&L'!$G$6:$R$6,0))-INDEX('P&L'!$G$58:$R$58,MATCH(E$7,'P&L'!$G$6:$R$6,0))-INDEX('P&L'!$G$59:$R$59,MATCH(E$7,'P&L'!$G$6:$R$6,0))+INDEX('P&L'!$G$35:$R$35,MATCH(E$7,'P&L'!$G$6:$R$6,0))+INDEX('P&L'!$G$77:$R$77,MATCH(E$7,'P&L'!$G$6:$R$6,0))),0)} -> 0 | F29: {=IFERROR(-(INDEX('P&L'!$G$74:$R$74,MATCH(F$7,'P&L'!$G$6:$R$6,0))-INDEX('P&L'!$G$58:$R$58,MATCH(F$7,'P&L'!$G$6:$R$6,0))-INDEX('P&L'!$G$59:$R$59,MATCH(F$7,'P&L'!$G$6:$R$6,0))+INDEX('P&L'!$G$35:$R$35,MATCH(F$7,'P&L'!$G$6:$R$6,0))+INDEX('P&L'!$G$77:$R$77,MATCH(F$7,'P&L'!$G$6:$R$6,0))),0)} -> -920383.09 | G29: {=IFERROR(-(INDEX('P&L'!$G$74:$R$74,MATCH(G$7,'P&L'!$G$6:$R$6,0))-INDEX('P&L'!$G$58:$R$58,MATCH(G$7,'P&L'!$G$6:$R$6,0))-INDEX('P&L'!$G$59:$R$59,MATCH(G$7,'P&L'!$G$6:$R$6,0))+INDEX('P&L'!$G$35:$R$35,MATCH(G$7,'P&L'!$G$6:$R$6,0))+INDEX('P&L'!$G$77:$R$77,MATCH(G$7,'P&L'!$G$6:$R$6,0))),0)} -> -8531980.2 | H29: {=IFERROR(-(INDEX('P&L'!$G$74:$R$74,MATCH(H$7,'P&L'!$G$6:$R$6,0))-INDEX('P&L'!$G$58:$R$58,MATCH(H$7,'P&L'!$G$6:$R$6,0))-INDEX('P&L'!$G$59:$R$59,MATCH(H$7,'P&L'!$G$6:$R$6,0))+INDEX('P&L'!$G$35:$R$35,MATCH(H$7,'P&L'!$G$6:$R$6,0))+INDEX('P&L'!$G$77:$R$77,MATCH(H$7,'P&L'!$G$6:$R$6,0))),0)} -> -9023210.4 | I29: {=IFERROR(-(INDEX('P&L'!$G$74:$R$74,MATCH(I$7,'P&L'!$G$6:$R$6,0))-INDEX('P&L'!$G$58:$R$58,MATCH(I$7,'P&L'!$G$6:$R$6,0))-INDEX('P&L'!$G$59:$R$59,MATCH(I$7,'P&L'!$G$6:$R$6,0))+INDEX('P&L'!$G$35:$R$35,MATCH(I$7,'P&L'!$G$6:$R$6,0))+INDEX('P&L'!$G$77:$R$77,MATCH(I$7,'P&L'!$G$6:$R$6,0))),0)} -> -9402844.5 | J29: {=IFERROR(-(INDEX('P&L'!$G$74:$R$74,MATCH(J$7,'P&L'!$G$6:$R$6,0))-INDEX('P&L'!$G$58:$R$58,MATCH(J$7,'P&L'!$G$6:$R$6,0))-INDEX('P&L'!$G$59:$R$59,MATCH(J$7,'P&L'!$G$6:$R$6,0))+INDEX('P&L'!$G$35:$R$35,MATCH(J$7,'P&L'!$G$6:$R$6,0))+INDEX('P&L'!$G$77:$R$77,MATCH(J$7,'P&L'!$G$6:$R$6,0))),0)} -> -9702415.9 | K29: {=IFERROR(-(INDEX('P&L'!$G$74:$R$74,MATCH(K$7,'P&L'!$G$6:$R$6,0))-INDEX('P&L'!$G$58:$R$58,MATCH(K$7,'P&L'!$G$6:$R$6,0))-INDEX('P&L'!$G$59:$R$59,MATCH(K$7,'P&L'!$G$6:$R$6,0))+INDEX('P&L'!$G$35:$R$35,MATCH(K$7,'P&L'!$G$6:$R$6,0))+INDEX('P&L'!$G$77:$R$77,MATCH(K$7,'P&L'!$G$6:$R$6,0))),0)} -> -9954966 | ... O29: {=IFERROR(-(INDEX('P&L'!$G$74:$R$74,MATCH(O$7,'P&L'!$G$6:$R$6,0))-INDEX('P&L'!$G$58:$R$58,MATCH(O$7,'P&L'!$G$6:$R$6,0))-INDEX('P&L'!$G$59:$R$59,MATCH(O$7,'P&L'!$G$6:$R$6,0))+INDEX('P&L'!$G$35:$R$35,MATCH(O$7,'P&L'!$G$6:$R$6,0))+INDEX('P&L'!$G$77:$R$77,MATCH(O$7,'P&L'!$G$6:$R$6,0))),0)} -> -11214704 | P29: {=IFERROR(-(INDEX('P&L'!$G$74:$T$74,MATCH(P$7,'P&L'!$G$6:$T$6,0))-INDEX('P&L'!$G$58:$T$58,MATCH(P$7,'P&L'!$G$6:$T$6,0))-INDEX('P&L'!$G$59:$T$59,MATCH(P$7,'P&L'!$G$6:$T$6,0))+INDEX('P&L'!$G$35:$T$35,MATCH(P$7,'P&L'!$G$6:$T$6,0))+INDEX('P&L'!$G$77:$T$77,MATCH(P$7,'P&L'!$G$6:$T$6,0))),0)} -> -11603059 | Q29: {=IFERROR(-(INDEX('P&L'!$G$74:$T$74,MATCH(Q$7,'P&L'!$G$6:$T$6,0))-INDEX('P&L'!$G$58:$T$58,MATCH(Q$7,'P&L'!$G$6:$T$6,0))-INDEX('P&L'!$G$59:$T$59,MATCH(Q$7,'P&L'!$G$6:$T$6,0))+INDEX('P&L'!$G$35:$T$35,MATCH(Q$7,'P&L'!$G$6:$T$6,0))+INDEX('P&L'!$G$77:$T$77,MATCH(Q$7,'P&L'!$G$6:$T$6,0))),0)} -> -11139414
A30: Lease payments (venue lease + outgoings) – from P&L | D30: {=IFERROR(-(INDEX('P&L'!$G$58:$R$58,MATCH(D$7,'P&L'!$G$6:$R$6,0))+INDEX('P&L'!$G$59:$R$59,MATCH(D$7,'P&L'!$G$6:$R$6,0))),0)} -> 0 | E30: {=IFERROR(-(INDEX('P&L'!$G$58:$R$58,MATCH(E$7,'P&L'!$G$6:$R$6,0))+INDEX('P&L'!$G$59:$R$59,MATCH(E$7,'P&L'!$G$6:$R$6,0))),0)} -> 0 | F30: {=IFERROR(-(INDEX('P&L'!$G$58:$R$58,MATCH(F$7,'P&L'!$G$6:$R$6,0))+INDEX('P&L'!$G$59:$R$59,MATCH(F$7,'P&L'!$G$6:$R$6,0))),0)} -> 0 | G30: {=IFERROR(-(INDEX('P&L'!$G$58:$R$58,MATCH(G$7,'P&L'!$G$6:$R$6,0))+INDEX('P&L'!$G$59:$R$59,MATCH(G$7,'P&L'!$G$6:$R$6,0))),0)} -> 0 | H30: {=IFERROR(-(INDEX('P&L'!$G$58:$R$58,MATCH(H$7,'P&L'!$G$6:$R$6,0))+INDEX('P&L'!$G$59:$R$59,MATCH(H$7,'P&L'!$G$6:$R$6,0))),0)} -> -431681.25 | I30: {=IFERROR(-(INDEX('P&L'!$G$58:$R$58,MATCH(I$7,'P&L'!$G$6:$R$6,0))+INDEX('P&L'!$G$59:$R$59,MATCH(I$7,'P&L'!$G$6:$R$6,0))),0)} -> -486033.84 | J30: {=IFERROR(-(INDEX('P&L'!$G$58:$R$58,MATCH(J$7,'P&L'!$G$6:$R$6,0))+INDEX('P&L'!$G$59:$R$59,MATCH(J$7,'P&L'!$G$6:$R$6,0))),0)} -> -503045.03 | K30: {=IFERROR(-(INDEX('P&L'!$G$58:$R$58,MATCH(K$7,'P&L'!$G$6:$R$6,0))+INDEX('P&L'!$G$59:$R$59,MATCH(K$7,'P&L'!$G$6:$R$6,0))),0)} -> -520651.6 | ... O30: {=IFERROR(-(INDEX('P&L'!$G$58:$R$58,MATCH(O$7,'P&L'!$G$6:$R$6,0))+INDEX('P&L'!$G$59:$R$59,MATCH(O$7,'P&L'!$G$6:$R$6,0))),0)} -> -1194919.4 | P30: {=IFERROR(-(INDEX('P&L'!$G$58:$T$58,MATCH(P$7,'P&L'!$G$6:$T$6,0))+INDEX('P&L'!$G$59:$T$59,MATCH(P$7,'P&L'!$G$6:$T$6,0))),0)} -> -1236741.6 | Q30: {=IFERROR(-(INDEX('P&L'!$G$58:$T$58,MATCH(Q$7,'P&L'!$G$6:$T$6,0))+INDEX('P&L'!$G$59:$T$59,MATCH(Q$7,'P&L'!$G$6:$T$6,0))),0)} -> -531234.67
A31: Debt service (principal + interest) – cash (from Debt) | D31: {=IFERROR(-INDEX(Debt!$H$120:$S$120,MATCH(D$7,Debt!$H$14:$S$14,0))+IF(D$5<Inputs!$E$22,INDEX(Debt!$H$119:$S$119,MATCH(D$7,Debt!$H$14:$S$14,0)),0),0)} -> 0 | E31: {=IFERROR(-INDEX(Debt!$H$120:$S$120,MATCH(E$7,Debt!$H$14:$S$14,0))+IF(E$5<Inputs!$E$22,INDEX(Debt!$H$119:$S$119,MATCH(E$7,Debt!$H$14:$S$14,0)),0),0)} -> 0 | F31: =-Debt!J120 -> -543161.6 | G31: {=IFERROR(-INDEX(Debt!$H$120:$S$120,MATCH(G$7,Debt!$H$14:$S$14,0))+IF(G$5<Inputs!$E$22,INDEX(Debt!$H$119:$S$119,MATCH(G$7,Debt!$H$14:$S$14,0)),0),0)} -> -1900198.2 | H31: {=IFERROR(-INDEX(Debt!$H$120:$S$120,MATCH(H$7,Debt!$H$14:$S$14,0))+IF(H$5<Inputs!$E$22,INDEX(Debt!$H$119:$S$119,MATCH(H$7,Debt!$H$14:$S$14,0)),0),0)} -> -2535183 | I31: {=IFERROR(-INDEX(Debt!$H$120:$S$120,MATCH(I$7,Debt!$H$14:$S$14,0))+IF(I$5<Inputs!$E$22,INDEX(Debt!$H$119:$S$119,MATCH(I$7,Debt!$H$14:$S$14,0)),0),0)} -> -2408423.9 | J31: {=IFERROR(-INDEX(Debt!$H$120:$S$120,MATCH(J$7,Debt!$H$14:$S$14,0))+IF(J$5<Inputs!$E$22,INDEX(Debt!$H$119:$S$119,MATCH(J$7,Debt!$H$14:$S$14,0)),0),0)} -> -2281664.7 | K31: {=IFERROR(-INDEX(Debt!$H$120:$S$120,MATCH(K$7,Debt!$H$14:$S$14,0))+IF(K$5<Inputs!$E$22,INDEX(Debt!$H$119:$S$119,MATCH(K$7,Debt!$H$14:$S$14,0)),0),0)} -> -2154905.5 | L31: {=IFERROR(-INDEX(Debt!$H$120:$S$120,MATCH(L$7,Debt!$H$14:$S$14,0))+IF(L$5<Inputs!$E$22,INDEX(Debt!$H$119:$S$119,MATCH(L$7,Debt!$H$14:$S$14,0)),0),0)} -> -2028146.4 | M31: {=IFERROR(-INDEX(Debt!$H$120:$S$120,MATCH(M$7,Debt!$H$14:$S$14,0))+IF(M$5<Inputs!$E$22,INDEX(Debt!$H$119:$S$119,MATCH(M$7,Debt!$H$14:$S$14,0)),0),0)} -> -1901387.2 | N31: {=IFERROR(-INDEX(Debt!$H$120:$S$120,MATCH(N$7,Debt!$H$14:$S$14,0))+IF(N$5<Inputs!$E$22,INDEX(Debt!$H$119:$S$119,MATCH(N$7,Debt!$H$14:$S$14,0)),0),0)} -> -1774628.1 | O31: {=IFERROR(-INDEX(Debt!$H$120:$S$120,MATCH(O$7,Debt!$H$14:$S$14,0))+IF(O$5<Inputs!$E$22,INDEX(Debt!$H$119:$S$119,MATCH(O$7,Debt!$H$14:$S$14,0)),0),0)} -> -1647868.9 | P31: {=IFERROR(-INDEX(Debt!$H$120:$U$120,MATCH(P$7,Debt!$H$14:$U$14,0))+IF(P$5<Inputs!$E$22,INDEX(Debt!$H$119:$U$119,MATCH(P$7,Debt!$H$14:$U$14,0)),0),0)} -> 0 | Q31: {=IFERROR(-INDEX(Debt!$H$120:$U$120,MATCH(Q$7,Debt!$H$14:$U$14,0))+IF(Q$5<Inputs!$E$22,INDEX(Debt!$H$119:$U$119,MATCH(Q$7,Debt!$H$14:$U$14,0)),0),0)} -> 0
A32: Taxes (from P&L if modelled) | D32: {=-INDEX('P&L'!$G$91:$R$91,MATCH(D$7,'P&L'!$G$6:$R$6,0))} -> 0 | E32: {=-INDEX('P&L'!$G$91:$R$91,MATCH(E$7,'P&L'!$G$6:$R$6,0))} -> 0 | F32: {=-INDEX('P&L'!$G$91:$R$91,MATCH(F$7,'P&L'!$G$6:$R$6,0))} -> 0 | G32: {=-INDEX('P&L'!$G$91:$R$91,MATCH(G$7,'P&L'!$G$6:$R$6,0))} -> -2021560.2 | H32: {=-INDEX('P&L'!$G$91:$R$91,MATCH(H$7,'P&L'!$G$6:$R$6,0))} -> -2484852.2 | I32: {=-INDEX('P&L'!$G$91:$R$91,MATCH(I$7,'P&L'!$G$6:$R$6,0))} -> -2674389.8 | J32: {=-INDEX('P&L'!$G$91:$R$91,MATCH(J$7,'P&L'!$G$6:$R$6,0))} -> -2975376.6 | K32: {=-INDEX('P&L'!$G$91:$R$91,MATCH(K$7,'P&L'!$G$6:$R$6,0))} -> -3079994 | ... O32: {=-INDEX('P&L'!$G$91:$R$91,MATCH(O$7,'P&L'!$G$6:$R$6,0))} -> -3287055.3 | P32: {=-INDEX('P&L'!$G$91:$T$91,MATCH(P$7,'P&L'!$G$6:$T$6,0))} -> -3347621.5 | Q32: {=-INDEX('P&L'!$G$91:$T$91,MATCH(Q$7,'P&L'!$G$6:$T$6,0))} -> -3873979.9
A33: Dividends | D33: {=-INDEX('P&L'!$G$104:$R$104,MATCH(D$7,'P&L'!$G$6:$R$6,0))} -> 0 | E33: {=-INDEX('P&L'!$G$105:$T$105,MATCH(E$7,'P&L'!$G$6:$T$6,0))} -> 0 | F33: {=-INDEX('P&L'!$G$105:$T$105,MATCH(F$7,'P&L'!$G$6:$T$6,0))} -> 0 | G33: {=-INDEX('P&L'!$G$105:$T$105,MATCH(G$7,'P&L'!$G$6:$T$6,0))} -> -3847688.2 | H33: {=-INDEX('P&L'!$G$105:$T$105,MATCH(H$7,'P&L'!$G$6:$T$6,0))} -> -4625550.2 | I33: {=-INDEX('P&L'!$G$105:$T$105,MATCH(I$7,'P&L'!$G$6:$T$6,0))} -> -4933391.9 | J33: {=-INDEX('P&L'!$G$105:$T$105,MATCH(J$7,'P&L'!$G$6:$T$6,0))} -> -5478014.2 | K33: {=-INDEX('P&L'!$G$105:$T$105,MATCH(K$7,'P&L'!$G$6:$T$6,0))} -> -5724980.5 | L33: {=-INDEX('P&L'!$G$105:$T$105,MATCH(L$7,'P&L'!$G$6:$T$6,0))} -> -5653138 | ... Q33: {=-INDEX('P&L'!$G$105:$T$105,MATCH(Q$7,'P&L'!$G$6:$T$6,0))} -> -7152677.1
A34: Transfer to Community Fund (Restricted Cash) | D34: {=IFERROR(-INDEX('P&L'!$G$102:$R$102,MATCH(D$7,'P&L'!$G$6:$R$6,0)),0)} -> 0 | E34: {=IFERROR(-INDEX('P&L'!$G$102:$R$102,MATCH(E$7,'P&L'!$G$6:$R$6,0)),0)} -> 0 | F34: {=IFERROR(-INDEX('P&L'!$G$102:$R$102,MATCH(F$7,'P&L'!$G$6:$R$6,0)),0)} -> 0 | G34: {=IFERROR(-INDEX('P&L'!$G$102:$R$102,MATCH(G$7,'P&L'!$G$6:$R$6,0)),0)} -> -101622.77 | H34: {=IFERROR(-INDEX('P&L'!$G$102:$R$102,MATCH(H$7,'P&L'!$G$6:$R$6,0)),0)} -> -103780.13 | I34: {=IFERROR(-INDEX('P&L'!$G$102:$R$102,MATCH(I$7,'P&L'!$G$6:$R$6,0)),0)} -> -105937.49 | J34: {=IFERROR(-INDEX('P&L'!$G$102:$R$102,MATCH(J$7,'P&L'!$G$6:$R$6,0)),0)} -> -113545 | K34: {=IFERROR(-INDEX('P&L'!$G$102:$R$102,MATCH(K$7,'P&L'!$G$6:$R$6,0)),0)} -> -113545 | ... O34: {=IFERROR(-INDEX('P&L'!$G$102:$R$102,MATCH(O$7,'P&L'!$G$6:$R$6,0)),0)} -> -113545 | P34: {=IFERROR(-INDEX('P&L'!$G$102:$T$102,MATCH(P$7,'P&L'!$G$6:$T$6,0)),0)} -> -113545 | Q34: {=IFERROR(-INDEX('P&L'!$G$102:$T$102,MATCH(Q$7,'P&L'!$G$6:$T$6,0)),0)} -> -113545
A35: Total outflows | D35: =D27+D28+D29+D30+D31+D32+D33+D34 -> 0 | E35: =E27+E28+E29+E30+E31+E32+E33+E34 -> 0 | F35: =F27+F28+F29+F30+F31+F32+F33+F34 -> -22044070 | G35: =G27+G28+G29+G30+G31+G32+G33+G34 -> -16403050 | H35: =H27+H28+H29+H30+H31+H32+H33+H34 -> -19204257 | I35: =I27+I28+I29+I30+I31+I32+I33+I34 -> -20011021 | J35: =J27+J28+J29+J30+J31+J32+J33+J34 -> -21054061 | K35: =K27+K28+K29+K30+K31+K32+K33+K34 -> -21549043 | ... Q35: =Q27+Q28+Q29+Q30+Q31+Q32+Q33+Q34 -> -22810851
A36: Net working capital movement (ΔWC) | D36: =D61 -> 0 | E36: =E61 -> 0 | F36: =F61 -> 0 | G36: =G61 -> -1096726.6 | H36: =H61 -> -12840.594 | I36: =I61 -> -58802.416 | J36: =J61 -> -76022.193 | K36: =K61 -> -24341.653 | ... Q36: =Q61 -> -78752.097
A37: Net Cash Flow | D37: =D23+D35+D36 -> 0 | E37: =E23+E35+E36 -> 0 | F37: =F23+F35+F36 -> 452228.4 | G37: =G23+G35+G36 -> 1272557.2 | H37: =H23+H35+H36 -> 459404.45 | I37: =I23+I35+I36 -> 545697.98 | J37: =J23+J35+J36 -> 678550.96 | K37: =K23+K35+K36 -> 727372.41 | ... Q37: =Q23+Q35+Q36 -> 2682388.6
A38: Closing Cash Balance | D38: =D10+D37 -> 0 | E38: =E10+E37 -> 0 | F38: =F10+F37 -> 452228.4 | G38: =G10+G37 -> 1724785.6 | H38: =H10+H37 -> 2184190 | I38: =I10+I37 -> 2729888 | J38: =J10+J37 -> 3408439 | K38: =K10+K37 -> 4135811.4 | ... Q38: =Q10+Q37 -> 12278575
A39: Cash tie (CFS - BS cash) | D39: =D38-'Balance Sheet'!F10 -> 0 | E39: =E38-'Balance Sheet'!G10 -> 0 | F39: =F38-'Balance Sheet'!H10 -> 0 | G39: =G38-'Balance Sheet'!I10 -> 0 | H39: =H38-'Balance Sheet'!J10 -> 0 | I39: =I38-'Balance Sheet'!K10 -> 0 | J39: =J38-'Balance Sheet'!L10 -> 0 | K39: =K38-'Balance Sheet'!M10 -> 0 | ... Q39: =Q38-'Balance Sheet'!S10 -> 0
A40: Cash tie (Waterfall - BS cash) | D40: =D10+D37-D38 -> 0 | E40: =E10+E37-E38 -> 0 | F40: =F10+F37-F38 -> 0 | G40: =G10+G37-G38 -> 0 | H40: =H10+H37-H38 -> 0 | I40: =I10+I37-I38 -> 0 | J40: =J10+J37-J38 -> 0 | K40: =K10+K37-K38 -> 0 | ... Q40: =Q10+Q37-Q38 -> 0
A43: Year | D43: =D7 -> FY25 | E43: =E7 -> FY26 | F43: =F7 -> FY27 | G43: =G7 -> FY28 | H43: =H7 -> FY29 | I43: =I7 -> FY30 | J43: =J7 -> FY31 | K43: =K7 -> FY32 | ... Q43: =Q7 -> FY38
A44: FY Start | D44: =D5 -> 45689 | E44: =E5 -> 45839 | F44: =F5 -> 46204 | G44: =G5 -> 46569 | H44: =H5 -> 46935 | I44: =I5 -> 47300 | J44: =J5 -> 47665 | K44: =K5 -> 48030 | ... Q44: =Q5 -> 50222
A45: FY End | D45: =D6 -> 45838 | E45: =E6 -> 46203 | F45: =F6 -> 46568 | G45: =G6 -> 46934 | H45: =H6 -> 47299 | I45: =I6 -> 47664 | J45: =J6 -> 48029 | K45: =K6 -> 48395 | ... Q45: =Q6 -> 50586
A47: DRIVERS
A48: Revenue | D48: {=IFERROR(INDEX('P&L'!$G$28:$R$28,MATCH(D$7,'P&L'!$G$6:$R$6,0)),0)} -> 0 | E48: {=IFERROR(INDEX('P&L'!$G$28:$R$28,MATCH(E$7,'P&L'!$G$6:$R$6,0)),0)} -> 0 | F48: {=IFERROR(INDEX('P&L'!$G$28:$R$28,MATCH(F$7,'P&L'!$G$6:$R$6,0)),0)} -> 0 | G48: {=IFERROR(INDEX('P&L'!$G$28:$R$28,MATCH(G$7,'P&L'!$G$6:$R$6,0)),0)} -> 18772333 | H48: {=IFERROR(INDEX('P&L'!$G$28:$R$28,MATCH(H$7,'P&L'!$G$6:$R$6,0)),0)} -> 19676502 | I48: {=IFERROR(INDEX('P&L'!$G$28:$R$28,MATCH(I$7,'P&L'!$G$6:$R$6,0)),0)} -> 20615522 | J48: {=IFERROR(INDEX('P&L'!$G$28:$R$28,MATCH(J$7,'P&L'!$G$6:$R$6,0)),0)} -> 21808635 | K48: {=IFERROR(INDEX('P&L'!$G$28:$R$28,MATCH(K$7,'P&L'!$G$6:$R$6,0)),0)} -> 22300757 | ... O48: {=IFERROR(INDEX('P&L'!$G$28:$R$28,MATCH(O$7,'P&L'!$G$6:$R$6,0)),0)} -> 24417930 | P48: {=IFERROR(INDEX('P&L'!$G$28:$T$28,MATCH(P$7,'P&L'!$G$6:$T$6,0)),0)} -> 24986615 | Q48: {=IFERROR(INDEX('P&L'!$G$28:$T$28,MATCH(Q$7,'P&L'!$G$6:$T$6,0)),0)} -> 25571992
A49: COGS | D49: {=IFERROR(INDEX('P&L'!$G$35:$R$35,MATCH(D$7,'P&L'!$G$6:$R$6,0)),0)} -> 0 | E49: {=IFERROR(INDEX('P&L'!$G$35:$R$35,MATCH(E$7,'P&L'!$G$6:$R$6,0)),0)} -> 0 | F49: {=IFERROR(INDEX('P&L'!$G$35:$R$35,MATCH(F$7,'P&L'!$G$6:$R$6,0)),0)} -> 0 | G49: {=IFERROR(INDEX('P&L'!$G$35:$R$35,MATCH(G$7,'P&L'!$G$6:$R$6,0)),0)} -> 2168980.6 | H49: {=IFERROR(INDEX('P&L'!$G$35:$R$35,MATCH(H$7,'P&L'!$G$6:$R$6,0)),0)} -> 2325901.7 | I49: {=IFERROR(INDEX('P&L'!$G$35:$R$35,MATCH(I$7,'P&L'!$G$6:$R$6,0)),0)} -> 2489948.7 | J49: {=IFERROR(INDEX('P&L'!$G$35:$R$35,MATCH(J$7,'P&L'!$G$6:$R$6,0)),0)} -> 2536926.4 | K49: {=IFERROR(INDEX('P&L'!$G$35:$R$35,MATCH(K$7,'P&L'!$G$6:$R$6,0)),0)} -> 2611117.8 | ... O49: {=IFERROR(INDEX('P&L'!$G$35:$R$35,MATCH(O$7,'P&L'!$G$6:$R$6,0)),0)} -> 2930818.3 | P49: {=IFERROR(INDEX('P&L'!$G$35:$T$35,MATCH(P$7,'P&L'!$G$6:$T$6,0)),0)} -> 3016826.4 | Q49: {=IFERROR(INDEX('P&L'!$G$35:$T$35,MATCH(Q$7,'P&L'!$G$6:$T$6,0)),0)} -> 3105414.7
...

Sheet P&L
A1: Profit & Loss Statement
A2: THE BEND Live House
F4: FY START | G4: 45689 | H4: =G5+1 -> 45839 | I4: =H5+1 -> 46204 | J4: =I5+1 -> 46569 | K4: =J5+1 -> 46935 | L4: =K5+1 -> 47300 | M4: =L5+1 -> 47665 | N4: =M5+1 -> 48030 | O4: =N5+1 -> 48396 | ... T4: =S5+1 -> 50222
F5: FY END | G5: =DATE(YEAR(G4) + (MONTH(G4)>=7), 6, 30) -> 45838 | H5: =DATE(YEAR(H4) + (MONTH(H4)>=7), 6, 30) -> 46203 | I5: =DATE(YEAR(I4) + (MONTH(I4)>=7), 6, 30) -> 46568 | J5: =DATE(YEAR(J4) + (MONTH(J4)>=7), 6, 30) -> 46934 | K5: =DATE(YEAR(K4) + (MONTH(K4)>=7), 6, 30) -> 47299 | L5: =DATE(YEAR(L4) + (MONTH(L4)>=7), 6, 30) -> 47664 | M5: =DATE(YEAR(M4) + (MONTH(M4)>=7), 6, 30) -> 48029 | N5: =DATE(YEAR(N4) + (MONTH(N4)>=7), 6, 30) -> 48395 | ... T5: =DATE(YEAR(T4) + (MONTH(T4)>=7), 6, 30) -> 50586
