Workbook
Name Construction_End_Date: Inputs!$E$19
Name Construction_Start_Date: Inputs!$E$18
Name GanttView: 'GANTT – MASTER OPTIONS'!$C$3
Name Model_Start: [1]Inputs!$E$7
Name Model_start: Inputs!$E$9
Name Operations_Start_Date: Inputs!$E$22
Name ProjectStart: MIN(#REF!)
Name RM_BaseEventDays: Inputs!$E$139
Name RM_EventDaysScale: Inputs!$E$276
Name RM_ExitMultiple: Inputs!$E$261
Name RM_HourlyRate: Inputs!$E$223
Name RM_IO_Months: Inputs!$E$57
Name RM_OutgoingsPct: Inputs!$E$36
Name RM_ShiftHours: Inputs!$E$224
Name RM_StaffPerEvent: Inputs!$E$222
Name RM_SustCapexPct: Inputs!$E$246
Name RM_TerminalGrowth: Inputs!$E$265
Name RM_VHA_Cap: Inputs!$E$146
Name RM_VHA_GBO_Fee: Inputs!$E$145
Name SelectedLevel: 'GANTT – MASTER OPTIONS'!$C$7
Name ShowPhaseBands: 'GANTT – MASTER OPTIONS'!$C$10
Name ShowToday: 'GANTT – MASTER OPTIONS'!$C$9
Name TimeScaleSelection: 'GANTT – MASTER OPTIONS'!$C$5
Name Total_Initial_Capex: 'Construction Timeline'!$G$17

Sheet General Information
A1: Integrated Entertainment and Recreational Development
A2: 349 Bridge Street Melbourne
A3: Live House Music Venue - following our discussions there is a need for a 4,000 to 5,000 live venue for the Melbourne market that is suitably located to avoid issues of noise and congestion for the local community. The location within our proposed precinct will provide a beneficial location for this development and allow for the improved development of access to culture, music, entertainment and activity. We are looking forward to understanding more about this concept from you so that we may prepare a joint presentation to Council, Goodman and the State government teams involved in Sport, Education, Tourism, Planning and Labour.
A5: URWLD - an active leisure concept that will house a Sports Climbing Centre of Excellence as well as a range of 15-18 active leisure activities including surfing, scuba, ice climbing, sports climbing, bouldering, canyoning, coasteering, ninja, junior climb academy, and a range of VR activities such as skiing, snowboarding, squirrel suit, tennis, golf and other immersive game concepts. There will also be an eSports arena and concept area and interactive video games concepts. These will be supported by 4 quality, chef curated F&B concepts and 2 event venues. URWLD addresses a key community and society issue of encouraging the entire populace to be active to support lifestyle mindset change and impact the alarming trend of obesity, diabetes and inactivity that threatens our future generations. By providing an accessible environment to help introduce a broad range of activities that encourage movement we will work to address this through our communications and positioning as well as with our event activities, TedTalks hosted and others to promote improving mobility for all age groups
A7: PARKING - we are in discussions with Wilson Parking to JV on a 900 space parking building connected to URWLD to service the precinct as well as to support the government policy on congestion reduction within the CBD. We will provide business day parking with shuttle service into the CBD area to Spencer St transport hub for trains, trams and buses. In the future when the Plummer St Light Rail/Tram is undertaken by state government the proximity will allow us to reduce shuttle services. The parking building will connect to both the live venue and URWLD buildings
A9: COSM - we have an EOI with a group in Melbourne who are negotiating the license for COSM. This is a highly immersive sports and entertainment experience with also educational opportunities for day use. We believe it will be a highly successful component of the precinct. www.cosm.com
A11: Central Park - in keeping with the need for green space and open areas for common use we have allocated space within the site for a central park which we plan to develop with native landscape focus and a central courtyard as a "FOOD TRUCK" park highlighting handheld foods from numerous cultures as part of our F&B offering. This area will also be used for day time and evening buskers for entertainment.
A13: Employment and Community - We believe that our combined development will create almost 1,000 FTE jobs within our precinct and support the planned redevelopment of the Fishermans Bend Urban Renewal Framework by encouraging further state and federal investment in infrastructure of light rail, metro and roads as well as private investor development of the larger sites for increased residential and commercial use of the area.
A15: The zone we are developing will include, on a site of 34,400 square metres:

Sheet Dashboard
A1: PORT MELBOURNE LIVE HOUSE — EXECUTIVE DASHBOARD
A2: Port Melbourne Live House | P2: Active Scenario | Q2: =Scenarios!$B$4 -> Base
P3: Model Health | Q3: =IF('Model Checks'!B24=0,"OK","FAIL") -> OK
B5: Summary
B6: FY | C6: =IFERROR(Cashflow!D$7,"") -> FY25 | D6: =IFERROR(Cashflow!E$7,"") -> FY26 | E6: =IFERROR(Cashflow!F$7,"") -> FY27 | F6: =IFERROR(Cashflow!G$7,"") -> FY28 | G6: =IFERROR(Cashflow!H$7,"") -> FY29 | H6: =IFERROR(Cashflow!I$7,"") -> FY30 | I6: =IFERROR(Cashflow!J$7,"") -> FY31 | J6: =IFERROR(Cashflow!K$7,"") -> FY32 | ... N6: =IFERROR(Cashflow!O$7,"") -> FY36
B7: Revenue | C7: =IFERROR(Cashflow!D$47,"") -> 0 | D7: =IFERROR(Cashflow!E$47,"") -> 0 | E7: =IFERROR(Cashflow!F$47,"") -> 0 | F7: =IFERROR(Cashflow!G$47,"") -> 18192909 | G7: =IFERROR(Cashflow!H$47,"") -> 19173295 | H7: =IFERROR(Cashflow!I$47,"") -> 20282270 | I7: =IFERROR(Cashflow!J$47,"") -> 20817159 | J7: =IFERROR(Cashflow!K$47,"") -> 21296978 | ... N7: =IFERROR(Cashflow!O$47,"") -> 23361053
B8: EBITDA | C8: =IFERROR(Cashflow!D$63,"") -> 0 | D8: =IFERROR(Cashflow!E$63,"") -> 0 | E8: =IFERROR(Cashflow!F$63,"") -> 0 | F8: =IFERROR(Cashflow!G$63,"") -> 13999302 | G8: =IFERROR(Cashflow!H$63,"") -> 14401312 | H8: =IFERROR(Cashflow!I$63,"") -> 15322990 | I8: =IFERROR(Cashflow!J$63,"") -> 15770796 | J8: =IFERROR(Cashflow!K$63,"") -> 16058922 | ... N8: =IFERROR(Cashflow!O$63,"") -> 16893778
B9: Closing Cash | C9: =IFERROR(Cashflow!D37,"") -> 0 | D9: =IFERROR(Cashflow!E37,"") -> 1707500 | E9: =IFERROR(Cashflow!F37,"") -> 16050500 | F9: =IFERROR(Cashflow!G37,"") -> -1231018.3 | G9: =IFERROR(Cashflow!H37,"") -> -396007.99 | H9: =IFERROR(Cashflow!I37,"") -> 513409.17 | I9: =IFERROR(Cashflow!J37,"") -> 1533142.7 | J9: =IFERROR(Cashflow!K37,"") -> 2307422.4 | ... N9: =IFERROR(Cashflow!O37,"") -> 1.4219797e+08
B10: Total Debt | C10: =IFERROR(Debt!H48,0) -> 0 | D10: =IFERROR(Debt!I48,0) -> 0 | E10: =IFERROR(Debt!J48,0) -> 9220500 | F10: =IFERROR(Debt!K48,0) -> 8196000 | G10: =IFERROR(Debt!L48,0) -> 7171500 | H10: =IFERROR(Debt!M48,0) -> 6147000 | I10: =IFERROR(Debt!N48,0) -> 5122500 | J10: =IFERROR(Debt!O48,0) -> 4098000 | ... N10: =IFERROR(Debt!S48,0) -> 0
B11: DSCR | C11: ='P&L'!H106 | D11: ='P&L'!I106 | E11: ='P&L'!J106 -> 0 | F11: ='P&L'!K106 -> 8.3450465 | G11: ='P&L'!L106 -> 9.0195084 | H11: ='P&L'!M106 -> 10.100328 | I11: ='P&L'!N106 -> 10.972249 | J11: ='P&L'!O106 -> 11.831354 | ... N11: ='P&L'!S106 -> 16.294063
B12: ICR | C12: =IFERROR(IF(Debt!H$57=0,"",Cashflow!D$63/Debt!H$57),"") | D12: =IFERROR(IF(Debt!I$57=0,"",Cashflow!E$63/Debt!I$57),"") | E12: =IFERROR(IF(Debt!J$57=0,"",Cashflow!F$63/Debt!J$57),"") -> 0 | F12: =IFERROR(IF(Debt!K$57=0,"",Cashflow!G$63/Debt!K$57),"") -> 20.094884 | G12: =IFERROR(IF(Debt!L$57=0,"",Cashflow!H$63/Debt!L$57),"") -> 23.428196 | H12: =IFERROR(IF(Debt!M$57=0,"",Cashflow!I$63/Debt!M$57),"") -> 28.762604 | I12: =IFERROR(IF(Debt!N$57=0,"",Cashflow!J$63/Debt!N$57),"") -> 34.985571 | J12: =IFERROR(IF(Debt!O$57=0,"",Cashflow!K$63/Debt!O$57),"") -> 43.541355 | ... N12: =IFERROR(IF(Debt!S$57=0,"",Cashflow!O$63/Debt!S$57),"") -> 412.24445
B13: Net Leverage (Net Debt/EBITDA) | C13: =IFERROR(IF(Cashflow!D$63=0,"",((Cashflow!D$70+Cashflow!D$71)-Cashflow!D$38)/Cashflow!D$63),"") | D13: =IFERROR(IF(Cashflow!E$63=0,"",((Cashflow!E$70+Cashflow!E$71)-Cashflow!E$38)/Cashflow!E$63),"") | E13: =IFERROR(IF(Cashflow!F$63=0,"",((Cashflow!F$70+Cashflow!F$71)-Cashflow!F$38)/Cashflow!F$63),"") | F13: =IFERROR(IF(Cashflow!G$63=0,"",((Cashflow!G$70+Cashflow!G$71)-Cashflow!G$38)/Cashflow!G$63),"") -> 0.58545776 | G13: =IFERROR(IF(Cashflow!H$63=0,"",((Cashflow!H$70+Cashflow!H$71)-Cashflow!H$38)/Cashflow!H$63),"") -> 0.49797545 | H13: =IFERROR(IF(Cashflow!I$63=0,"",((Cashflow!I$70+Cashflow!I$71)-Cashflow!I$38)/Cashflow!I$63),"") -> 0.40116192 | I13: =IFERROR(IF(Cashflow!J$63=0,"",((Cashflow!J$70+Cashflow!J$71)-Cashflow!J$38)/Cashflow!J$63),"") -> 0.32480923 | J13: =IFERROR(IF(Cashflow!K$63=0,"",((Cashflow!K$70+Cashflow!K$71)-Cashflow!K$38)/Cashflow!K$63),"") -> 0.25518524 | ... N13: =IFERROR(IF(Cashflow!O$63=0,"",((Cashflow!O$70+Cashflow!O$71)-Cashflow!O$38)/Cashflow!O$63),"") -> 0
A15: PORT MELBOURNE LIVE HOUSE — EXECUTIVE DASHBOARD
A16: Port Melbourne Live House | P16: Active Scenario | Q16: =Scenarios!B4 -> Base
P17: Model Health | Q17: =Q3 -> OK
B19: FINANCIAL SUMMARY
C20: FY25 | D20: FY26 | E20: FY27 | F20: FY28 | G20: FY29 | H20: FY30 | I20: FY31 | J20: FY32 | K20: FY33 | L20: FY34 | M20: FY35 | N20: FY36
B21: Revenue | C21: ='P&L'!I28 -> 0 | D21: ='P&L'!J28 -> 0 | E21: ='P&L'!K28 -> 18192909 | F21: ='P&L'!L28 -> 19173295 | G21: ='P&L'!M28 -> 20282270 | H21: ='P&L'!N28 -> 20817159 | I21: ='P&L'!O28 -> 21296978 | J21: ='P&L'!P28 -> 21790858 | ... M21: ='P&L'!S28 -> 23361053 | N21: ='P&L'!S28 -> 23361053
B22: EBITDA | C22: ='P&L'!I77 -> 0 | D22: ='P&L'!J77 -> 0 | E22: ='P&L'!K77 -> 13999302 | F22: ='P&L'!L77 -> 14401312 | G22: ='P&L'!M77 -> 15322990 | H22: ='P&L'!N77 -> 15770796 | I22: ='P&L'!O77 -> 16058922 | J22: ='P&L'!P77 -> 15923838 | ... M22: ='P&L'!S77 -> 16893778 | N22: ='P&L'!S77 -> 16893778
B23: Closing Cash | C23: ='Balance Sheet'!G10 -> 1707500 | D23: ='Balance Sheet'!H10 -> 16050500 | E23: ='Balance Sheet'!I10 -> -1231018.3 | F23: ='Balance Sheet'!J10 -> -396007.99 | G23: ='Balance Sheet'!K10 -> 513409.17 | H23: ='Balance Sheet'!L10 -> 1533142.7 | I23: ='Balance Sheet'!M10 -> 2307422.4 | J23: ='Balance Sheet'!N10 -> 3446826.6 | ... M23: ='Balance Sheet'!Q10 -> 1.4219797e+08 | N23: ='Balance Sheet'!Q10 -> 1.4219797e+08
B24: Total Debt | C24: =Debt!I24+Debt!I43 -> 0 | D24: =Debt!J24+Debt!J43 -> 9220500 | E24: =Debt!K24+Debt!K43 -> 8196000 | F24: =Debt!L24+Debt!L43 -> 7171500 | G24: =Debt!M24+Debt!M43 -> 6147000 | H24: =Debt!N24+Debt!N43 -> 5122500 | I24: =Debt!O24+Debt!O43 -> 4098000 | J24: =Debt!P24+Debt!P43 -> 3073500 | ... M24: =Debt!S24+Debt!S43 -> 0 | N24: =Debt!S24+Debt!S43 -> 0
B27: DEBT & LEVERAGE | E27: KEY INVESTMENT METRICS
B28: Metric | C28: Value | E28: Metric | F28: Value
B29: Total Debt Facility | C29: =Inputs!E54 -> 10245000 | E29: Total Capex | F29: =Inputs!E113 -> 17075000
B30: Bank Debt | C30: =Inputs!E54 -> 10245000 | E30: Total Equity | F30: =Inputs!E75 -> 7610000
B31: PE Equity | C31: =Inputs!E73 -> 5122500 | E31: Total Debt | F31: =Inputs!E54 -> 10245000
B32: Bank Term (years) | C32: =Inputs!E52 -> 10 | E32: Debt/Equity Ratio | F32: =IF(Inputs!E75>0,Inputs!E54/Inputs!E75,0) -> 1.3462549
B33: PE Equity Injection Year | C33: =Inputs!E86 -> FY27 | E33: Project IRR | F33: =Valuations!C20 -> 0.75463788
B34: Bank Interest Rate | C34: =Inputs!E51 -> 0.08 | E34: Equity IRR | F34: =Valuations!C22 -> 0.36201056
B35: Shareholder Loan Toggle | C35: =IF(Inputs!E88=0,"OFF","ON") -> OFF | E35: MOIC | F35: =Valuations!C24 -> 21.968719
B36: Debt/Total Capex | C36: =(Inputs!E54+Inputs!E63)/Inputs!E113 -> 0.6 | E36: Payback Period | F36: =Valuations!C25 -> FY29
B39: VALUATION SUMMARY
B40: Metric | C40: Value | D40: Notes
B41: WACC | C41: =Valuations!C9 -> 0.1 | D41: Discount rate
B42: Exit Multiple | C42: =Valuations!C15 -> 8 | D42: EBITDA multiple
B43: Exit EBITDA | C43: =Valuations!C72 -> 16893778 | D43: FY36 EBITDA
B44: Terminal Value | C44: =Valuations!C74 -> 1.3515022e+08 | D44: Exit value
B45: Enterprise Value | C45: =Valuations!C91 -> 92246992 | D45: DCF valuation
B46: Net Debt (Exit) | C46: =Valuations!C93+Valuations!C94 -> 6830000 | D46: Debt - Cash at exit
B47: Equity Value | C47: =Valuations!C23 -> 99076992 | D47: EV less Net Debt
...

Sheet Valuations
B1: PORT MELBOURNE LIVE HOUSE — VALUATIONS
B2: Architecture sheet: valuation approaches, return metrics (IRR/NPV), and sensitivity framework. Calculations will be wired in the next step.
B4: VALUATION CONTROLS & INPUTS
B5: Active Scenario | C5: =Scenarios!B4 -> Base | D5: Pulled from Scenarios toggle (read-only)
B6: Valuation Currency | C6: AUD | D6: Match model currency
B7: Valuation Date | C7: =Inputs!E14 -> 46174 | D7: Leave blank or set to transaction / IC date
B8: Discount Rate Basis | C8: WACC (FCFF) / Ke (Equity) | D8: Choose which return metric you’re presenting
B9: WACC (nominal) | C9: =Inputs!E257 -> 0.1 | D9: Linked to Inputs!E223
B10: Cost of Equity (Ke) | C10: =Inputs!E258 -> 0.15 | D10: Linked to Inputs!E224
B11: Cost of Debt (Kd) | C11: =Debt!C7 -> 0.08 | D11: To be linked to Debt terms
B12: Corporate Tax Rate | C12: =Inputs!E260 -> 0.3 | D12: Linked to Inputs!E226
B13: Exit FY | C13: =Inputs!E266 -> FY36 | D13: Linked to Inputs!E232
B14: Exit Method | C14: ="EBITDA Multiple" -> EBITDA Multiple | D14: Choose primary method
B15: Exit EBITDA Multiple | C15: =Inputs!E261 -> 8 | D15: Linked to Inputs!E227
B16: Mid-year convention | C16: =Inputs!E263 -> No | D16: Linked to Inputs!E229
B19: Metric | C19: Value | D19: Units / Format | E19: Cash Flow Basis | F19: Method / Formula Guidance + Link Source
B20: Project IRR (Unlevered) | C20: =C109 -> 0.75463788 | D20: % | E20: Unlevered | F20: XIRR(unlevered FCF, dates) — exclude debt & equity flows | Source: Cashflow (build Unlevered FCF series)
B21: Project NPV @ WACC | C21: =C91 -> 92246992 | D21: A$ | E21: Unlevered | F21: XNPV(WACC, unlevered FCF, dates) OR PV factors | Source: Valuations DCF block below
B22: Equity IRR (Levered) | C22: =C123 -> 0.36201056 | D22: % | E22: Equity | F22: XIRR(equity cash flows, dates) | Source: Equity injections + distributions + exit equity
B23: Equity NPV @ Ke | C23: =C98 -> 99076992 | D23: A$ | E23: Equity | F23: XNPV(Ke, equity cash flows, dates) | Source: Equity cash flow schedule
B24: Equity MOIC | C24: =C127 -> 21.968719 | D24: x | E24: Equity | F24: (Total distributions + exit equity) / Total equity injected | Source: Dashboard already calculates
B25: Payback Period (Equity) | C25: =C128 -> FY29 | D25: FY | E25: Equity | F25: First year cumulative equity distributions exceed equity injected | Source: To be added (optional)
B26: Yield on Cost (Stabilised) | C26: =C130 -> 0.81987128 | D26: % | E26: Operating | F26: Stabilised EBITDA / Total Project Cost | Source: Dashboard already calculates
B29: WEIGHTED AVERAGE COST OF CAPITAL (WACC)
B30: Component | C30: Value | D30: Source/Formula
B31: Risk-Free Rate | C31: =Inputs!E267 -> 0.04 | D31: Linked to Inputs!E233
B32: Market Risk Premium | C32: =0.065 -> 0.065 | D32: Hard-coded: 6.5% historical equity premium (add to Inputs if row available)
B33: Asset Beta (Unlevered) | C33: =Inputs!E269 -> 0.8 | D33: Linked to Inputs!E235
B34: Target D/E Ratio | C34: =Dashboard!F68/Dashboard!F67 -> 4.118593 | D34: From model capital structure
B35: Tax Rate | C35: =C12 -> 0.3 | D35: Corporate tax rate
B36: Levered Beta | C36: =C33*(1+(1-C35)*C34) -> 3.1064121 | D36: Hamada formula: βu×(1+(1-T)×D/E)
B37: Cost of Equity (Ke) | C37: =C31+C36*C32 -> 0.24191678 | D37: CAPM: Rf + β × MRP
B38: Pre-Tax Cost of Debt (Kd) | C38: =C11 -> 0.08 | D38: From Debt sheet
B39: After-Tax Cost of Debt | C39: =C38*(1-C35) -> 0.056 | D39: Kd × (1-T)
B41: Weight of Equity | C41: =1/(1+C34) -> 0.19536619 | D41: E/(D+E)
B42: Weight of Debt | C42: =C34/(1+C34) -> 0.80463381 | D42: D/(D+E)
B44: WACC (Calculated) | C44: =C41*C37+C42*C39 -> 0.092321854 | D44: We×Ke + Wd×Kd(1-T)
B45: WACC (Input Override) | C45: =C9 -> 0.1 | D45: Manual input for sensitivity
B47: Applied Discount Rate | C47: =C45 -> 0.1 | D47: Uses input WACC for discounting
B50: UNLEVERED DCF VALUATION
...

Sheet VBA
A1: Paste this into a VBA Module (Alt+F11 > Insert > Module)
A3: Sub RecalcAndCheck()
A4: Application.CalculateFull
A5: If Sheets("Model Checks").Range("B2").Value > 1 Then MsgBox "Balance Sheet Error!"
A6: End Sub

Sheet Scenarios
A1: SCENARIO MANAGER
A2: Port Melbourne Live House - Dynamic Scenario Analysis
A4: ACTIVE SCENARIO | B4: Base | D4: SCENARIO DEFINITIONS
A5: APPLIED MULTIPLIERS | D5: Scenario | E5: Rev Mult | F5: Cost Mult | G5: Delay (m) | H5: Int Δ (bps) | I5: Capex Mult | J5: Infl Mult | K5: Days Mult | L5: Event Days
A6: Revenue Multiplier | B6: =Inputs!E272 -> 1 | D6: Base | E6: 1 | F6: 1 | G6: 0 | H6: 0 | I6: 1 | J6: 1 | K6: 1 | L6: 120
A7: Cost Multiplier | B7: =Inputs!E273 -> 1 | D7: Optimistic | E7: 1.1 | F7: 0.95 | G7: 0 | H7: 0 | I7: 0.95 | J7: 0.95 | K7: 1.25 | L7: 150
A8: Opening Delay (months) | B8: =Inputs!E277 -> 0 | D8: Pessimistic | E8: 0.85 | F8: 1.1 | G8: 0 | H8: 0 | I8: 1.1 | J8: 1.05 | K8: 0.75 | L8: 90
A9: Interest Rate Delta (bps) | B9: =Inputs!E278 -> 0 | D9: Delayed Opening +3m | E9: 1 | F9: 1 | G9: 3 | H9: 0 | I9: 1 | J9: 1 | K9: 1 | L9: 120
A10: Capex Multiplier | B10: =Inputs!E274 -> 1 | D10: Delayed Opening +6m | E10: 1 | F10: 1 | G10: 6 | H10: 0 | I10: 1 | J10: 1 | K10: 1 | L10: 120
A11: Inflation Multiplier | B11: =Inputs!E275 -> 1 | D11: Higher Capex +10% | E11: 1 | F11: 1 | G11: 0 | H11: 0 | I11: 1.1 | J11: 1 | K11: 1 | L11: 120
A12: Event Days Multiplier | B12: =Inputs!E276 -> 1 | D12: Higher Capex +20% | E12: 1 | F12: 1 | G12: 0 | H12: 0 | I12: 1.2 | J12: 1 | K12: 1 | L12: 120
D13: Sponsorship Underperformance | E13: 0.9 | F13: 1 | G13: 0 | H13: 0 | I13: 1 | J13: 1 | K13: 1 | L13: 120
A15: SCENARIO IMPACT PREVIEW | H15: QUICK SCENARIO COMPARISON
A16: Metric | B16: Base Case | C16: Scenario Value | D16: Variance | E16: % Change | F16: Status | H16: Scenario | I16: Revenue Impact | J16: Cost Impact | K16: IRR Impact | L16: Risk Level
A17: Total Revenue (Exit FY) | B17: =IFERROR(Dashboard!N7/B6,Dashboard!N7) -> 23361053 | C17: =Dashboard!N7 -> 23361053 | D17: =C17-B17 -> 0 | E17: =IFERROR(D17/B17,0) -> 0 | F17: =IF(E17>0.02,"▲ Up",IF(E17<-0.02,"▼ Down","◆ Same")) -> ◆ Same | H17: Base | I17: 0 | J17: 0 | K17: Baseline | L17: ●●○○○
A18: EBITDA (Exit FY) | B18: =IFERROR(Dashboard!N7/B6 - (Dashboard!N7-Dashboard!N8)/B7, Dashboard!N8) -> 16893778 | C18: =Dashboard!N8 -> 16893778 | D18: =C18-B18 -> 0 | E18: =IFERROR(D18/B18,0) -> 0 | F18: =IF(E18>0.02,"▲ Up",IF(E18<-0.02,"▼ Down","◆ Same")) -> ◆ Same | H18: Optimistic | I18: 0.1 | J18: -0.05 | K18: =3-5% -> 2.95 | L18: ●○○○○
A19: Project IRR | B19: =Valuations!C20 -> 0.75463788 | C19: =Valuations!C20 -> 0.75463788 | D19: =C19-B19 -> 0 | E19: =IFERROR(D19/B19,0) -> 0 | F19: =IF(E19>0.02,"▲ Up",IF(E19<-0.02,"▼ Down","◆ Same")) -> ◆ Same | H19: Pessimistic | I19: -0.15 | J19: 0.1 | K19: =-5-8% -> -5.08 | L19: ●●●●○
A20: Equity IRR | B20: =Valuations!C22 -> 0.36201056 | C20: =Valuations!C22 -> 0.36201056 | D20: =C20-B20 -> 0 | E20: =IFERROR(D20/B20,0) -> 0 | F20: =IF(E20>0.02,"▲ Up",IF(E20<-0.02,"▼ Down","◆ Same")) -> ◆ Same | H20: Delayed +3m | I20: 0 | J20: 0 | K20: =-1-2% -> -1.02 | L20: ●●●○○
A21: Total Capex | B21: =Inputs!E113 -> 17075000 | C21: =Inputs!E113*B10 -> 17075000 | D21: =C21-B21 -> 0 | E21: =IFERROR(D21/B21,0) -> 0 | F21: =IF(E21>0.02,"▼ Up (Bad)",IF(E21<-0.02,"▲ Down (Good)","◆ Same")) -> ◆ Same | H21: Delayed +6m | I21: 0 | J21: 0 | K21: =-2-4% -> -2.04 | L21: ●●●●○
A22: Debt Service Coverage | B22: =Dashboard!F11 -> 8.3450465 | C22: =Dashboard!F11 -> 8.3450465 | D22: =C22-B22 -> 0 | E22: =IFERROR(D22/B22,0) -> 0 | F22: =IF(E22>0.02,"▲ Up",IF(E22<-0.02,"▼ Down","◆ Same")) -> ◆ Same | H22: Capex +10% | I22: 0 | J22: 0.1 | K22: =-2-3% -> -2.03 | L22: ●●●○○
A23: Payback Period | B23: =Valuations!C25 -> FY29 | C23: =Valuations!C25 -> FY29 | D23: =IFERROR(VALUE(RIGHT(C23,2))-VALUE(RIGHT(B23,2)),0) -> 0 | E23: ="N/A" -> N/A | F23: ="-" -> - | H23: Capex +20% | I23: 0 | J23: 0.2 | K23: =-4-5% -> -4.05 | L23: ●●●●○
A24: Sens Exit Multiple Multiplier | B24: =Inputs!E287 -> 1 | H24: Sponsorship Under | I24: -0.1 | J24: 0 | K24: =-2-3% -> -2.03 | L24: ●●●○○
A25: SENSITIVITY OVERRIDES
A26: Override Parameter | B26: Value
A27: Event Days Override | B27: =Inputs!E282 -> 1
A28: Avg Rev/Event Override | B28: =Inputs!E283 -> 1
A29: Non-event Rev Override | B29: =Inputs!E284 -> 1
A30: Capex Override | B30: =Inputs!E274 -> 1
A31: Lease Cost Override | B31: =Inputs!E285 -> 1
A32: WACC Override | B32: =Inputs!E286 -> 1
A33: Exit Multiple Override | B33: =Inputs!E287 -> 1
A35: INSTRUCTIONS
A36: 1. Select a scenario from the dropdown in cell B4
A37: 2. The model will automatically recalculate all P&L, Balance Sheet, and Cash Flow projections
A38: 3. Review the Scenario Impact Preview (rows 17-23) to see key metric changes
A39: 4. Use Sensitivity Overrides (rows 27-33) for fine-tuning individual parameters
A40: 5. The Dashboard and Valuations tabs will reflect the selected scenario

Sheet Inputs
G1: v35 | 04/03/2026
B2: GLOBAL INPUTS
B3: Port Melbourne Live House — Financial Model
C5: Input | D5: Units | E5: Value | F5: Source | G5: Notes
B7: 1. PROJECT TIMING | I7: FORMAT LEGEND
I8: User Input
C9: Model Start Date | D9: Date | E9: 45715 | G9: Feb-2025 — Model commencement | I9: Formula/Link
C10: Model End Date | D10: Date | E10: 50099 | G10: Feb-2037 — 12-year horizon | I10: Section
C11: Model Duration | D11: Years | E11: 12 | G11: Total projection period | I11: Sub-Section
C12: Currency | E12: AUD | G12: Australian Dollars | I12: Table Header
I13: Subtotal
C14: Lease Signing Date | D14: Date | E14: 46174 | G14: Apr-2026 — Triggers deposit payment | I14: Total
C15: Possession / Handover Date | D15: Date | E15: 46419 | G15: Feb-2027 — Site access begins | I15: Section Header
C16: Major Capex Start | D16: Date | E16: 46266 | G16: Sept-2026 — Fabrication begins | I16: Model Status: | J16: READY
C17: Major Capex End | D17: Date | E17: =DATE(2027,6,30) -> 46568 | G17: Jun-2026 — Fabrication complete | I17: Total/Subtotal
C18: Construction Start | D18: Date | E18: 46420 | G18: Feb-2027 — On-site assembly
C19: Construction End | D19: Date | E19: 46568 | G19: Jun-2027 — Practical completion
C20: Commissioning Start | D20: Date | E20: 46508 | G20: 46508
C21: Commissioning End | D21: Date | E21: 46568 | G21: 46539
C22: Operations Start | D22: Date | E22: 46569 | G22: Jul-2027 — First revenue month
C23: Exit Year | D23: FY | E23: FY34 | G23: Target exit/valuation date
B24: 2. LEASE ASSUMPTIONS
C26: Lease Commencement | D26: Date | E26: 46419 | G26: Matches Possession Date
C27: Lease Period | D27: Years | E27: 10 | G27: Initial lease term
C28: Months in Year 1 | D28: Months | E28: 11 | G28: Partial first year
C29: Operational Months in Year 1 | D29: Months | E29: 6 | G29: Jul-Dec FY27
C30: Rent-Free Period | D30: Months | E30: 18 | G30: Fitout/construction allowance
C31: Base Rent Rate | D31: $/m²/yr | E31: 156 | G31: Per annum rate
C32: Plot Area | D32: m² | E32: 5000 | G32: Total leasable area
C33: Annual Base Rent (Yr 1) | D33: AUD | E33: 780000 | F33: Formula | G33: =E31*E32 -> 780000
C34: Lease Deposit | D34: AUD | E34: 780000 | G34: Equivalent to 1 year rent
C35: Rent Escalation | D35: % p.a. | E35: 0.035 | G35: 3.5% fixed annual increase
C36: Landlord Outgoings | D36: % of rent | E36: 0.15 | G36: 15% additional outgoings
C37: Rent-Free End Date | D37: Date | E37: =EDATE(E26,E30) -> 46966 | F37: Formula | G37: Lease Commencement + Rent-Free Period
C38: Rent Rebate Period | D38: Months | E38: 48 | G38: 48 months at reduced rent after rent-free ends
C39: Rent Rebate Multiplier | D39: x | E39: 0.5 | G39: 50% of normal rent during rebate period
C40: Rent Rebate End Date | D40: Date | E40: =EDATE($E$37,$E$38) -> 48427 | G40: Rent-Free End Date + Rebate Period
C41: Tenant Break Option | D41: Year | E41: 5 | G41: Years from lease start
C42: Break Notice Period | D42: Months | E42: 6 | G42: Required notice
C43: Renewal Option | D43: Years | E43: 5 | G43: Extension available
...

Sheet Construction Timeline
C2: Initial CAPEX
D5: Capex
D6: Consultants | G6: 1270000
D7: Structure | G7: 7280000
D8: Civil | G8: 1105000
D9: ICT | G9: 420000
D10: FF&E | G10: 1200000
D11: Services | G11: 4950000
D12: Security | G12: 220000
D13: Finance | G13: 130000
D14: Total | E14: AUD | G14: =SUM(G6:G13) -> 16575000
D16: Miscellaneous | E16: AUD | G16: 500000
C17: Total initial CAPEX | D17: Total initial CAPEX | E17: AUD | G17: =SUM(G16) -> 500000
Z18: Toilets
Z19: For a 5,000 cap venue with swing flexibility
C20: Pre-lease works | Z20: 7–8 toilet containers total, typically:
I21: Design Development | K21: Fabrication and Shipping | P21: Handover, Construction, Mobisation and Commissioning Period | Z21: 5–6 × 40’ WC blocks
C22: CONSULTANTS | E22: AUD | I22: P1 (Feb-25) | J22: P2 (Mar-25) | K22: P3 (Apr-25) | L22: P4 (May-25) | M22: P5 (Jun-25) | N22: P6 (Jul-25) | O22: P7 (Aug-25) | P22: P8 (Sep-25) | Q22: P9 (Oct-25) | R22: P10 (Nov-25) | S22: P11 (Dec-25) | T22: P12 (Jan-26) | U22: P13 (Feb-26) | V22: Totals | Z22: 0–1 × 20’ WC block
D23: Project Management | G23: 800000 | I23: 61538 | J23: 61538 | K23: 61538 | L23: 61538 | M23: 61538 | N23: 61538 | O23: 61538 | P23: 61538 | Q23: 61538 | R23: 61538 | S23: 61538 | T23: 61538 | U23: 61538 | V23: 800000 | W23: =IF(ABS(V23-G23)<1,"OK","Check") -> OK | Z23: 2–3 × 40’ urinal blocks
D24: Building Surveyor | G24: 50000 | I24: 20000 | J24: 10000 | K24: 0 | L24: 0 | M24: 0 | N24: 0 | O24: 0 | P24: 10000 | Q24: 0 | R24: 0 | S24: 0 | T24: 0 | U24: 10000 | V24: 50000 | W24: =IF(ABS(V24-G24)<1,"OK","Check") -> OK | Z24: Design for ~55 WC cubicles total, ~40–60 urinals, 4–6 accessible distributed.
D25: Acoustics | G25: 75000 | I25: 10000 | J25: 25000 | K25: 0 | L25: 0 | M25: 0 | N25: 0 | O25: 10000 | P25: 0 | Q25: 0 | R25: 0 | S25: 0 | T25: 10000 | U25: 20000 | V25: 75000 | W25: =IF(ABS(V25-G25)<1,"OK","Check") -> OK
D26: Fire | G26: 50000 | I26: 10000 | J26: 20000 | K26: 0 | L26: 0 | M26: 10000 | N26: 0 | O26: 0 | P26: 0 | Q26: 0 | R26: 0 | S26: 0 | T26: 0 | U26: 10000 | V26: 50000 | W26: =IF(ABS(V26-G26)<1,"OK","Check") -> OK
D27: Licenscing | G27: 45000 | I27: 15000 | J27: 0 | K27: 0 | L27: 0 | M27: 15000 | N27: 0 | O27: 0 | P27: 0 | Q27: 0 | R27: 0 | S27: 0 | T27: 0 | U27: 15000 | V27: 45000 | W27: =IF(ABS(V27-G27)<1,"OK","Check") -> OK
D28: Crowd Dynamics | G28: 40000 | I28: 0 | J28: 20000 | K28: 0 | L28: 0 | M28: 5000 | N28: 0 | O28: 0 | P28: 0 | Q28: 5000 | R28: 0 | S28: 5000 | T28: 0 | U28: 5000 | V28: 40000 | W28: =IF(ABS(V28-G28)<1,"OK","Check") -> OK
D29: Environmental | G29: 30000 | I29: 0 | J29: 20000 | K29: 0 | L29: 0 | M29: 0 | N29: 0 | O29: 0 | P29: 0 | Q29: 0 | R29: 0 | S29: 0 | T29: 0 | U29: 10000 | V29: 30000 | W29: =IF(ABS(V29-G29)<1,"OK","Check") -> OK
D30: Architecture and ID | G30: 100000 | I30: 0 | J30: 25000 | K30: 25000 | L30: 10000 | M30: 0 | N30: 0 | O30: 15000 | P30: 15000 | Q30: 0 | R30: 0 | S30: 0 | T30: 0 | U30: 10000 | V30: 100000 | W30: =IF(ABS(V30-G30)<1,"OK","Check") -> OK
D31: ICT | G31: 50000 | I31: 0 | J31: 15000 | K31: 0 | L31: 10000 | M31: 0 | N31: 0 | O31: 0 | P31: 0 | Q31: 15000 | R31: 0 | S31: 0 | T31: 10000 | U31: 0 | V31: 50000 | W31: =IF(ABS(V31-G31)<1,"OK","Check") -> OK
D32: Transportation | G32: 30000 | I32: 0 | J32: 20000 | K32: 0 | L32: 0 | M32: 0 | N32: 0 | O32: 0 | P32: 0 | Q32: 0 | R32: 0 | S32: 0 | T32: 0 | U32: 10000 | V32: 30000 | W32: =IF(ABS(V32-G32)<1,"OK","Check") -> OK
D33: Total initial capex for Consultancts | G33: =SUM(G23:G32) -> 1270000 | I33: =SUM(I23:I32) -> 116538 | J33: =SUM(J23:J32) -> 216538 | K33: =SUM(K23:K32) -> 86538 | L33: =SUM(L23:L32) -> 81538 | M33: =SUM(M23:M32) -> 91538 | N33: =SUM(N23:N32) -> 61538 | O33: =SUM(O23:O32) -> 86538 | P33: =SUM(P23:P32) -> 86538 | ... V33: =SUM(V23:V32) -> 1270000 | W33: =IF(ABS(V33-G33)<1,"OK","Check") -> OK
C35: STRUCTURE
D36: Performance area | G36: 3400000 | I36: 0 | J36: 0 | K36: 0 | L36: 680000 | M36: 680000 | N36: 1360000 | O36: 0 | P36: 340000 | Q36: 0 | R36: 0 | S36: 0 | T36: 0 | U36: 340000 | V36: 3400000 | W36: =IF(ABS(V36-G36)<1,"OK","Check") -> OK
D37: Venue Façade (inc Lighting) | G37: 2600000 | I37: 0 | J37: 0 | K37: 0 | L37: 0 | M37: 0 | N37: 260000 | O37: 1820000 | P37: 390000 | Q37: 0 | R37: 0 | S37: 0 | T37: 0 | U37: 130000 | V37: 2600000 | W37: =IF(ABS(V37-G37)<1,"OK","Check") -> OK
D38: Concessions | G38: 250000 | I38: 0 | J38: 0 | K38: 0 | L38: 0 | M38: 0 | N38: 25000 | O38: 150000 | P38: 0 | Q38: 25000 | R38: 0 | S38: 0 | T38: 25000 | U38: 25000 | V38: 250000 | W38: =IF(ABS(V38-G38)<1,"OK","Check") -> OK
D39: BoH Dressing Rooms | G39: 200000 | I39: 0 | J39: 0 | K39: 0 | L39: 0 | M39: 0 | N39: 20000 | O39: 80000 | P39: 0 | Q39: 20000 | R39: 0 | S39: 0 | T39: 70000 | U39: 10000 | V39: 200000 | W39: =IF(ABS(V39-G39)<1,"OK","Check") -> OK
D40: Venue Management Offices | G40: 200000 | I40: 0 | J40: 0 | K40: 0 | L40: 0 | M40: 0 | N40: 20000 | O40: 80000 | P40: 0 | Q40: 20000 | R40: 0 | S40: 0 | T40: 70000 | U40: 10000 | V40: 200000 | W40: =IF(ABS(V40-G40)<1,"OK","Check") -> OK
D41: Toilets | G41: 230000 | I41: 0 | J41: 0 | K41: 0 | L41: 0 | M41: 0 | N41: 46000 | O41: 138000 | P41: 0 | Q41: 34500 | R41: 0 | S41: 0 | T41: 0 | U41: 11500 | V41: 230000 | W41: =IF(ABS(V41-G41)<1,"OK","Check") -> OK
D42: Premium | G42: 300000 | I42: 0 | J42: 0 | K42: 0 | L42: 0 | M42: 0 | N42: 60000 | O42: 150000 | P42: 0 | Q42: 0 | R42: 0 | S42: 0 | T42: 0 | U42: 90000 | V42: 300000 | W42: =IF(ABS(V42-G42)<1,"OK","Check") -> OK
D43: First Aid | G43: 30000 | I43: 0 | J43: 0 | K43: 0 | L43: 0 | M43: 0 | N43: 6000 | O43: 12000 | P43: 0 | Q43: 3000 | R43: 0 | S43: 0 | T43: 0 | U43: 9000 | V43: 30000 | W43: =IF(ABS(V43-G43)<1,"OK","Check") -> OK
D44: Storage Block & Workshop | G44: 70000 | I44: 0 | J44: 0 | K44: 0 | L44: 0 | M44: 0 | N44: 14000 | O44: 42000 | P44: 0 | Q44: 7000 | R44: 0 | S44: 0 | T44: 0 | U44: 7000 | V44: 70000 | W44: =IF(ABS(V44-G44)<1,"OK","Check") -> OK
D45: Total initial capex for structure | E45: AUD | G45: =SUM(G36:G44) -> 7280000 | I45: =SUM(I36:I44) -> 0 | J45: =SUM(J36:J44) -> 0 | K45: =SUM(K36:K44) -> 0 | L45: =SUM(L36:L44) -> 680000 | M45: =SUM(M36:M44) -> 680000 | N45: =SUM(N36:N44) -> 1811000 | O45: =SUM(O36:O44) -> 2472000 | P45: =SUM(P36:P44) -> 730000 | ... V45: =SUM(V36:V44) -> 7280000 | W45: =IF(ABS(V45-G45)<1,"OK","Check") -> OK
...

Sheet P&L
A1: Profit & Loss Statement
A2: Port Melbourne Live House
G4: FY START | H4: =Model_start -> 45715 | I4: =H5+1 -> 45839 | J4: =I5+1 -> 46204 | K4: =J5+1 -> 46569 | L4: =K5+1 -> 46935 | M4: =L5+1 -> 47300 | N4: =M5+1 -> 47665 | O4: =N5+1 -> 48030 | P4: =O5+1 -> 48396 | ... S4: =R5+1 -> 49491
G5: FY END | H5: =DATE(YEAR(H4) + (MONTH(H4)>=7), 6, 30) -> 45838 | I5: =DATE(YEAR(I4) + (MONTH(I4)>=7), 6, 30) -> 46203 | J5: =DATE(YEAR(J4) + (MONTH(J4)>=7), 6, 30) -> 46568 | K5: =DATE(YEAR(K4) + (MONTH(K4)>=7), 6, 30) -> 46934 | L5: =DATE(YEAR(L4) + (MONTH(L4)>=7), 6, 30) -> 47299 | M5: =DATE(YEAR(M4) + (MONTH(M4)>=7), 6, 30) -> 47664 | N5: =DATE(YEAR(N4) + (MONTH(N4)>=7), 6, 30) -> 48029 | O5: =DATE(YEAR(O4) + (MONTH(O4)>=7), 6, 30) -> 48395 | ... S5: =DATE(YEAR(S4) + (MONTH(S4)>=7), 6, 30) -> 49856
G6: Year | H6: ="FY"&RIGHT(YEAR(H5)+(MONTH(H5)>6),2) -> FY25 | I6: ="FY"&RIGHT(YEAR(I5)+(MONTH(I5)>6),2) -> FY26 | J6: ="FY"&RIGHT(YEAR(J5)+(MONTH(J5)>6),2) -> FY27 | K6: ="FY"&RIGHT(YEAR(K5)+(MONTH(K5)>6),2) -> FY28 | L6: ="FY"&RIGHT(YEAR(L5)+(MONTH(L5)>6),2) -> FY29 | M6: ="FY"&RIGHT(YEAR(M5)+(MONTH(M5)>6),2) -> FY30 | N6: ="FY"&RIGHT(YEAR(N5)+(MONTH(N5)>6),2) -> FY31 | O6: ="FY"&RIGHT(YEAR(O5)+(MONTH(O5)>6),2) -> FY32 | ... S6: ="FY"&RIGHT(YEAR(S5)+(MONTH(S5)>6),2) -> FY36
C8: Ops Flag | D8: =Inputs!E22 -> 46569 | H8: =IF(H$5>$D$8,1,0) -> 0 | I8: =IF(I$5>$D$8,1,0) -> 0 | J8: =IF(J$5>$D$8,1,0) -> 0 | K8: =IF(K$5>$D$8,1,0) -> 1 | L8: =IF(L$5>$D$8,1,0) -> 1 | M8: =IF(M$5>$D$8,1,0) -> 1 | N8: =IF(N$5>$D$8,1,0) -> 1 | O8: =IF(O$5>$D$8,1,0) -> 1 | ... S8: =IF(S$5>$D$8,1,0) -> 1
C9: Construciton Flag | D9: =Inputs!E18 -> 46420 | H9: =IF(H8=1,0,IF(AND(H$5>=$D$9,H$5<=$D$10),1,0)) -> 0 | I9: =IF(I8=1,0,IF(AND(I$5>=$D$9,I$5<=$D$10),1,0)) -> 0 | J9: =IF(J8=1,0,IF(AND(J$5>=$D$9,J$5<=$D$10),1,0)) -> 1 | K9: =IF(K8=1,0,IF(AND(K$5>=$D$9,K$5<=$D$10),1,0)) -> 0 | L9: =IF(L8=1,0,IF(AND(L$5>=$D$9,L$5<=$D$10),1,0)) -> 0 | M9: =IF(M8=1,0,IF(AND(M$5>=$D$9,M$5<=$D$10),1,0)) -> 0 | N9: =IF(N8=1,0,IF(AND(N$5>=$D$9,N$5<=$D$10),1,0)) -> 0 | O9: =IF(O8=1,0,IF(AND(O$5>=$D$9,O$5<=$D$10),1,0)) -> 0 | ... S9: =IF(S8=1,0,IF(AND(S$5>=$D$9,S$5<=$D$10),1,0)) -> 0
C10: =Inputs!D17 -> Date | D10: =Inputs!E19 -> 46568
B12: REVENUE
C13: Event day revenue
C14: VHA | H14: =(IF(H8=1,INDEX('Revenue Assumptions'!$F$108:$P$108,MATCH((2000+VALUE(RIGHT(H$6,2))),'Revenue Assumptions'!$F$35:$P$35,0))*Scenarios!$B$6,0)) -> 0 | I14: =(IF(I8=1,INDEX('Revenue Assumptions'!$F$108:$P$108,MATCH((2000+VALUE(RIGHT(I$6,2))),'Revenue Assumptions'!$F$35:$P$35,0))*Scenarios!$B$6,0)) -> 0 | J14: =(IF(J8=1,INDEX('Revenue Assumptions'!$F$108:$P$108,MATCH((2000+VALUE(RIGHT(J$6,2))),'Revenue Assumptions'!$F$35:$P$35,0))*Scenarios!$B$6,0)) -> 0 | K14: =(IF(K8=1,INDEX('Revenue Assumptions'!$F$108:$P$108,MATCH((2000+VALUE(RIGHT(K$6,2))),'Revenue Assumptions'!$F$35:$P$35,0))*Scenarios!$B$6,0)) -> 5428852.5 | L14: =(IF(L8=1,INDEX('Revenue Assumptions'!$F$108:$P$108,MATCH((2000+VALUE(RIGHT(L$6,2))),'Revenue Assumptions'!$F$35:$P$35,0))*Scenarios!$B$6,0)) -> 5879207.5 | M14: =(IF(M8=1,INDEX('Revenue Assumptions'!$F$108:$P$108,MATCH((2000+VALUE(RIGHT(M$6,2))),'Revenue Assumptions'!$F$35:$P$35,0))*Scenarios!$B$6,0)) -> 6281388.4 | N14: =(IF(N8=1,INDEX('Revenue Assumptions'!$F$108:$P$108,MATCH((2000+VALUE(RIGHT(N$6,2))),'Revenue Assumptions'!$F$35:$P$35,0))*Scenarios!$B$6,0)) -> 6469770.2 | O14: =(IF(O8=1,INDEX('Revenue Assumptions'!$F$108:$P$108,MATCH((2000+VALUE(RIGHT(O$6,2))),'Revenue Assumptions'!$F$35:$P$35,0))*Scenarios!$B$6,0)) -> 6663803.4 | ... S14: =(IF(S8=1,INDEX('Revenue Assumptions'!$F$108:$P$108,MATCH((2000+VALUE(RIGHT(S$6,2))),'Revenue Assumptions'!$F$35:$P$35,0))*Scenarios!$B$6,0)) -> 7499918.4
C15: Premium Sales | H15: =(IF(H8=1,INDEX('Revenue Assumptions'!$F$124:$P$124,MATCH((2000+VALUE(RIGHT(H$6,2))),'Revenue Assumptions'!$F$35:$P$35,0))*Scenarios!$B$6,0)) -> 0 | I15: =(IF(I8=1,INDEX('Revenue Assumptions'!$F$124:$P$124,MATCH((2000+VALUE(RIGHT(I$6,2))),'Revenue Assumptions'!$F$35:$P$35,0))*Scenarios!$B$6,0)) -> 0 | J15: =(IF(J8=1,INDEX('Revenue Assumptions'!$F$124:$P$124,MATCH((2000+VALUE(RIGHT(J$6,2))),'Revenue Assumptions'!$F$35:$P$35,0))*Scenarios!$B$6,0)) -> 0 | K15: =(IF(K8=1,INDEX('Revenue Assumptions'!$F$124:$P$124,MATCH((2000+VALUE(RIGHT(K$6,2))),'Revenue Assumptions'!$F$35:$P$35,0))*Scenarios!$B$6,0)) -> 754257.03 | L15: =(IF(L8=1,INDEX('Revenue Assumptions'!$F$124:$P$124,MATCH((2000+VALUE(RIGHT(L$6,2))),'Revenue Assumptions'!$F$35:$P$35,0))*Scenarios!$B$6,0)) -> 832673.89 | M15: =(IF(M8=1,INDEX('Revenue Assumptions'!$F$124:$P$124,MATCH((2000+VALUE(RIGHT(M$6,2))),'Revenue Assumptions'!$F$35:$P$35,0))*Scenarios!$B$6,0)) -> 857654.1 | N15: =(IF(N8=1,INDEX('Revenue Assumptions'!$F$124:$P$124,MATCH((2000+VALUE(RIGHT(N$6,2))),'Revenue Assumptions'!$F$35:$P$35,0))*Scenarios!$B$6,0)) -> 883383.73 | O15: =(IF(O8=1,INDEX('Revenue Assumptions'!$F$124:$P$124,MATCH((2000+VALUE(RIGHT(O$6,2))),'Revenue Assumptions'!$F$35:$P$35,0))*Scenarios!$B$6,0)) -> 909885.24 | ... S15: =(IF(S8=1,INDEX('Revenue Assumptions'!$F$124:$P$124,MATCH((2000+VALUE(RIGHT(S$6,2))),'Revenue Assumptions'!$F$35:$P$35,0))*Scenarios!$B$6,0)) -> 1024083.9
C16: Premium F&B | H16: =(IF(H8=1,INDEX('Revenue Assumptions'!$F$159:$P$159,MATCH((2000+VALUE(RIGHT(H$6,2))),'Revenue Assumptions'!$F$35:$P$35,0))*Scenarios!$B$6,0)) -> 0 | I16: =(IF(I8=1,INDEX('Revenue Assumptions'!$F$159:$P$159,MATCH((2000+VALUE(RIGHT(I$6,2))),'Revenue Assumptions'!$F$35:$P$35,0))*Scenarios!$B$6,0)) -> 0 | J16: =(IF(J8=1,INDEX('Revenue Assumptions'!$F$159:$P$159,MATCH((2000+VALUE(RIGHT(J$6,2))),'Revenue Assumptions'!$F$35:$P$35,0))*Scenarios!$B$6,0)) -> 0 | K16: =(IF(K8=1,INDEX('Revenue Assumptions'!$F$159:$P$159,MATCH((2000+VALUE(RIGHT(K$6,2))),'Revenue Assumptions'!$F$35:$P$35,0))*Scenarios!$B$6,0)) -> 111570.94 | L16: =(IF(L8=1,INDEX('Revenue Assumptions'!$F$159:$P$159,MATCH((2000+VALUE(RIGHT(L$6,2))),'Revenue Assumptions'!$F$35:$P$35,0))*Scenarios!$B$6,0)) -> 119583 | M16: =(IF(M8=1,INDEX('Revenue Assumptions'!$F$159:$P$159,MATCH((2000+VALUE(RIGHT(M$6,2))),'Revenue Assumptions'!$F$35:$P$35,0))*Scenarios!$B$6,0)) -> 119583 | N16: =(IF(N8=1,INDEX('Revenue Assumptions'!$F$159:$P$159,MATCH((2000+VALUE(RIGHT(N$6,2))),'Revenue Assumptions'!$F$35:$P$35,0))*Scenarios!$B$6,0)) -> 123170.49 | O16: =(IF(O8=1,INDEX('Revenue Assumptions'!$F$159:$P$159,MATCH((2000+VALUE(RIGHT(O$6,2))),'Revenue Assumptions'!$F$35:$P$35,0))*Scenarios!$B$6,0)) -> 126865.6 | ... S16: =(IF(S8=1,INDEX('Revenue Assumptions'!$F$159:$P$159,MATCH((2000+VALUE(RIGHT(S$6,2))),'Revenue Assumptions'!$F$35:$P$35,0))*Scenarios!$B$6,0)) -> 142788.36
C17: F&B | H17: =(IF(H8=1,INDEX('Revenue Assumptions'!$F$141:$P$141,MATCH((2000+VALUE(RIGHT(H$6,2))),'Revenue Assumptions'!$F$35:$P$35,0))*Scenarios!$B$6,0)) -> 0 | I17: =(IF(I8=1,INDEX('Revenue Assumptions'!$F$141:$P$141,MATCH((2000+VALUE(RIGHT(I$6,2))),'Revenue Assumptions'!$F$35:$P$35,0))*Scenarios!$B$6,0)) -> 0 | J17: =(IF(J8=1,INDEX('Revenue Assumptions'!$F$141:$P$141,MATCH((2000+VALUE(RIGHT(J$6,2))),'Revenue Assumptions'!$F$35:$P$35,0))*Scenarios!$B$6,0)) -> 0 | K17: ='Revenue Assumptions'!F159 -> 106115.4 | L17: ='Revenue Assumptions'!G159 -> 111570.94 | M17: ='Revenue Assumptions'!H159 -> 119583 | N17: ='Revenue Assumptions'!I159 -> 119583 | O17: ='Revenue Assumptions'!J159 -> 123170.49 | P17: ='Revenue Assumptions'!K159 -> 126865.6 | Q17: ='Revenue Assumptions'!L159 -> 130671.57 | R17: ='Revenue Assumptions'!M159 -> 134591.72 | S17: ='Revenue Assumptions'!N159 -> 138629.47
C18: Merchandise | H18: =IF(H$8=1,INDEX('Calendar Assumptions'!$F$52:$Q$52,MATCH((2000+VALUE(RIGHT(H$6,2))),'Calendar Assumptions'!$F$2:$Q$2,0))*Inputs!$E$192*Scenarios!$B$6,0) -> 0 | I18: =IF(I$8=1,INDEX('Calendar Assumptions'!$F$52:$Q$52,MATCH((2000+VALUE(RIGHT(I$6,2))),'Calendar Assumptions'!$F$2:$Q$2,0))*Inputs!$E$192*Scenarios!$B$6,0) -> 0 | J18: =IF(J$8=1,INDEX('Calendar Assumptions'!$F$52:$Q$52,MATCH((2000+VALUE(RIGHT(J$6,2))),'Calendar Assumptions'!$F$2:$Q$2,0))*Inputs!$E$192*Scenarios!$B$6,0) -> 0 | K18: ='Revenue Assumptions'!F141 -> 5342413.7 | L18: ='Revenue Assumptions'!G141 -> 5635293.4 | M18: ='Revenue Assumptions'!H141 -> 6039971.5 | N18: ='Revenue Assumptions'!I141 -> 6169462.6 | O18: ='Revenue Assumptions'!J141 -> 6354546.5 | P18: ='Revenue Assumptions'!K141 -> 6545182.9 | Q18: ='Revenue Assumptions'!L141 -> 6741538.3 | R18: ='Revenue Assumptions'!M141 -> 6943784.5 | S18: ='Revenue Assumptions'!N141 -> 7152098
C19: Facilities Fee | H19: =IF(H$8=1,INDEX('Calendar Assumptions'!$F$16:$Q$16,MATCH((2000+VALUE(RIGHT(H$6,2))),'Calendar Assumptions'!$F$2:$Q$2,0))*Inputs!$E$194*Scenarios!$B$6,0) -> 0 | I19: =IF(I$8=1,INDEX('Calendar Assumptions'!$F$16:$Q$16,MATCH((2000+VALUE(RIGHT(I$6,2))),'Calendar Assumptions'!$F$2:$Q$2,0))*Inputs!$E$194*Scenarios!$B$6,0) -> 0 | J19: =IF(J$8=1,INDEX('Calendar Assumptions'!$F$16:$Q$16,MATCH((2000+VALUE(RIGHT(J$6,2))),'Calendar Assumptions'!$F$2:$Q$2,0))*Inputs!$E$194*Scenarios!$B$6,0) -> 0 | K19: =Inputs!$E$192*'Calendar Assumptions'!F52 -> 1635202.9 | L19: =Inputs!$E$192*'Calendar Assumptions'!G52 -> 1669916.7 | M19: =Inputs!$E$192*'Calendar Assumptions'!H52 -> 1704630.5 | N19: =Inputs!$E$192*'Calendar Assumptions'!I52 -> 1827042.3 | O19: =Inputs!$E$192*'Calendar Assumptions'!J52 -> 1827042.3 | P19: =Inputs!$E$192*'Calendar Assumptions'!K52 -> 1827042.3 | Q19: =Inputs!$E$192*'Calendar Assumptions'!L52 -> 1827042.3 | R19: =Inputs!$E$192*'Calendar Assumptions'!M52 -> 1827042.3 | S19: =Inputs!$E$192*'Calendar Assumptions'!N52 -> 1827042.3
C20: Equipment Hire | H20: =IF(H$8=1,INDEX('Calendar Assumptions'!$F$83:$Q$83,MATCH((2000+VALUE(RIGHT(H$6,2))),'Calendar Assumptions'!$F$2:$Q$2,0))*Scenarios!$B$6,0) -> 0 | I20: =IF(I$8=1,INDEX('Calendar Assumptions'!$F$83:$Q$83,MATCH((2000+VALUE(RIGHT(I$6,2))),'Calendar Assumptions'!$F$2:$Q$2,0))*Scenarios!$B$6,0) -> 0 | J20: =IF(J$8=1,INDEX('Calendar Assumptions'!$F$83:$Q$83,MATCH((2000+VALUE(RIGHT(J$6,2))),'Calendar Assumptions'!$F$2:$Q$2,0))*Scenarios!$B$6,0) -> 0 | K20: ='Calendar Assumptions'!G83 -> 2328872 | L20: ='Calendar Assumptions'!H83 -> 2377284 | M20: ='Calendar Assumptions'!I83 -> 2548000 | N20: ='Calendar Assumptions'!J83 -> 2548000 | O20: ='Calendar Assumptions'!K83 -> 2548000 | P20: ='Calendar Assumptions'!L83 -> 2548000 | Q20: ='Calendar Assumptions'!M83 -> 2548000 | R20: ='Calendar Assumptions'!N83 -> 2548000 | S20: ='Calendar Assumptions'!O83 -> 2548000
C21: ="Total "& C13 -> Total Event day revenue | H21: =SUM(H14:H20) -> 0 | I21: =SUM(I14:I20) -> 0 | J21: =SUM(J14:J20) -> 0 | K21: =SUM(K14:K20) -> 15707284 | L21: =SUM(L14:L20) -> 16625529 | M21: =SUM(M14:M20) -> 17670811 | N21: =SUM(N14:N20) -> 18140412 | O21: =SUM(O14:O20) -> 18553313 | ... S21: =SUM(S14:S20) -> 20332560
C23: Non-event day revenue
C24: Sponorship | H24: =IF(H8=1,INDEX('Revenue Assumptions'!$F$175:$P$175,MATCH((2000+VALUE(RIGHT(H$6,2))),'Revenue Assumptions'!$F$35:$P$35,0))*Scenarios!$B$6,0) -> 0 | I24: =IF(I8=1,INDEX('Revenue Assumptions'!$F$175:$P$175,MATCH((2000+VALUE(RIGHT(I$6,2))),'Revenue Assumptions'!$F$35:$P$35,0))*Scenarios!$B$6,0) -> 0 | J24: =IF(J8=1,INDEX('Revenue Assumptions'!$F$175:$P$175,MATCH((2000+VALUE(RIGHT(J$6,2))),'Revenue Assumptions'!$F$35:$P$35,0))*Scenarios!$B$6,0) -> 0 | K24: =IF(K8=1,INDEX('Revenue Assumptions'!$F$175:$P$175,MATCH((2000+VALUE(RIGHT(K$6,2))),'Revenue Assumptions'!$F$35:$P$35,0))*Scenarios!$B$6,0) -> 1896250 | L24: =IF(L8=1,INDEX('Revenue Assumptions'!$F$175:$P$175,MATCH((2000+VALUE(RIGHT(L$6,2))),'Revenue Assumptions'!$F$35:$P$35,0))*Scenarios!$B$6,0) -> 1943656.2 | M24: =IF(M8=1,INDEX('Revenue Assumptions'!$F$175:$P$175,MATCH((2000+VALUE(RIGHT(M$6,2))),'Revenue Assumptions'!$F$35:$P$35,0))*Scenarios!$B$6,0) -> 1992247.7 | N24: =IF(N8=1,INDEX('Revenue Assumptions'!$F$175:$P$175,MATCH((2000+VALUE(RIGHT(N$6,2))),'Revenue Assumptions'!$F$35:$P$35,0))*Scenarios!$B$6,0) -> 2042053.8 | O24: =IF(O8=1,INDEX('Revenue Assumptions'!$F$175:$P$175,MATCH((2000+VALUE(RIGHT(O$6,2))),'Revenue Assumptions'!$F$35:$P$35,0))*Scenarios!$B$6,0) -> 2093105.2 | ... S24: =IF(S8=1,INDEX('Revenue Assumptions'!$F$175:$P$175,MATCH((2000+VALUE(RIGHT(S$6,2))),'Revenue Assumptions'!$F$35:$P$35,0))*Scenarios!$B$6,0) -> 2310396.5
C25: Advertising | H25: =(IF(H8=1,INDEX('Revenue Assumptions'!$F$183:$P$183,MATCH((2000+VALUE(RIGHT(H$6,2))),'Revenue Assumptions'!$F$35:$P$35,0))*Scenarios!$B$6,0)) -> 0 | I25: =(IF(I8=1,INDEX('Revenue Assumptions'!$F$183:$P$183,MATCH((2000+VALUE(RIGHT(I$6,2))),'Revenue Assumptions'!$F$35:$P$35,0))*Scenarios!$B$6,0)) -> 0 | J25: =(IF(J8=1,INDEX('Revenue Assumptions'!$F$183:$P$183,MATCH((2000+VALUE(RIGHT(J$6,2))),'Revenue Assumptions'!$F$35:$P$35,0))*Scenarios!$B$6,0)) -> 0 | K25: =(IF(K8=1,INDEX('Revenue Assumptions'!$F$183:$P$183,MATCH((2000+VALUE(RIGHT(K$6,2))),'Revenue Assumptions'!$F$35:$P$35,0))*Scenarios!$B$6,0)) -> 589375 | L25: =(IF(L8=1,INDEX('Revenue Assumptions'!$F$183:$P$183,MATCH((2000+VALUE(RIGHT(L$6,2))),'Revenue Assumptions'!$F$35:$P$35,0))*Scenarios!$B$6,0)) -> 604109.37 | M25: =(IF(M8=1,INDEX('Revenue Assumptions'!$F$183:$P$183,MATCH((2000+VALUE(RIGHT(M$6,2))),'Revenue Assumptions'!$F$35:$P$35,0))*Scenarios!$B$6,0)) -> 619212.11 | N25: =(IF(N8=1,INDEX('Revenue Assumptions'!$F$183:$P$183,MATCH((2000+VALUE(RIGHT(N$6,2))),'Revenue Assumptions'!$F$35:$P$35,0))*Scenarios!$B$6,0)) -> 634692.41 | O25: =(IF(O8=1,INDEX('Revenue Assumptions'!$F$183:$P$183,MATCH((2000+VALUE(RIGHT(O$6,2))),'Revenue Assumptions'!$F$35:$P$35,0))*Scenarios!$B$6,0)) -> 650559.72 | ... S25: =(IF(S8=1,INDEX('Revenue Assumptions'!$F$183:$P$183,MATCH((2000+VALUE(RIGHT(S$6,2))),'Revenue Assumptions'!$F$35:$P$35,0))*Scenarios!$B$6,0)) -> 718096.21
C26: ="Total "& C23 -> Total Non-event day revenue | H26: =H24+H25 -> 0 | I26: =I24+I25 -> 0 | J26: =J24+J25 -> 0 | K26: =K24+K25 -> 2485625 | L26: =L24+L25 -> 2547765.6 | M26: =M24+M25 -> 2611459.8 | N26: =N24+N25 -> 2676746.3 | O26: =O24+O25 -> 2743664.9 | ... S26: =S24+S25 -> 3028492.7
C28: Total Revenue | H28: =H21+H26 -> 0 | I28: =I21+I26 -> 0 | J28: =J21+J26 -> 0 | K28: =K21+K26 -> 18192909 | L28: =L21+L26 -> 19173295 | M28: =M21+M26 -> 20282270 | N28: =N21+N26 -> 20817159 | O28: =O21+O26 -> 21296978 | ... S28: =S21+S26 -> 23361053
B30: COGS
C31: Food & Beverage
C32: CoG F&B (GA) | H32: =H17*Inputs!$E$250*Scenarios!$B$7 -> 0 | I32: =I17*Inputs!$E$250*Scenarios!$B$7 -> 0 | J32: =J17*Inputs!$E$250*Scenarios!$B$7 -> 0 | K32: =K17*Inputs!$E$250*Scenarios!$B$7 -> 31834.62 | L32: =L17*Inputs!$E$250*Scenarios!$B$7 -> 33471.282 | M32: =M17*Inputs!$E$250*Scenarios!$B$7 -> 35874.9 | N32: =N17*Inputs!$E$250*Scenarios!$B$7 -> 35874.9 | O32: =O17*Inputs!$E$250*Scenarios!$B$7 -> 36951.147 | ... S32: =S17*Inputs!$E$250*Scenarios!$B$7 -> 41588.841
C33: CoG F&B (Premium) | H33: =H16*Inputs!$E$250*Scenarios!$B$7 -> 0 | I33: =I16*Inputs!$E$250*Scenarios!$B$7 -> 0 | J33: =J16*Inputs!$E$250*Scenarios!$B$7 -> 0 | K33: =K16*Inputs!$E$250*Scenarios!$B$7 -> 33471.282 | L33: =L16*Inputs!$E$250*Scenarios!$B$7 -> 35874.9 | M33: =M16*Inputs!$E$250*Scenarios!$B$7 -> 35874.9 | N33: =N16*Inputs!$E$250*Scenarios!$B$7 -> 36951.147 | O33: =O16*Inputs!$E$250*Scenarios!$B$7 -> 38059.681 | ... S33: =S16*Inputs!$E$250*Scenarios!$B$7 -> 42836.507
C34: Consumables | H34: =(H16+H17)*Inputs!$E$251*Scenarios!$B$7 -> 0 | I34: =(I16+I17)*Inputs!$E$251*Scenarios!$B$7 -> 0 | J34: =(J16+J17)*Inputs!$E$251*Scenarios!$B$7 -> 0 | K34: =(K16+K17)*Inputs!$E$251*Scenarios!$B$7 -> 10884.317 | L34: =(L16+L17)*Inputs!$E$251*Scenarios!$B$7 -> 11557.697 | M34: =(M16+M17)*Inputs!$E$251*Scenarios!$B$7 -> 11958.3 | N34: =(N16+N17)*Inputs!$E$251*Scenarios!$B$7 -> 12137.675 | O34: =(O16+O17)*Inputs!$E$251*Scenarios!$B$7 -> 12501.805 | ... S34: =(S16+S17)*Inputs!$E$251*Scenarios!$B$7 -> 14070.891
C35: F&B RM | H35: =0 -> 0 | I35: =0 -> 0 | J35: =0 -> 0 | K35: =0 -> 0 | L35: =0 -> 0 | M35: =0 -> 0 | N35: =0 -> 0 | O35: =0 -> 0 | ... S35: =0 -> 0
C36: Total COGS | H36: =SUM(H32:H35) -> 0 | I36: =SUM(I32:I35) -> 0 | J36: =SUM(J32:J35) -> 0 | K36: =SUM(K32:K35) -> 76190.219 | L36: =SUM(L32:L35) -> 80903.879 | M36: =SUM(M32:M35) -> 83708.1 | N36: =SUM(N32:N35) -> 84963.721 | O36: =SUM(O32:O35) -> 87512.633 | ... S36: =SUM(S32:S35) -> 98496.24
J37: =SUM(J33:J36) -> 0
C38: COGS Margin | H38: =IF(H28=0,"",H36/H28) | I38: =IF(I28=0,"",I36/I28) | J38: =IF(J28=0,"",J36/J28) | K38: =IF(K28=0,"",K36/K28) -> 0.0041879073 | L38: =IF(L28=0,"",L36/L28) -> 0.0042196127 | M38: =IF(M28=0,"",M36/M28) -> 0.0041271563 | N38: =IF(N28=0,"",N36/N28) -> 0.0040814274 | O38: =IF(O28=0,"",O36/O28) -> 0.0041091573 | ... S38: =IF(S28=0,"",S36/S28) -> 0.0042162585
B40: GROSS PROFIT
C41: Gross Profit | H41: =H28-H36 -> 0 | I41: =I28-I36 -> 0 | J41: =J28-J36 -> 0 | K41: =K28-K36 -> 18116719 | L41: =L28-L36 -> 19092391 | M41: =M28-M36 -> 20198562 | N41: =N28-N36 -> 20732195 | O41: =O28-O36 -> 21209466 | ... S41: =S28-S36 -> 23262557
C42: GPM | H42: =IF(H28=0,"",H41/H28) | I42: =IF(I28=0,"",I41/I28) | J42: =IF(J28=0,"",J41/J28) | K42: =IF(K28=0,"",K41/K28) -> 0.99581209 | L42: =IF(L28=0,"",L41/L28) -> 0.99578039 | M42: =IF(M28=0,"",M41/M28) -> 0.99587284 | N42: =IF(N28=0,"",N41/N28) -> 0.99591857 | O42: =IF(O28=0,"",O41/O28) -> 0.99589084 | ... S42: =IF(S28=0,"",S41/S28) -> 0.99578374
B44: OPERATING EXPENSES
C45: Leased equipment | H45: =IF(H$8=1,Inputs!$E$227*Scenarios!$B$7,0) -> 0 | I45: =IF(I$8=1,Inputs!$E$227*Scenarios!$B$7,0) -> 0 | J45: =IF(J$8=1,Inputs!$E$227*Scenarios!$B$7,0) -> 0 | K45: =IF(K$8=1,Inputs!$E$227*Scenarios!$B$7,0) -> 350000 | L45: =IF(L$8=1,Inputs!$E$227*Scenarios!$B$7,0) -> 350000 | M45: =IF(M$8=1,Inputs!$E$227*Scenarios!$B$7,0) -> 350000 | N45: =IF(N$8=1,Inputs!$E$227*Scenarios!$B$7,0) -> 350000 | O45: =IF(O$8=1,Inputs!$E$227*Scenarios!$B$7,0) -> 350000 | ... S45: =IF(S$8=1,Inputs!$E$227*Scenarios!$B$7,0) -> 350000
C46: Utilities | H46: =IF(H8=1,Inputs!$E$228*(1+Inputs!$E$310)^((2000+VALUE(RIGHT(H$6,2)))-2027)*Scenarios!$B$7,0) -> 0 | I46: =IF(I8=1,Inputs!$E$228*(1+Inputs!$E$310)^((2000+VALUE(RIGHT(I$6,2)))-2027)*Scenarios!$B$7,0) -> 0 | J46: =IF(J8=1,Inputs!$E$228*(1+Inputs!$E$310)^((2000+VALUE(RIGHT(J$6,2)))-2027)*Scenarios!$B$7,0) -> 0 | K46: =IF(K8=1,Inputs!$E$228*(1+Inputs!$E$310)^((2000+VALUE(RIGHT(K$6,2)))-2027)*Scenarios!$B$7,0) -> 206000 | L46: =IF(L8=1,Inputs!$E$228*(1+Inputs!$E$310)^((2000+VALUE(RIGHT(L$6,2)))-2027)*Scenarios!$B$7,0) -> 212180 | M46: =IF(M8=1,Inputs!$E$228*(1+Inputs!$E$310)^((2000+VALUE(RIGHT(M$6,2)))-2027)*Scenarios!$B$7,0) -> 218545.4 | N46: =IF(N8=1,Inputs!$E$228*(1+Inputs!$E$310)^((2000+VALUE(RIGHT(N$6,2)))-2027)*Scenarios!$B$7,0) -> 225101.76 | O46: =IF(O8=1,Inputs!$E$228*(1+Inputs!$E$310)^((2000+VALUE(RIGHT(O$6,2)))-2027)*Scenarios!$B$7,0) -> 231854.81 | ... S46: =IF(S8=1,Inputs!$E$228*(1+Inputs!$E$310)^((2000+VALUE(RIGHT(S$6,2)))-2027)*Scenarios!$B$7,0) -> 260954.64
C47: Maintenance (R&M) | H47: =IF(H8=1,INDEX('Expense Assumptions'!$F$86:$Q$86,MATCH((2000+VALUE(RIGHT(H$6,2))),'Expense Assumptions'!$F$21:$Q$21,0))*Scenarios!$B$7,0) -> 0 | I47: =IF(I8=1,INDEX('Expense Assumptions'!$F$86:$Q$86,MATCH((2000+VALUE(RIGHT(I$6,2))),'Expense Assumptions'!$F$21:$Q$21,0))*Scenarios!$B$7,0) -> 0 | J47: =IF(J8=1,INDEX('Expense Assumptions'!$F$86:$Q$86,MATCH((2000+VALUE(RIGHT(J$6,2))),'Expense Assumptions'!$F$21:$Q$21,0))*Scenarios!$B$7,0) -> 0 | K47: =IF(K8=1,INDEX('Expense Assumptions'!$F$86:$Q$86,MATCH((2000+VALUE(RIGHT(K$6,2))),'Expense Assumptions'!$F$21:$Q$21,0))*Scenarios!$B$7,0) -> 149350 | L47: =IF(L8=1,INDEX('Expense Assumptions'!$F$86:$Q$86,MATCH((2000+VALUE(RIGHT(L$6,2))),'Expense Assumptions'!$F$21:$Q$21,0))*Scenarios!$B$7,0) -> 153830.5 | M47: =IF(M8=1,INDEX('Expense Assumptions'!$F$86:$Q$86,MATCH((2000+VALUE(RIGHT(M$6,2))),'Expense Assumptions'!$F$21:$Q$21,0))*Scenarios!$B$7,0) -> 158445.42 | N47: =IF(N8=1,INDEX('Expense Assumptions'!$F$86:$Q$86,MATCH((2000+VALUE(RIGHT(N$6,2))),'Expense Assumptions'!$F$21:$Q$21,0))*Scenarios!$B$7,0) -> 163198.78 | O47: =IF(O8=1,INDEX('Expense Assumptions'!$F$86:$Q$86,MATCH((2000+VALUE(RIGHT(O$6,2))),'Expense Assumptions'!$F$21:$Q$21,0))*Scenarios!$B$7,0) -> 168094.74 | ... S47: =IF(S8=1,INDEX('Expense Assumptions'!$F$86:$Q$86,MATCH((2000+VALUE(RIGHT(S$6,2))),'Expense Assumptions'!$F$21:$Q$21,0))*Scenarios!$B$7,0) -> 189192.11
C48: Marketing | H48: =IF(H8=1,Inputs!$E$229*(1+Inputs!$E$308)^((2000+VALUE(RIGHT(H$6,2)))-2027)*Scenarios!$B$7,0) -> 0 | I48: =IF(I8=1,Inputs!$E$229*(1+Inputs!$E$308)^((2000+VALUE(RIGHT(I$6,2)))-2027)*Scenarios!$B$7,0) -> 0 | J48: =IF(J8=1,Inputs!$E$229*(1+Inputs!$E$308)^((2000+VALUE(RIGHT(J$6,2)))-2027)*Scenarios!$B$7,0) -> 0 | K48: =IF(K8=1,Inputs!$E$229*(1+Inputs!$E$308)^((2000+VALUE(RIGHT(K$6,2)))-2027)*Scenarios!$B$7,0) -> 51500 | L48: =IF(L8=1,Inputs!$E$229*(1+Inputs!$E$308)^((2000+VALUE(RIGHT(L$6,2)))-2027)*Scenarios!$B$7,0) -> 53045 | M48: =IF(M8=1,Inputs!$E$229*(1+Inputs!$E$308)^((2000+VALUE(RIGHT(M$6,2)))-2027)*Scenarios!$B$7,0) -> 54636.35 | N48: =IF(N8=1,Inputs!$E$229*(1+Inputs!$E$308)^((2000+VALUE(RIGHT(N$6,2)))-2027)*Scenarios!$B$7,0) -> 56275.44 | O48: =IF(O8=1,Inputs!$E$229*(1+Inputs!$E$308)^((2000+VALUE(RIGHT(O$6,2)))-2027)*Scenarios!$B$7,0) -> 57963.704 | ... S48: =IF(S8=1,Inputs!$E$229*(1+Inputs!$E$308)^((2000+VALUE(RIGHT(S$6,2)))-2027)*Scenarios!$B$7,0) -> 65238.659
...

Sheet Balance Sheet
A1: Balance Sheet
A2: Port Melbourne Live House
B4: FY Start | F4: ='P&L'!H4 -> 45715 | G4: ='P&L'!I4 -> 45839 | H4: ='P&L'!J4 -> 46204 | I4: ='P&L'!K4 -> 46569 | J4: ='P&L'!L4 -> 46935 | K4: ='P&L'!M4 -> 47300 | L4: ='P&L'!N4 -> 47665 | M4: ='P&L'!O4 -> 48030 | ... Q4: ='P&L'!S4 -> 49491
B5: FY End | F5: ='P&L'!H5 -> 45838 | G5: ='P&L'!I5 -> 46203 | H5: ='P&L'!J5 -> 46568 | I5: ='P&L'!K5 -> 46934 | J5: ='P&L'!L5 -> 47299 | K5: ='P&L'!M5 -> 47664 | L5: ='P&L'!N5 -> 48029 | M5: ='P&L'!O5 -> 48395 | ... Q5: ='P&L'!S5 -> 49856
B6: Year | F6: ='P&L'!H6 -> FY25 | G6: ='P&L'!I6 -> FY26 | H6: ='P&L'!J6 -> FY27 | I6: ='P&L'!K6 -> FY28 | J6: ='P&L'!L6 -> FY29 | K6: ='P&L'!M6 -> FY30 | L6: ='P&L'!N6 -> FY31 | M6: ='P&L'!O6 -> FY32 | ... Q6: ='P&L'!S6 -> FY36
B8: ASSETS
C9: Current Assets
D10: Cash | F10: =Cashflow!D37 -> 0 | G10: =Cashflow!E37 -> 1707500 | H10: =Cashflow!F37 -> 16050500 | I10: =Cashflow!G37 -> -1231018.3 | J10: =Cashflow!H37 -> -396007.99 | K10: =Cashflow!I37 -> 513409.17 | L10: =Cashflow!J37 -> 1533142.7 | M10: =Cashflow!K37 -> 2307422.4 | ... Q10: =Cashflow!O37 -> 1.4219797e+08
D11: Community Fund Reserve (Restricted Cash) | F11: =0 -> 0 | G11: =F11 -> 0 | H11: =G11 -> 0 | I11: =H11+'P&L'!K100 -> 139159.72 | J11: =I11+'P&L'!L100 -> 281212.26 | K11: =J11+'P&L'!M100 -> 433465.79 | L11: =K11+'P&L'!N100 -> 585719.31 | M11: =L11+'P&L'!O100 -> 737972.84 | N11: =M11+'P&L'!P100 -> 890226.36 | O11: =N11+'P&L'!Q100 -> 1042479.9 | P11: =O11+'P&L'!R100 -> 1194733.4 | Q11: =P11+'P&L'!S100 -> 1346986.9
D12: Accounts receivable | F12: =INDEX(Cashflow!$D$52:$O$52,MATCH(F$6,Cashflow!$D$42:$O$42,0)) -> 0 | G12: =INDEX(Cashflow!$D$52:$O$52,MATCH(G$6,Cashflow!$D$42:$O$42,0)) -> 0 | H12: =INDEX(Cashflow!$D$52:$O$52,MATCH(H$6,Cashflow!$D$42:$O$42,0)) -> 0 | I12: =INDEX(Cashflow!$D$52:$O$52,MATCH(I$6,Cashflow!$D$42:$O$42,0)) -> 1495307.6 | J12: =INDEX(Cashflow!$D$52:$O$52,MATCH(J$6,Cashflow!$D$42:$O$42,0)) -> 1575887.3 | K12: =INDEX(Cashflow!$D$52:$O$52,MATCH(K$6,Cashflow!$D$42:$O$42,0)) -> 1667035.9 | L12: =INDEX(Cashflow!$D$52:$O$52,MATCH(L$6,Cashflow!$D$42:$O$42,0)) -> 1710999.3 | M12: =INDEX(Cashflow!$D$52:$O$52,MATCH(M$6,Cashflow!$D$42:$O$42,0)) -> 1750436.6 | ... Q12: =INDEX(Cashflow!$D$52:$O$52,MATCH(Q$6,Cashflow!$D$42:$O$42,0)) -> 1920086.6
D13: Inventory | F13: =INDEX(Cashflow!$D$53:$O$53,MATCH(F$6,Cashflow!$D$42:$O$42,0)) -> 0 | G13: =INDEX(Cashflow!$D$53:$O$53,MATCH(G$6,Cashflow!$D$42:$O$42,0)) -> 0 | H13: =INDEX(Cashflow!$D$53:$O$53,MATCH(H$6,Cashflow!$D$42:$O$42,0)) -> 0 | I13: =INDEX(Cashflow!$D$53:$O$53,MATCH(I$6,Cashflow!$D$42:$O$42,0)) -> 3131.1049 | J13: =INDEX(Cashflow!$D$53:$O$53,MATCH(J$6,Cashflow!$D$42:$O$42,0)) -> 3324.8169 | K13: =INDEX(Cashflow!$D$53:$O$53,MATCH(K$6,Cashflow!$D$42:$O$42,0)) -> 3440.0589 | L13: =INDEX(Cashflow!$D$53:$O$53,MATCH(L$6,Cashflow!$D$42:$O$42,0)) -> 3491.6598 | M13: =INDEX(Cashflow!$D$53:$O$53,MATCH(M$6,Cashflow!$D$42:$O$42,0)) -> 3596.4096 | ... Q13: =INDEX(Cashflow!$D$53:$O$53,MATCH(Q$6,Cashflow!$D$42:$O$42,0)) -> 4047.7907
C15: Total current assets | F15: =SUM(F10:F13) -> 0 | G15: =SUM(G10:G13) -> 1707500 | H15: =SUM(H10:H13) -> 16050500 | I15: =SUM(I10:I13) -> 406580.19 | J15: =SUM(J10:J13) -> 1464416.3 | K15: =SUM(K10:K13) -> 2617350.9 | L15: =SUM(L10:L13) -> 3833353 | M15: =SUM(M10:M13) -> 4799428.2 | ... Q15: =SUM(Q10:Q13) -> 1.4546909e+08
C17: Non-Current Assets
D18: Lease deposit / bond | F18: ='Construction Timeline'!D170 -> 0 | G18: ='Construction Timeline'!E170 -> 780000 | H18: ='Construction Timeline'!F170 -> 780000 | I18: ='Construction Timeline'!G170 -> 780000 | J18: ='Construction Timeline'!H170 -> 780000 | K18: ='Construction Timeline'!I170 -> 780000 | L18: ='Construction Timeline'!J170 -> 780000 | M18: ='Construction Timeline'!K170 -> 780000 | ... Q18: ='Construction Timeline'!O170 -> 780000
D19: Work in Progress (WIP) | F19: ='Construction Timeline'!D166 -> 0 | G19: ='Construction Timeline'!E166 -> 0 | H19: ='Construction Timeline'!F166 -> 0 | I19: ='Construction Timeline'!G166 -> 17758000 | J19: ='Construction Timeline'!H166 -> 17758000 | K19: ='Construction Timeline'!I166 -> 17758000 | L19: ='Construction Timeline'!J166 -> 17758000 | M19: ='Construction Timeline'!K166 -> 17758000 | ... Q19: ='Construction Timeline'!O166 -> 17758000
D20: Property, Plant & Equipment (gross) | F20: ='Construction Timeline'!D177 -> 0 | G20: ='Construction Timeline'!E177 -> 0 | H20: ='Construction Timeline'!F177 -> 0 | I20: ='Construction Timeline'!G177 -> 0 | J20: ='Construction Timeline'!H177 -> 0 | K20: ='Construction Timeline'!I177 -> 0 | L20: ='Construction Timeline'!J177 -> 0 | M20: ='Construction Timeline'!K177 -> 0 | ... Q20: ='Construction Timeline'!O177 -> 0
D21: Accumulated depreciation | F21: =-'Construction Timeline'!D181 -> 0 | G21: =-'Construction Timeline'!E181 -> 0 | H21: =-'Construction Timeline'!F181 -> 0 | I21: =-'Construction Timeline'!G181 -> 0 | J21: =-'Construction Timeline'!H181 -> 0 | K21: =-'Construction Timeline'!I181 -> 0 | L21: =-'Construction Timeline'!J181 -> 0 | M21: =-'Construction Timeline'!K181 -> 0 | ... Q21: =-'Construction Timeline'!O181 -> 0
D22: PPE (net) | F22: ='Construction Timeline'!D183 -> 0 | G22: ='Construction Timeline'!E183 -> 0 | H22: ='Construction Timeline'!F183 -> 0 | I22: ='Construction Timeline'!G183 -> 0 | J22: ='Construction Timeline'!H183 -> 0 | K22: ='Construction Timeline'!I183 -> 0 | L22: ='Construction Timeline'!J183 -> 0 | M22: ='Construction Timeline'!K183 -> 0 | ... Q22: ='Construction Timeline'!O183 -> 0
C23: Total Non-Current Assets | F23: =F18+F19+F22 -> 0 | G23: =G18+G19+G22 -> 780000 | H23: =H18+H19+H22 -> 780000 | I23: =I18+I19+I22 -> 18538000 | J23: =J18+J19+J22 -> 18538000 | K23: =K18+K19+K22 -> 18538000 | L23: =L18+L19+L22 -> 18538000 | M23: =M18+M19+M22 -> 18538000 | ... Q23: =Q18+Q19+Q22 -> 18538000
C25: Total Assets | F25: =F15+F23 -> 0 | G25: =G15+G23 -> 2487500 | H25: =H15+H23 -> 16830500 | I25: =I15+I23 -> 18944580 | J25: =J15+J23 -> 20002416 | K25: =K15+K23 -> 21155351 | L25: =L15+L23 -> 22371353 | M25: =M15+M23 -> 23337428 | ... Q25: =Q15+Q23 -> 1.6400709e+08
C26: NWC (AR + Inv – AP – Deferred rev) | F26: =F12+F13-IFERROR(INDEX(Cashflow!$D$54:$O$54,MATCH(F$6,Cashflow!$D$42:$O$42,0)),0)-F32 -> 0 | G26: =G12+G13-IFERROR(INDEX(Cashflow!$D$54:$O$54,MATCH(G$6,Cashflow!$D$42:$O$42,0)),0)-G32 -> 0 | H26: =H12+H13-IFERROR(INDEX(Cashflow!$D$54:$O$54,MATCH(H$6,Cashflow!$D$42:$O$42,0)),0)-H32 -> 0 | I26: =I12+I13-IFERROR(INDEX(Cashflow!$D$54:$O$54,MATCH(I$6,Cashflow!$D$42:$O$42,0)),0)-I32 -> 981418.65 | J26: =J12+J13-IFERROR(INDEX(Cashflow!$D$54:$O$54,MATCH(J$6,Cashflow!$D$42:$O$42,0)),0)-J32 -> 990885.44 | K26: =K12+K13-IFERROR(INDEX(Cashflow!$D$54:$O$54,MATCH(K$6,Cashflow!$D$42:$O$42,0)),0)-K32 -> 1059057.8 | L26: =L12+L13-IFERROR(INDEX(Cashflow!$D$54:$O$54,MATCH(L$6,Cashflow!$D$42:$O$42,0)),0)-L32 -> 1092336.7 | M26: =M12+M13-IFERROR(INDEX(Cashflow!$D$54:$O$54,MATCH(M$6,Cashflow!$D$42:$O$42,0)),0)-M32 -> 1108245.3 | ... Q26: =Q12+Q13-IFERROR(INDEX(Cashflow!$D$54:$O$54,MATCH(Q$6,Cashflow!$D$42:$O$42,0)),0)-Q32 -> 1126799
B28: LIABILITIES
C29: Current Liabilities
D30: Accounts payable / accruals | F30: =IFERROR(F25-(F31+F36+F32)-F44,0) -> 0 | G30: =IFERROR(G25-(G31+G36+G32)-G44,0) -> 0 | H30: =IFERROR(H25-(H31+H36+H32)-H44,0) -> 0 | I30: =IFERROR(I25-(I31+I36+I32)-I44,0) -> 1415370 | J30: =IFERROR(J25-(J31+J36+J32)-J44,0) -> 1709633 | K30: =IFERROR(K25-(K31+K36+K32)-K44,0) -> 1968686.1 | L30: =IFERROR(L25-(L31+L36+L32)-L44,0) -> 2216639.5 | M30: =IFERROR(M25-(M31+M36+M32)-M44,0) -> 2111219.1 | ... Q30: =IFERROR(Q25-(Q31+Q36+Q32)-Q44,0) -> 1.3839911e+08
D31: Borrowings – current | F31: =INDEX(Debt!$H$49:$S$49, MATCH(F$6, Debt!$H$14:$S$14,0)) -> 0 | G31: =INDEX(Debt!$H$49:$S$49, MATCH(G$6, Debt!$H$14:$S$14,0)) -> 0 | H31: =INDEX(Debt!$H$49:$S$49, MATCH(H$6, Debt!$H$14:$S$14,0)) -> 1024500 | I31: =INDEX(Debt!$H$49:$S$49, MATCH(I$6, Debt!$H$14:$S$14,0)) -> 1024500 | J31: =INDEX(Debt!$H$49:$S$49, MATCH(J$6, Debt!$H$14:$S$14,0)) -> 1024500 | K31: =INDEX(Debt!$H$49:$S$49, MATCH(K$6, Debt!$H$14:$S$14,0)) -> 1024500 | L31: =INDEX(Debt!$H$49:$S$49, MATCH(L$6, Debt!$H$14:$S$14,0)) -> 1024500 | M31: =INDEX(Debt!$H$49:$S$49, MATCH(M$6, Debt!$H$14:$S$14,0)) -> 1024500 | ... Q31: =INDEX(Debt!$H$49:$S$49, MATCH(Q$6, Debt!$H$14:$S$14,0)) -> 0
