Workbook
Name CF_Report?: Summary!$A$37
Name ConstDebt_Payoff: Underwriting!$E$75
Name CU?: Underwriting!$EQ$207
Name Dbl_Promote?: Underwriting!$A$220
Name Debt_LTC_Actual: Underwriting!$F$61
Name Debt_LTC_Target: Underwriting!$C$61
Name Debt_Total: Underwriting!$I$61
Name Dev_Spread: Underwriting!$I$5
Name EGR_0: Underwriting!$L$130
Name Equity_Total: Underwriting!$I$60
Name Fixed_Variable: Underwriting!$A$62
Name Interest_Const_Loan: Underwriting!$E$65
Name Interest_Mezz_Loan: Underwriting!$E$66
Name Investment_Name: Underwriting!$E$9
Name Items_Hard_Costs: Underwriting!$ER$38
Name Items_Industrial_Tenants: Underwriting!$I$91
Name Items_Land_Costs: Underwriting!$ER$31
Name Items_Opex: Underwriting!$ER$138
Name Items_Soft_Costs: Underwriting!$ER$47
Name Land_Value: Underwriting!$I$27
Name LeaseUp_Formula: Underwriting!$L$89
Name Mgmt_Fee_0: Underwriting!$L$135
Name Mgmt_Fee_Pct: Underwriting!$G$135
Name Nav_Development_CF: Underwriting!$B$23:$I$85
Name Nav_Industrial_Expenses: Underwriting!$B$132:$I$141
Name Nav_Industrial_Reserves: Underwriting!$B$142:$I$151
Name Nav_Investment_Description: Underwriting!$B$8:$I$21
Name Nav_Operating_CF: Underwriting!$B$86:$I$158
Name Nav_Operating_Expenses_Summary: Underwriting!$B$152:$I$155
Name Nav_Residual_CF: Underwriting!$B$159:$I$193
Name Nav_Sensitivity: Underwriting!$B$269:$I$286
Name Nav_Waterfall_CF: Underwriting!$B$194:$I$246
Name OpEx_6: Underwriting!$I$152
Name OpEx_7: Underwriting!$I$153
Name OpEx_Ins: Underwriting!$I$155
Name OpEx_MgtFee: Underwriting!$I$154
Name Perm_Debt?: Underwriting!$A$79
Name PermDebt_Fund: Underwriting!$C$82
Name PermDebt_Payoff: Underwriting!$C$83
Name Project_Cost_Total: Underwriting!$I$57
Name Proxy_Fee: Underwriting!$G$290
Name Range_Building_Type: Data!$B$25:INDEX(Data!$B$25:$B$46,COUNTA(Data!$B$25:$B$46))
Name Range_Debt: Underwriting!$L$75:INDEX(Underwriting!$L$75:$EN$75,1,Timing_Reversion_Month+1)
Name Range_Equity: Underwriting!$L$69:INDEX(Underwriting!$L$69:$EN$69,1,Timing_Reversion_Month+1)
Name Range_LeaseUp: Underwriting!$M$89:$EN$89
Name Range_Levered_CF: Underwriting!$L$212:INDEX(Underwriting!$L$212:$EN$212,1,Timing_Reversion_Month+1)
Name Range_Months: Underwriting!$L$86:INDEX(Underwriting!$L$86:$EN$86,1,Timing_Reversion_Month+1)
Name Range_NOI: Underwriting!$L$140:INDEX(Underwriting!$L$140:$EN$140,1,Timing_Reversion_Month+1)
Name Range_PermDebt: Underwriting!$80:$84
Name Range_PermDS: Underwriting!$156:$157
Name Range_Tenant_Type: Data!$D$25:INDEX(Data!$D$25:$D$46,COUNTA(Data!$D$25:$D$46))
Name Range_Total_Cost: Underwriting!$L$57:INDEX(Underwriting!$L$57:$EN$57,1,Timing_Reversion_Month+1)
Name Recalc?: Underwriting!$C$292
Name Recalc_Const: Underwriting!$C$290
Name Recalc_Mgmt: Underwriting!$C$291
Name Rel_2nd_Promote: Underwriting!$A$247:$A$267
Name Rel_Calc: Underwriting!$EP$1:$JX$1
Name Rel_EGR_ProForma: Underwriting!$I$130
Name Rel_End: Underwriting!$A$287
Name Rel_Hard_Costs: Underwriting!$A$38

Sheet Summary
B2: =Underwriting!B2 -> THE BEND ENTERTAINMENT PRECINCT | S2: =UPPER(Underwriting!I2) -> MAYABAY ACTIVE (MELBOURNE) PTY LTD
B3: =Underwriting!E11&", "&Underwriting!I10 -> Port Melbourne, VIC | S3: ="ANALYSIS START - "&UPPER(TEXT(Underwriting!E13,"MMM YYYY")) -> ANALYSIS START - JUL 2026
B4: INVESTMENT DESCRIPTION | Q4: Run Residual Land Value Tool
B5: Address | F5: =Underwriting!E10&", "&Underwriting!E11&" "&Underwriting!I10 -> Port Melbourne, Port Melbourne VIC | G5: STRENGTHS | N5: MODEL GOVERNANCE & CONTROL STATUS
B6: ="Net Rentable Area ("&Unit_Type&")" -> Net Rentable Area (M2) | F6: ='VALUATION & RETURNS'!$CS$38 -> 78470.38 | G6: Large Fishermans Bend urban-renewal location | N6: Purpose | O6: Integrated development, debt, valuation and investor-return model for The Bend Precinct.
B7: Land Area | F7: =Underwriting!$E$17 -> 8.5004251 | G7: Diversified leisure, PBSA and ancillary uses | N7: Audience | O7: Management, prospective investors and lenders; not a substitute for legal, tax, valuation or lender advice.
B8: Retail Type | F8: ="Mixed-use entertainment, leisure, PBSA and ancillary precinct" -> Mixed-use entertainment, leisure, PBSA and ancillary precinct | G8: Integrated property and operating schedules | N8: Version | O8: V16 | 1 Aug 2026 | Phase 11 exact S-curve compatibility modernisation applied; full desktop-Excel recalculation remains required.
B9: # of Retail Buildings | F9: ="Multiple component buildings — see component tabs" -> Multiple component buildings — see component tabs | G9: Livehouse is quick to market operation. | N9: Input hub | O9: PROJECT INPUTS is the sole ProjectCo assumption hub. Detailed source-evidence rows remain read-only and are not calculation inputs.
B10: Parking (Surfaces + Structured) | F10: =SUM(Underwriting!$E$20:$E$21) -> 353.11671 | G10: Reduced single-use concentration risk | N10: Scenario control | O10: Authoritative ProjectCo scenario: PROJECT INPUTS!B8. VALUATION & RETURNS!CR7 and INVESTOR REPORT!I3 are formula-linked displays.
B11: Analysis Start | E11: 1 | F11: =Underwriting!$E$13 -> 46204 | G11: Sustainability and green-building objectives | N11: Period status | O11: Forecast-only base model. Explicit Actual / Forecast classification is shown at Underwriting!L4:EN4.
B12: Construction Start | E12: 1 | F12: =Underwriting!$E$13 -> 46204 | G12: WEAKNESSES | N12: Balance sheet control | O12: =IFERROR(IF(MAX(MAX('Financial Statements'!$G$50:$X$50),-MIN('Financial Statements'!$G$50:$X$50))<=1,"PASS","FAIL"),"PENDING RECALC") -> FAIL
B13: Construction End | E13: =Timing_Construction_End -> 36 | F13: =EOMONTH(Underwriting!$E$13,Underwriting!$D$88-2) -> 47299 | G13: Commercial assumptions remain provisional | N13: Sources and uses control | O13: =IFERROR(IF(ABS(Underwriting!$I$57-SUM(Underwriting!$I$69,Underwriting!$I$75))<0.01,"PASS","FAIL"),"PENDING RECALC") -> FAIL
B14: Operation Begin | E14: =Timing_Operation_Begin_Month -> 37 | F14: =EOMONTH(F13,1) -> 47330 | G14: Independent valuation evidence required | N14: Debt roll-forward control | O14: =IFERROR(IF(AND(MAX(MAX(DEBT!$F$96:$DV$96),-MIN(DEBT!$F$96:$DV$96))<=0.01,MAX(MAX(DEBT!$F$136:$DV$136),-MIN(DEBT!$F$136:$DV$136))<=0.01),"PASS","FAIL"),"PENDING RECALC") -> FAIL
B15: Stabilization | E15: =Stabilization_1st_Month -> 49 | F15: =EOMONTH(Underwriting!$E$13,Underwriting!$D$89-1) -> 47695 | G15: Executed lender terms remain outstanding | N15: Macros / calculation | O15: Existing VBA retained. Full recalculation is forced on open; external reliance remains gated until owner decisions and specialist tax, lender, valuation and QS confirmation are complete.
B16: Sale Date | E16: =Timing_Reversion_Month -> 61 | F16: =Underwriting!$I$15 -> 48030 | G16: Final QS scope and cost sign-off required | N16: Macro modules | O16: ThisWorkbook; Sheet modules; General; Budget; Sensitivity; Returns; Operating; PermDebt.
F17: Tax, GST and depreciation assumptions require specialist advice | G17: Tax and GST assumptions require specialist advice | N17: Open commercial items | O17: OWNER DECISIONS: executed lender terms; written Australian tax/GST advice; independent property valuation; approved OpCo margin and multiple; final QS cost plan; executed shareholder and waterfall terms.
F18: Returns remain sensitive to cost, timing, stabilisation and exit-yield assumptions | G18: Exit yield remains a material sensitivity | N18: Governance record | O18: 30 Jul 2026: FAST/SAVi/project-finance best practice and official Australian benchmark/regulatory research applied through source records, detailed evidence checklists and fail-safe release gates. Public research has not been treated as executed project evidence.
A19: 0 | B19: KEY ASSUMPTIONS & RETURN METRICS | Q19: TENANT ANALYSIS REPORT: | R19: Hide | S19: Show
B20: Growth Rates - Income / Expense | G20: =TEXT(Underwriting!G105,"0.00%")&" / "&TEXT(Underwriting!F138,"0.00%") -> 3.50% / 0.00% | H20: PRO FORMA | L20: =+Underwriting!H165 -> STABILIZED (UNTRENDED) | M20: =+Underwriting!I165 -> SALE | N20: PARTNERSHIP RETURNS | Q20: ROI | R20: EMx | S20: IRR
B21: ="Effective Rent / "&Unit_Type -> Effective Rent / M2 | G21: =Underwriting!H105 -> 194.72316 | H21: Effective Gross Revenue | L21: =+Underwriting!H171 -> 48830200 | M21: =+Underwriting!I171 -> 52215580 | N21: Limited Partners | Q21: =Underwriting!G223 -> 1.3761098 | R21: =Underwriting!H223 -> 3.6516198 | S21: =Underwriting!I223 -> 4.7683716e-09
B22: General Vacancy & Credit Loss | G22: =Underwriting!G129 -> 0 | H22: - Operating Expenses | L22: =+Underwriting!H177 -> 3288278.6 | M22: =+Underwriting!I177 -> 3454747.7 | N22: General Partner / Sponsor | Q22: =Underwriting!G224 -> NA | R22: =Underwriting!H224 -> NA | S22: =Underwriting!I224 -> NA
B23: Expense Recovery Ratio | G23: =IF(Underwriting!$I$138=0,"",Underwriting!$I$120/Underwriting!$I$138) -> 1 | H23: Net Operating Income | L23: =L21-L22 -> 45541922 | M23: =M21-M22 -> 48760833 | N23: =Underwriting!B225 | Q23: =Underwriting!G225 | R23: =Underwriting!H225 | S23: =Underwriting!I225
B24: CapEx Reserve % of NOI | G24: =IF(Underwriting!$I$140=0,"",OpEx_7/Underwriting!$I$140) -> 0 | H24: - Capital Expenditures | L24: =+Underwriting!H183 -> 0 | M24: =+Underwriting!I183 -> 0 | N24: PROPERTY RETURNS | Q24: ROI | R24: EMx | S24: IRR
B25: ="Leasing Cost Reserve / "&Unit_Type&" / Yr" -> Leasing Cost Reserve / M2 / Yr | G25: =+Underwriting!H151 -> 0 | H25: Cash Flow from Operations | L25: =L23-L24 -> 45541922 | M25: =M23-M24 -> 48760833 | N25: Unlevered | Q25: =IFERROR(IF(Underwriting!$I$49=0,"",Underwriting!$I$211/Underwriting!$I$49),"") -> 1.0011752 | R25: =Underwriting!G211 -> 2.3177032 | S25: =Underwriting!H211 -> 0.26738072
H26: Cap Rate | L26: =Underwriting!H189 -> 0.067008197 | M26: =Underwriting!I189 -> 0.0675 | N26: Levered | Q26: =IFERROR(IF(Equity_Total=0,"",Underwriting!$I$212/Equity_Total),"") -> 1.7496555 | R26: =Underwriting!G212 -> 3.6516198 | S26: =Underwriting!H212 -> 2.9802322e-09
B27: Reversion Net Proceeds (After Selling Costs) | G27: =Underwriting!E190 -> 7.0793505e+08 | H27: Valuation | L27: =Underwriting!H191 -> 6.7964703e+08 | M27: =Underwriting!I191 -> 7.2238271e+08 | N27: DEVELOPMENT RETURNS | R27: =PROPER(Underwriting!H214) -> Stabilized (Untrended) | S27: =PROPER(Underwriting!I214) -> Sale
B28: =IF(Perm_Debt?,"Permanent Loan Payoff","Construction Loan Payoff") -> Construction Loan Payoff | G28: =IFERROR(IF(Perm_Debt?,Underwriting!$I$83,-Underwriting!$I$75),"") -> -2.3520265e+08 | H28: % of Total Project Cost | L28: =L27/$M$36 -> 1.514174 | M28: =M27/$M$36 -> 1.609384 | N28: =Underwriting!B215 -> Yield-on-Cost | R28: =Underwriting!H215 -> 0.10146207 | S28: =Underwriting!I215 -> 0.10863342
B29: Equity Proceeds from Sale | G29: =IFERROR(Underwriting!$E$192,"") -> 4.727324e+08 | H29: ="Valuation/"&Unit_Type -> Valuation/M2 | L29: =L27/Units -> 8661.192 | M29: =M27/Units -> 9205.801 | N29: =Underwriting!B216 -> Market Cap Rate | R29: =Underwriting!H216 -> 0.067008197 | S29: =Underwriting!I216 -> 0.0675
N30: =Underwriting!B217 -> Development Spread | R30: =Underwriting!H217 -> 344.5387 | S30: =Underwriting!I217 -> 411.33423
B31: SOURCES | E31: % | F31: /Unit | G31: Amount | H31: USES | K31: % | L31: ="/Buildable "&Unit_Type -> /Buildable M2 | M31: Amount | N31: =Underwriting!$C$271 -> Vacancy
B32: =Underwriting!B61 -> Construction Debt | E32: =IF(IF(Dbl_Promote?=1,$G$36,$G$35)=0,"",G32/IF(Dbl_Promote?=1,$G$36,$G$35)) -> 0.51818608 | F32: =IFERROR(G32/Units,"") -> 2997.3431 | G32: =IFERROR(Debt_Total,0) -> 2.3520265e+08 | H32: =Underwriting!B26 -> Land Costs | K32: =M32/$M$36 -> 0.20567814 | L32: =M32/Units -> 1176.4949 | M32: =Underwriting!I31 -> 92320000 | N32: SENSITIVITY | Q32: Exit Cap Rate | R32: =Underwriting!H271 -> Dev. Spread | S32: =Underwriting!I271 -> Levered EMx
B33: Limited Partners | E33: =IF(IF(Dbl_Promote?=1,$G$36,$G$35)=0,"",G33/IF(Dbl_Promote?=1,$G$36,$G$35)) -> 0.48181392 | F33: =IFERROR(G33/Units,"") -> 2786.9557 | G33: =Underwriting!D223 -> 2.1869347e+08 | H33: =Underwriting!B33 -> 0 | K33: =M33/$M$36 -> 0.79432186 | L33: =M33/Units -> 4543.5824 | M33: =Underwriting!I38 -> 3.5653664e+08 | N33: =Underwriting!B272 -> Base Case | Q33: =Underwriting!G272 -> 0.0675 | R33: =Underwriting!H272 -> 411.33423 | S33: =Underwriting!I272 -> 3.6516198
B34: General Partner / Sponsor | E34: =IF(IF(Dbl_Promote?=1,$G$36,$G$35)=0,"",G34/IF(Dbl_Promote?=1,$G$36,$G$35)) -> 0 | F34: =IFERROR(G34/Units,"") -> 0 | G34: =Underwriting!D224 -> 0 | H34: =Underwriting!B40 -> 0 | K34: =M34/$M$36 -> 0 | L34: =M34/Units -> 0 | M34: =Underwriting!I47 -> 0 | N34: =Underwriting!B273 -> Downside #1 | Q34: =Underwriting!G273 -> 0.06 | R34: =Underwriting!H273 -> 486.33423 | S34: =Underwriting!I273 -> 4.2734712
B35: =IF(Dbl_Promote?=1,Underwriting!B225,"Total Sources") -> Total Sources | E35: =IF(IF(Dbl_Promote?=1,$G$36,$G$35)=0,"",G35/IF(Dbl_Promote?=1,$G$36,$G$35)) -> 1 | F35: =IFERROR(G35/Units,"") -> 5784.2988 | G35: =IFERROR(IF(B36="",SUM(G32:G34),Underwriting!$D$225),SUM(G32:G34)) -> 4.5389613e+08 | H35: =Underwriting!B51 -> 0 | K35: =M35/$M$36 -> 0 | L35: =M35/Units -> 0 | M35: =Underwriting!I55 -> 0 | N35: =Underwriting!B274 -> Downside #2 | Q35: =Underwriting!G274 -> 0.0625 | R35: =Underwriting!H274 -> 461.33423 | S35: =Underwriting!I274 -> 4.0496047
B36: =IF(Dbl_Promote?=1,"Total Sources","") | E36: =IF(Dbl_Promote?=1,G36/$G$36,"") | F36: =IFERROR(G36/Units,"") | G36: =IF(B36="","",SUM(G32:G35)) | H36: Total Uses | K36: =M36/$M$36 -> 1 | L36: =SUM(L32:L35) -> 5720.0772 | M36: =SUM(M32:M35) -> 4.4885664e+08 | N36: =Underwriting!B275 -> Downside #3 | Q36: =Underwriting!G275 -> 0.065 | R36: =Underwriting!H275 -> 436.33423 | S36: =Underwriting!I275 -> 3.8429587
A37: 0 | B37: PROPERTY-LEVEL CASH FLOW | Q37: ANNUAL CASH FLOW REPORT: | R37: Hide | S37: Show
S86: 0.33

Sheet Underwriting
B2: =UPPER(Investment_Name) -> THE BEND ENTERTAINMENT PRECINCT | D2: =IFERROR(IF(Recalc?,"","CLICK TO RECALCULATE"),"CLICK TO RECALCULATE") -> CLICK TO RECALCULATE | I2: Mayabay Active (Melbourne) Pty Ltd | K2: Analysis Year | L2: =ROUNDUP(L3/12,0) -> 0 | M2: =ROUNDUP(M3/12,0) -> 1 | N2: =ROUNDUP(N3/12,0) -> 1 | O2: =ROUNDUP(O3/12,0) -> 1 | P2: =ROUNDUP(P3/12,0) -> 1 | Q2: =ROUNDUP(Q3/12,0) -> 1 | R2: =ROUNDUP(R3/12,0) -> 1 | S2: =ROUNDUP(S3/12,0) -> 1 | ... EN2: =ROUNDUP(EN3/12,0) -> 11 | EV2: =L2 -> 0 | EW2: =M2 -> 1 | EX2: =N2 -> 1 | EY2: =O2 -> 1 | EZ2: =P2 -> 1 | FA2: =Q2 -> 1 | FB2: =R2 -> 1 | FC2: =S2 -> 1 | ... JX2: =EN2 -> 11 | KF2: =EV2 -> 0 | KG2: =EW2 -> 1 | KH2: =EX2 -> 1 | KI2: =EY2 -> 1 | KJ2: =EZ2 -> 1 | KK2: =FA2 -> 1 | KL2: =FB2 -> 1 | KM2: =FC2 -> 1 | ... PH2: =JX2 -> 11
K3: Analysis Month | L3: =COLUMN()-COLUMN($L$3) -> 0 | M3: =COLUMN()-COLUMN($L$3) -> 1 | N3: =COLUMN()-COLUMN($L$3) -> 2 | O3: =COLUMN()-COLUMN($L$3) -> 3 | P3: =COLUMN()-COLUMN($L$3) -> 4 | Q3: =COLUMN()-COLUMN($L$3) -> 5 | R3: =COLUMN()-COLUMN($L$3) -> 6 | S3: =COLUMN()-COLUMN($L$3) -> 7 | ... EN3: =COLUMN()-COLUMN($L$3) -> 132 | EV3: =L3 -> 0 | EW3: =M3 -> 1 | EX3: =N3 -> 2 | EY3: =O3 -> 3 | EZ3: =P3 -> 4 | FA3: =Q3 -> 5 | FB3: =R3 -> 6 | FC3: =S3 -> 7 | ... JX3: =EN3 -> 132 | KF3: =EV3 -> 0 | KG3: =EW3 -> 1 | KH3: =EX3 -> 2 | KI3: =EY3 -> 3 | KJ3: =EZ3 -> 4 | KK3: =FA3 -> 5 | KL3: =FB3 -> 6 | KM3: =FC3 -> 7 | ... PH3: =JX3 -> 132
K4: Actual / Forecast Status | L4: =IF(L$24="","",IF(L$24<=$E$13,"Actual","Forecast")) -> Actual | M4: =IF(M$24="","",IF(M$24<=$E$13,"Actual","Forecast")) -> Forecast | N4: =IF(N$24="","",IF(N$24<=$E$13,"Actual","Forecast")) -> Forecast | O4: =IF(O$24="","",IF(O$24<=$E$13,"Actual","Forecast")) -> Forecast | P4: =IF(P$24="","",IF(P$24<=$E$13,"Actual","Forecast")) -> Forecast | Q4: =IF(Q$24="","",IF(Q$24<=$E$13,"Actual","Forecast")) -> Forecast | R4: =IF(R$24="","",IF(R$24<=$E$13,"Actual","Forecast")) -> Forecast | S4: =IF(S$24="","",IF(S$24<=$E$13,"Actual","Forecast")) -> Forecast | ... EN4: =IF(EN$24="","",IF(EN$24<=$E$13,"Actual","Forecast")) -> Forecast
B5: Levered IRR | C5: =H212 -> 2.9802322e-09 | D5: Levered EMx: | E5: =G212 -> 3.6516198 | F5: =Timing_Reversion_Month -> 61 | H5: Development Spread (Untrended) | I5: =H217 -> 344.5387 | EM5: Hide Calc | EN5: Show Calc | EO5: 1
B8: INVESTMENT DESCRIPTION | I8: M2
B9: Name | E9: ='URWLD COMPANY INPUTS'!$F$37 -> THE BEND Entertainment Precinct | F9: County | I9: [County]
B10: Address | E10: ='URWLD COMPANY INPUTS'!$F$38 -> Port Melbourne | F10: State | I10: =IF($E$10="Port Melbourne","VIC","") -> VIC
B11: City | E11: ='URWLD COMPANY INPUTS'!$F$38 -> Port Melbourne | F11: Zip Code | I11: [Zip Code]
B13: Analysis Begin Date | E13: =DATE(VALUE(RIGHT('URWLD COMPANY INPUTS'!$F$45,4)),VALUE(MID('URWLD COMPANY INPUTS'!$F$45,2,1))*3-2,1) -> 46204 | F13: Country | I13: =IF($E$10<>"","Australia","") -> Australia
B15: Retail Building Type | D15: Neighborhood Center | F15: Sale Date | I15: =EDATE(E13,I16-1) -> 48030
B16: Leasing Strategy | E16: Speculative | F16: Analysis Period | I16: =Timing_Reversion_Month -> 61
B17: Land Area | C17: =IF(Unit_Type="SF",E17*43560,E17*4046.86) -> 34400.03 | D17: =Unit_Type -> M2 | E17: ='URWLD COMPANY INPUTS'!$F$43/4046.8564224 -> 8.5004251 | F17: Suites/Tenants | I17: =COUNTA($B$93:$B$105)-1 -> 12
B18: ="Gross Buildable (NRA - "&Unit_Type&")" -> Gross Buildable (NRA - M2) | E18: =I18 -> 78470.38 | F18: ="Net Rentable (NRA - "&Unit_Type&")" -> Net Rentable (NRA - M2) | I18: =SUM(E93:E104) -> 78470.38
B19: # of Buildings | E19: 4 | F19: Building Coverage (Assumes one-story bldgs) | I19: =Units_SF_M2/C17 -> 2.2811137
B20: Surface Parking Spaces | E20: =Units_SF_M2/1000*0.5 -> 39.23519 | F20: Efficiency Ratio | I20: =Units_SF_M2/E18 -> 1
B21: Structured Parking Spaces | E21: =Units_SF_M2/1000*4 -> 313.88152 | F21: ="Parking Ratio (Per "&Unit_Type&")" -> Parking Ratio (Per M2) | I21: =(E21+E20)/(Units_SF_M2/1000) -> 4.5
B23: INVESTMENT PERIOD CASH FLOWS | K23: Analysis Month | L23: =COLUMN()-COLUMN($L$23) -> 0 | M23: =COLUMN()-COLUMN($L$23) -> 1 | N23: =COLUMN()-COLUMN($L$23) -> 2 | O23: =COLUMN()-COLUMN($L$23) -> 3 | P23: =COLUMN()-COLUMN($L$23) -> 4 | Q23: =COLUMN()-COLUMN($L$23) -> 5 | R23: =COLUMN()-COLUMN($L$23) -> 6 | S23: =COLUMN()-COLUMN($L$23) -> 7 | ... EN23: =COLUMN()-COLUMN($L$23) -> 132 | EP23: S-CURVE CALCULATION | EV23: =L23 -> 0 | EW23: =M23 -> 1 | EX23: =N23 -> 2 | EY23: =O23 -> 3 | EZ23: =P23 -> 4 | FA23: =Q23 -> 5 | FB23: =R23 -> 6 | FC23: =S23 -> 7 | ... JX23: =EN23 -> 132 | JZ23: GROWTH/DECLINE CALCULATION | KF23: =EV23 -> 0 | KG23: =EW23 -> 1 | KH23: =EX23 -> 2 | KI23: =EY23 -> 3 | KJ23: =EZ23 -> 4 | KK23: =FA23 -> 5 | KL23: =FB23 -> 6 | KM23: =FC23 -> 7 | ... PH23: =JX23 -> 132
B24: SOURCES AND USES | K24: Analysis Date | L24: =EOMONTH($E$13,COLUMN()-COLUMN($L$24)-1) -> 46203 | M24: =EOMONTH($E$13,COLUMN()-COLUMN($L$24)-1) -> 46234 | N24: =EOMONTH($E$13,COLUMN()-COLUMN($L$24)-1) -> 46265 | O24: =EOMONTH($E$13,COLUMN()-COLUMN($L$24)-1) -> 46295 | P24: =EOMONTH($E$13,COLUMN()-COLUMN($L$24)-1) -> 46326 | Q24: =EOMONTH($E$13,COLUMN()-COLUMN($L$24)-1) -> 46356 | R24: =EOMONTH($E$13,COLUMN()-COLUMN($L$24)-1) -> 46387 | S24: =EOMONTH($E$13,COLUMN()-COLUMN($L$24)-1) -> 46418 | ... EN24: =EOMONTH($E$13,COLUMN()-COLUMN($L$24)-1) -> 50221 | EP24: Amount | EQ24: Start Period | ER24: End Period | ES24: Months | ET24: Timing | EU24: StDev | EV24: =L24 -> 46203 | EW24: =M24 -> 46234 | EX24: =N24 -> 46265 | EY24: =O24 -> 46295 | EZ24: =P24 -> 46326 | FA24: =Q24 -> 46356 | FB24: =R24 -> 46387 | FC24: =S24 -> 46418 | ... JX24: =EN24 -> 50221 | KF24: =EV24 -> 46203 | KG24: =EW24 -> 46234 | KH24: =EX24 -> 46265 | KI24: =EY24 -> 46295 | KJ24: =EZ24 -> 46326 | KK24: =FA24 -> 46356 | KL24: =FB24 -> 46387 | KM24: =FC24 -> 46418 | ... PH24: =JX24 -> 50221
B25: USES | D25: START | E25: END | F25: METHOD | H25: ="/RENTABLE "&Unit_Type -> /RENTABLE M2 | I25: AMOUNT | K25: Cum. Spent % | L25: =SUM($L$57:L57)/Project_Cost_Total -> 0.20723257 | M25: =SUM($L$57:M57)/Project_Cost_Total -> 0.20919763 | N25: =SUM($L$57:N57)/Project_Cost_Total -> 0.21176691 | O25: =SUM($L$57:O57)/Project_Cost_Total -> 0.21519912 | P25: =SUM($L$57:P57)/Project_Cost_Total -> 0.2198269 | Q25: =SUM($L$57:Q57)/Project_Cost_Total -> 0.22606061 | R25: =SUM($L$57:R57)/Project_Cost_Total -> 0.2343842 | S25: =SUM($L$57:S57)/Project_Cost_Total -> 0.24534022 | ... EN25: =SUM($L$57:EN57)/Project_Cost_Total -> 1 | JZ25: =B25 -> USES | KB25: Start | KC25: End | KD25: Length | KE25: Amount
B26: Land Costs | K26: Spent % | L26: =L25 -> 0.20723257 | M26: =M25-L25 -> 0.0019650559 | N26: =N25-M25 -> 0.0025692809 | O26: =O25-N25 -> 0.0034322136 | P26: =P25-O25 -> 0.0046277776 | Q26: =Q25-P25 -> 0.0062337101 | R26: =R25-Q25 -> 0.0083235906 | S26: =S25-R25 -> 0.010956018 | T26: =T25-S25 -> 0.014161728 | ... EN26: =EN25-EM25 -> 0 | JZ26: =B26 -> Land Costs
C27: 0 | E27: =D27 -> 0 | F27: Straight-Line | G27: =I27/Units_SF_M2 -> 1166.9371 | I27: ='URWLD COMPANY INPUTS'!$D$122*1000000 -> 91570000 | K27: =IF(ROUND(SUM(L27:EN27),0)=ROUND(I27,0),"","Incomplete") | L27: =AND(L$23>=$D27,L$23<=$E27)*(OR($F27="Straight-Line",$F27="Detail")*($I27/$ES27)+($F27="S-Curve")*EV27+OR($F27="Steady Growth",$F27="Steady Decline")*KF27) -> 91570000 | M27: =AND(M$23>=$D27,M$23<=$E27)*(OR($F27="Straight-Line",$F27="Detail")*($I27/$ES27)+($F27="S-Curve")*EW27+OR($F27="Steady Growth",$F27="Steady Decline")*KG27) -> 0 | N27: =AND(N$23>=$D27,N$23<=$E27)*(OR($F27="Straight-Line",$F27="Detail")*($I27/$ES27)+($F27="S-Curve")*EX27+OR($F27="Steady Growth",$F27="Steady Decline")*KH27) -> 0 | O27: =AND(O$23>=$D27,O$23<=$E27)*(OR($F27="Straight-Line",$F27="Detail")*($I27/$ES27)+($F27="S-Curve")*EY27+OR($F27="Steady Growth",$F27="Steady Decline")*KI27) -> 0 | P27: =AND(P$23>=$D27,P$23<=$E27)*(OR($F27="Straight-Line",$F27="Detail")*($I27/$ES27)+($F27="S-Curve")*EZ27+OR($F27="Steady Growth",$F27="Steady Decline")*KJ27) -> 0 | Q27: =AND(Q$23>=$D27,Q$23<=$E27)*(OR($F27="Straight-Line",$F27="Detail")*($I27/$ES27)+($F27="S-Curve")*FA27+OR($F27="Steady Growth",$F27="Steady Decline")*KK27) -> 0 | R27: =AND(R$23>=$D27,R$23<=$E27)*(OR($F27="Straight-Line",$F27="Detail")*($I27/$ES27)+($F27="S-Curve")*FB27+OR($F27="Steady Growth",$F27="Steady Decline")*KL27) -> 0 | S27: =AND(S$23>=$D27,S$23<=$E27)*(OR($F27="Straight-Line",$F27="Detail")*($I27/$ES27)+($F27="S-Curve")*FC27+OR($F27="Steady Growth",$F27="Steady Decline")*KM27) -> 0 | ... EN27: =AND(EN$23>=$D27,EN$23<=$E27)*(OR($F27="Straight-Line",$F27="Detail")*($I27/$ES27)+($F27="S-Curve")*JX27+OR($F27="Steady Growth",$F27="Steady Decline")*PH27) -> 0 | EP27: =I27 -> 91570000 | EQ27: =INDEX($L$24:$EN$24,1,$D27+1) -> 46203 | ER27: =INDEX($L$24:$EN$24,1,$E27+1) -> 46203 | ES27: =+E27-D27+1 -> 1 | ET27: =F27 -> Straight-Line | EU27: =ES27/Scurve_Dist -> 0.16666667 | EV27: =AND($ET27="S-Curve",EV$24>=$EQ27,EV$24<=$ER27)*(NORMDIST((YEAR(EV$24)-YEAR($EQ27))*12+MONTH(EV$24)-MONTH($EQ27)+1,$ES27/2,$EU27,TRUE)-NORMDIST((YEAR(EV$24)-YEAR($EQ27))*12+MONTH(EV$24)-MONTH($EQ27),$ES27/2,$EU27,TRUE))/(1-2*NORMDIST(0,$ES27/2,$EU27,TRUE))*$EP27 -> 0 | EW27: =AND($ET27="S-Curve",EW$24>=$EQ27,EW$24<=$ER27)*(NORMDIST((YEAR(EW$24)-YEAR($EQ27))*12+MONTH(EW$24)-MONTH($EQ27)+1,$ES27/2,$EU27,TRUE)-NORMDIST((YEAR(EW$24)-YEAR($EQ27))*12+MONTH(EW$24)-MONTH($EQ27),$ES27/2,$EU27,TRUE))/(1-2*NORMDIST(0,$ES27/2,$EU27,TRUE))*$EP27 -> 0 | EX27: =AND($ET27="S-Curve",EX$24>=$EQ27,EX$24<=$ER27)*(NORMDIST((YEAR(EX$24)-YEAR($EQ27))*12+MONTH(EX$24)-MONTH($EQ27)+1,$ES27/2,$EU27,TRUE)-NORMDIST((YEAR(EX$24)-YEAR($EQ27))*12+MONTH(EX$24)-MONTH($EQ27),$ES27/2,$EU27,TRUE))/(1-2*NORMDIST(0,$ES27/2,$EU27,TRUE))*$EP27 -> 0 | EY27: =AND($ET27="S-Curve",EY$24>=$EQ27,EY$24<=$ER27)*(NORMDIST((YEAR(EY$24)-YEAR($EQ27))*12+MONTH(EY$24)-MONTH($EQ27)+1,$ES27/2,$EU27,TRUE)-NORMDIST((YEAR(EY$24)-YEAR($EQ27))*12+MONTH(EY$24)-MONTH($EQ27),$ES27/2,$EU27,TRUE))/(1-2*NORMDIST(0,$ES27/2,$EU27,TRUE))*$EP27 -> 0 | EZ27: =AND($ET27="S-Curve",EZ$24>=$EQ27,EZ$24<=$ER27)*(NORMDIST((YEAR(EZ$24)-YEAR($EQ27))*12+MONTH(EZ$24)-MONTH($EQ27)+1,$ES27/2,$EU27,TRUE)-NORMDIST((YEAR(EZ$24)-YEAR($EQ27))*12+MONTH(EZ$24)-MONTH($EQ27),$ES27/2,$EU27,TRUE))/(1-2*NORMDIST(0,$ES27/2,$EU27,TRUE))*$EP27 -> 0 | FA27: =AND($ET27="S-Curve",FA$24>=$EQ27,FA$24<=$ER27)*(NORMDIST((YEAR(FA$24)-YEAR($EQ27))*12+MONTH(FA$24)-MONTH($EQ27)+1,$ES27/2,$EU27,TRUE)-NORMDIST((YEAR(FA$24)-YEAR($EQ27))*12+MONTH(FA$24)-MONTH($EQ27),$ES27/2,$EU27,TRUE))/(1-2*NORMDIST(0,$ES27/2,$EU27,TRUE))*$EP27 -> 0 | FB27: =AND($ET27="S-Curve",FB$24>=$EQ27,FB$24<=$ER27)*(NORMDIST((YEAR(FB$24)-YEAR($EQ27))*12+MONTH(FB$24)-MONTH($EQ27)+1,$ES27/2,$EU27,TRUE)-NORMDIST((YEAR(FB$24)-YEAR($EQ27))*12+MONTH(FB$24)-MONTH($EQ27),$ES27/2,$EU27,TRUE))/(1-2*NORMDIST(0,$ES27/2,$EU27,TRUE))*$EP27 -> 0 | FC27: =AND($ET27="S-Curve",FC$24>=$EQ27,FC$24<=$ER27)*(NORMDIST((YEAR(FC$24)-YEAR($EQ27))*12+MONTH(FC$24)-MONTH($EQ27)+1,$ES27/2,$EU27,TRUE)-NORMDIST((YEAR(FC$24)-YEAR($EQ27))*12+MONTH(FC$24)-MONTH($EQ27),$ES27/2,$EU27,TRUE))/(1-2*NORMDIST(0,$ES27/2,$EU27,TRUE))*$EP27 -> 0 | ... JX27: =AND($ET27="S-Curve",JX$24>=$EQ27,JX$24<=$ER27)*(NORMDIST((YEAR(JX$24)-YEAR($EQ27))*12+MONTH(JX$24)-MONTH($EQ27)+1,$ES27/2,$EU27,TRUE)-NORMDIST((YEAR(JX$24)-YEAR($EQ27))*12+MONTH(JX$24)-MONTH($EQ27),$ES27/2,$EU27,TRUE))/(1-2*NORMDIST(0,$ES27/2,$EU27,TRUE))*$EP27 -> 0 | JZ27: =B27 -> 0 | KB27: =D27 -> 0 | KC27: =E27 -> 0 | KD27: =KC27-KB27+1 -> 1 | KE27: =I27 -> 91570000 | KF27: =AND(KF$23>=$KB27,KF$23<=$KC27)*(IF($F27="Steady Growth",KF$23-$KB27,$KC27-KF$23)+1)/($KD27*($KD27+1)/2)*$KE27 -> 91570000 | KG27: =AND(KG$23>=$KB27,KG$23<=$KC27)*(IF($F27="Steady Growth",KG$23-$KB27,$KC27-KG$23)+1)/($KD27*($KD27+1)/2)*$KE27 -> 0 | KH27: =AND(KH$23>=$KB27,KH$23<=$KC27)*(IF($F27="Steady Growth",KH$23-$KB27,$KC27-KH$23)+1)/($KD27*($KD27+1)/2)*$KE27 -> 0 | KI27: =AND(KI$23>=$KB27,KI$23<=$KC27)*(IF($F27="Steady Growth",KI$23-$KB27,$KC27-KI$23)+1)/($KD27*($KD27+1)/2)*$KE27 -> 0 | KJ27: =AND(KJ$23>=$KB27,KJ$23<=$KC27)*(IF($F27="Steady Growth",KJ$23-$KB27,$KC27-KJ$23)+1)/($KD27*($KD27+1)/2)*$KE27 -> 0 | KK27: =AND(KK$23>=$KB27,KK$23<=$KC27)*(IF($F27="Steady Growth",KK$23-$KB27,$KC27-KK$23)+1)/($KD27*($KD27+1)/2)*$KE27 -> 0 | KL27: =AND(KL$23>=$KB27,KL$23<=$KC27)*(IF($F27="Steady Growth",KL$23-$KB27,$KC27-KL$23)+1)/($KD27*($KD27+1)/2)*$KE27 -> 0 | KM27: =AND(KM$23>=$KB27,KM$23<=$KC27)*(IF($F27="Steady Growth",KM$23-$KB27,$KC27-KM$23)+1)/($KD27*($KD27+1)/2)*$KE27 -> 0 | ... PH27: =AND(PH$23>=$KB27,PH$23<=$KC27)*(IF($F27="Steady Growth",PH$23-$KB27,$KC27-PH$23)+1)/($KD27*($KD27+1)/2)*$KE27 -> 0
B28: Interim site acquisition lease deposit | C28: 0 | E28: 0 | F28: Straight-Line | G28: =I28/Units_SF_M2 -> 9.5577465 | I28: ='URWLD COMPANY INPUTS'!$D$89*1000000 -> 750000 | K28: =IF(ROUND(SUM(L28:EN28),0)=ROUND(I28,0),"","Incomplete") | L28: =AND(L$23>=$D28,L$23<=$E28)*(OR($F28="Straight-Line",$F28="Detail")*($I28/$ES28)+($F28="S-Curve")*EV28+OR($F28="Steady Growth",$F28="Steady Decline")*KF28) -> 750000 | M28: =AND(M$23>=$D28,M$23<=$E28)*(OR($F28="Straight-Line",$F28="Detail")*($I28/$ES28)+($F28="S-Curve")*EW28+OR($F28="Steady Growth",$F28="Steady Decline")*KG28) -> 0 | N28: =AND(N$23>=$D28,N$23<=$E28)*(OR($F28="Straight-Line",$F28="Detail")*($I28/$ES28)+($F28="S-Curve")*EX28+OR($F28="Steady Growth",$F28="Steady Decline")*KH28) -> 0 | O28: =AND(O$23>=$D28,O$23<=$E28)*(OR($F28="Straight-Line",$F28="Detail")*($I28/$ES28)+($F28="S-Curve")*EY28+OR($F28="Steady Growth",$F28="Steady Decline")*KI28) -> 0 | P28: =AND(P$23>=$D28,P$23<=$E28)*(OR($F28="Straight-Line",$F28="Detail")*($I28/$ES28)+($F28="S-Curve")*EZ28+OR($F28="Steady Growth",$F28="Steady Decline")*KJ28) -> 0 | Q28: =AND(Q$23>=$D28,Q$23<=$E28)*(OR($F28="Straight-Line",$F28="Detail")*($I28/$ES28)+($F28="S-Curve")*FA28+OR($F28="Steady Growth",$F28="Steady Decline")*KK28) -> 0 | R28: =AND(R$23>=$D28,R$23<=$E28)*(OR($F28="Straight-Line",$F28="Detail")*($I28/$ES28)+($F28="S-Curve")*FB28+OR($F28="Steady Growth",$F28="Steady Decline")*KL28) -> 0 | S28: =AND(S$23>=$D28,S$23<=$E28)*(OR($F28="Straight-Line",$F28="Detail")*($I28/$ES28)+($F28="S-Curve")*FC28+OR($F28="Steady Growth",$F28="Steady Decline")*KM28) -> 0 | ... EN28: =AND(EN$23>=$D28,EN$23<=$E28)*(OR($F28="Straight-Line",$F28="Detail")*($I28/$ES28)+($F28="S-Curve")*JX28+OR($F28="Steady Growth",$F28="Steady Decline")*PH28) -> 0 | EP28: =I28 -> 750000 | EQ28: =INDEX($L$24:$EN$24,1,$D28+1) -> 46203 | ER28: =INDEX($L$24:$EN$24,1,$E28+1) -> 46203 | ES28: =+E28-D28+1 -> 1 | ET28: =F28 -> Straight-Line | EU28: =ES28/Scurve_Dist -> 0.16666667 | EV28: =AND($ET28="S-Curve",EV$24>=$EQ28,EV$24<=$ER28)*(NORMDIST((YEAR(EV$24)-YEAR($EQ28))*12+MONTH(EV$24)-MONTH($EQ28)+1,$ES28/2,$EU28,TRUE)-NORMDIST((YEAR(EV$24)-YEAR($EQ28))*12+MONTH(EV$24)-MONTH($EQ28),$ES28/2,$EU28,TRUE))/(1-2*NORMDIST(0,$ES28/2,$EU28,TRUE))*$EP28 -> 0 | EW28: =AND($ET28="S-Curve",EW$24>=$EQ28,EW$24<=$ER28)*(NORMDIST((YEAR(EW$24)-YEAR($EQ28))*12+MONTH(EW$24)-MONTH($EQ28)+1,$ES28/2,$EU28,TRUE)-NORMDIST((YEAR(EW$24)-YEAR($EQ28))*12+MONTH(EW$24)-MONTH($EQ28),$ES28/2,$EU28,TRUE))/(1-2*NORMDIST(0,$ES28/2,$EU28,TRUE))*$EP28 -> 0 | EX28: =AND($ET28="S-Curve",EX$24>=$EQ28,EX$24<=$ER28)*(NORMDIST((YEAR(EX$24)-YEAR($EQ28))*12+MONTH(EX$24)-MONTH($EQ28)+1,$ES28/2,$EU28,TRUE)-NORMDIST((YEAR(EX$24)-YEAR($EQ28))*12+MONTH(EX$24)-MONTH($EQ28),$ES28/2,$EU28,TRUE))/(1-2*NORMDIST(0,$ES28/2,$EU28,TRUE))*$EP28 -> 0 | EY28: =AND($ET28="S-Curve",EY$24>=$EQ28,EY$24<=$ER28)*(NORMDIST((YEAR(EY$24)-YEAR($EQ28))*12+MONTH(EY$24)-MONTH($EQ28)+1,$ES28/2,$EU28,TRUE)-NORMDIST((YEAR(EY$24)-YEAR($EQ28))*12+MONTH(EY$24)-MONTH($EQ28),$ES28/2,$EU28,TRUE))/(1-2*NORMDIST(0,$ES28/2,$EU28,TRUE))*$EP28 -> 0 | EZ28: =AND($ET28="S-Curve",EZ$24>=$EQ28,EZ$24<=$ER28)*(NORMDIST((YEAR(EZ$24)-YEAR($EQ28))*12+MONTH(EZ$24)-MONTH($EQ28)+1,$ES28/2,$EU28,TRUE)-NORMDIST((YEAR(EZ$24)-YEAR($EQ28))*12+MONTH(EZ$24)-MONTH($EQ28),$ES28/2,$EU28,TRUE))/(1-2*NORMDIST(0,$ES28/2,$EU28,TRUE))*$EP28 -> 0 | FA28: =AND($ET28="S-Curve",FA$24>=$EQ28,FA$24<=$ER28)*(NORMDIST((YEAR(FA$24)-YEAR($EQ28))*12+MONTH(FA$24)-MONTH($EQ28)+1,$ES28/2,$EU28,TRUE)-NORMDIST((YEAR(FA$24)-YEAR($EQ28))*12+MONTH(FA$24)-MONTH($EQ28),$ES28/2,$EU28,TRUE))/(1-2*NORMDIST(0,$ES28/2,$EU28,TRUE))*$EP28 -> 0 | FB28: =AND($ET28="S-Curve",FB$24>=$EQ28,FB$24<=$ER28)*(NORMDIST((YEAR(FB$24)-YEAR($EQ28))*12+MONTH(FB$24)-MONTH($EQ28)+1,$ES28/2,$EU28,TRUE)-NORMDIST((YEAR(FB$24)-YEAR($EQ28))*12+MONTH(FB$24)-MONTH($EQ28),$ES28/2,$EU28,TRUE))/(1-2*NORMDIST(0,$ES28/2,$EU28,TRUE))*$EP28 -> 0 | FC28: =AND($ET28="S-Curve",FC$24>=$EQ28,FC$24<=$ER28)*(NORMDIST((YEAR(FC$24)-YEAR($EQ28))*12+MONTH(FC$24)-MONTH($EQ28)+1,$ES28/2,$EU28,TRUE)-NORMDIST((YEAR(FC$24)-YEAR($EQ28))*12+MONTH(FC$24)-MONTH($EQ28),$ES28/2,$EU28,TRUE))/(1-2*NORMDIST(0,$ES28/2,$EU28,TRUE))*$EP28 -> 0 | ... JX28: =AND($ET28="S-Curve",JX$24>=$EQ28,JX$24<=$ER28)*(NORMDIST((YEAR(JX$24)-YEAR($EQ28))*12+MONTH(JX$24)-MONTH($EQ28)+1,$ES28/2,$EU28,TRUE)-NORMDIST((YEAR(JX$24)-YEAR($EQ28))*12+MONTH(JX$24)-MONTH($EQ28),$ES28/2,$EU28,TRUE))/(1-2*NORMDIST(0,$ES28/2,$EU28,TRUE))*$EP28 -> 0 | JZ28: =B28 -> Interim site acquisition lease deposit | KB28: =D28 -> 0 | KC28: =E28 -> 0 | KD28: =KC28-KB28+1 -> 1 | KE28: =I28 -> 750000 | KF28: =AND(KF$23>=$KB28,KF$23<=$KC28)*(IF($F28="Steady Growth",KF$23-$KB28,$KC28-KF$23)+1)/($KD28*($KD28+1)/2)*$KE28 -> 750000 | KG28: =AND(KG$23>=$KB28,KG$23<=$KC28)*(IF($F28="Steady Growth",KG$23-$KB28,$KC28-KG$23)+1)/($KD28*($KD28+1)/2)*$KE28 -> 0 | KH28: =AND(KH$23>=$KB28,KH$23<=$KC28)*(IF($F28="Steady Growth",KH$23-$KB28,$KC28-KH$23)+1)/($KD28*($KD28+1)/2)*$KE28 -> 0 | KI28: =AND(KI$23>=$KB28,KI$23<=$KC28)*(IF($F28="Steady Growth",KI$23-$KB28,$KC28-KI$23)+1)/($KD28*($KD28+1)/2)*$KE28 -> 0 | KJ28: =AND(KJ$23>=$KB28,KJ$23<=$KC28)*(IF($F28="Steady Growth",KJ$23-$KB28,$KC28-KJ$23)+1)/($KD28*($KD28+1)/2)*$KE28 -> 0 | KK28: =AND(KK$23>=$KB28,KK$23<=$KC28)*(IF($F28="Steady Growth",KK$23-$KB28,$KC28-KK$23)+1)/($KD28*($KD28+1)/2)*$KE28 -> 0 | KL28: =AND(KL$23>=$KB28,KL$23<=$KC28)*(IF($F28="Steady Growth",KL$23-$KB28,$KC28-KL$23)+1)/($KD28*($KD28+1)/2)*$KE28 -> 0 | KM28: =AND(KM$23>=$KB28,KM$23<=$KC28)*(IF($F28="Steady Growth",KM$23-$KB28,$KC28-KM$23)+1)/($KD28*($KD28+1)/2)*$KE28 -> 0 | ... PH28: =AND(PH$23>=$KB28,PH$23<=$KC28)*(IF($F28="Steady Growth",PH$23-$KB28,$KC28-PH$23)+1)/($KD28*($KD28+1)/2)*$KE28 -> 0
B29: Other acquisition costs | C29: 0 | E29: 0 | F29: Straight-Line | G29: =I29/Units_SF_M2 -> 0 | I29: 0 | K29: =IF(ROUND(SUM(L29:EN29),0)=ROUND(I29,0),"","Incomplete") | L29: =AND(L$23>=$D29,L$23<=$E29)*(OR($F29="Straight-Line",$F29="Detail")*($I29/$ES29)+($F29="S-Curve")*EV29+OR($F29="Steady Growth",$F29="Steady Decline")*KF29) -> 0 | M29: =AND(M$23>=$D29,M$23<=$E29)*(OR($F29="Straight-Line",$F29="Detail")*($I29/$ES29)+($F29="S-Curve")*EW29+OR($F29="Steady Growth",$F29="Steady Decline")*KG29) -> 0 | N29: =AND(N$23>=$D29,N$23<=$E29)*(OR($F29="Straight-Line",$F29="Detail")*($I29/$ES29)+($F29="S-Curve")*EX29+OR($F29="Steady Growth",$F29="Steady Decline")*KH29) -> 0 | O29: =AND(O$23>=$D29,O$23<=$E29)*(OR($F29="Straight-Line",$F29="Detail")*($I29/$ES29)+($F29="S-Curve")*EY29+OR($F29="Steady Growth",$F29="Steady Decline")*KI29) -> 0 | P29: =AND(P$23>=$D29,P$23<=$E29)*(OR($F29="Straight-Line",$F29="Detail")*($I29/$ES29)+($F29="S-Curve")*EZ29+OR($F29="Steady Growth",$F29="Steady Decline")*KJ29) -> 0 | Q29: =AND(Q$23>=$D29,Q$23<=$E29)*(OR($F29="Straight-Line",$F29="Detail")*($I29/$ES29)+($F29="S-Curve")*FA29+OR($F29="Steady Growth",$F29="Steady Decline")*KK29) -> 0 | R29: =AND(R$23>=$D29,R$23<=$E29)*(OR($F29="Straight-Line",$F29="Detail")*($I29/$ES29)+($F29="S-Curve")*FB29+OR($F29="Steady Growth",$F29="Steady Decline")*KL29) -> 0 | S29: =AND(S$23>=$D29,S$23<=$E29)*(OR($F29="Straight-Line",$F29="Detail")*($I29/$ES29)+($F29="S-Curve")*FC29+OR($F29="Steady Growth",$F29="Steady Decline")*KM29) -> 0 | ... EN29: =AND(EN$23>=$D29,EN$23<=$E29)*(OR($F29="Straight-Line",$F29="Detail")*($I29/$ES29)+($F29="S-Curve")*JX29+OR($F29="Steady Growth",$F29="Steady Decline")*PH29) -> 0 | EP29: =I29 -> 0 | EQ29: =INDEX($L$24:$EN$24,1,$D29+1) -> 46203 | ER29: =INDEX($L$24:$EN$24,1,$E29+1) -> 46203 | ES29: =+E29-D29+1 -> 1 | ET29: =F29 -> Straight-Line | EU29: =ES29/Scurve_Dist -> 0.16666667 | EV29: =AND($ET29="S-Curve",EV$24>=$EQ29,EV$24<=$ER29)*(NORMDIST((YEAR(EV$24)-YEAR($EQ29))*12+MONTH(EV$24)-MONTH($EQ29)+1,$ES29/2,$EU29,TRUE)-NORMDIST((YEAR(EV$24)-YEAR($EQ29))*12+MONTH(EV$24)-MONTH($EQ29),$ES29/2,$EU29,TRUE))/(1-2*NORMDIST(0,$ES29/2,$EU29,TRUE))*$EP29 -> 0 | EW29: =AND($ET29="S-Curve",EW$24>=$EQ29,EW$24<=$ER29)*(NORMDIST((YEAR(EW$24)-YEAR($EQ29))*12+MONTH(EW$24)-MONTH($EQ29)+1,$ES29/2,$EU29,TRUE)-NORMDIST((YEAR(EW$24)-YEAR($EQ29))*12+MONTH(EW$24)-MONTH($EQ29),$ES29/2,$EU29,TRUE))/(1-2*NORMDIST(0,$ES29/2,$EU29,TRUE))*$EP29 -> 0 | EX29: =AND($ET29="S-Curve",EX$24>=$EQ29,EX$24<=$ER29)*(NORMDIST((YEAR(EX$24)-YEAR($EQ29))*12+MONTH(EX$24)-MONTH($EQ29)+1,$ES29/2,$EU29,TRUE)-NORMDIST((YEAR(EX$24)-YEAR($EQ29))*12+MONTH(EX$24)-MONTH($EQ29),$ES29/2,$EU29,TRUE))/(1-2*NORMDIST(0,$ES29/2,$EU29,TRUE))*$EP29 -> 0 | EY29: =AND($ET29="S-Curve",EY$24>=$EQ29,EY$24<=$ER29)*(NORMDIST((YEAR(EY$24)-YEAR($EQ29))*12+MONTH(EY$24)-MONTH($EQ29)+1,$ES29/2,$EU29,TRUE)-NORMDIST((YEAR(EY$24)-YEAR($EQ29))*12+MONTH(EY$24)-MONTH($EQ29),$ES29/2,$EU29,TRUE))/(1-2*NORMDIST(0,$ES29/2,$EU29,TRUE))*$EP29 -> 0 | EZ29: =AND($ET29="S-Curve",EZ$24>=$EQ29,EZ$24<=$ER29)*(NORMDIST((YEAR(EZ$24)-YEAR($EQ29))*12+MONTH(EZ$24)-MONTH($EQ29)+1,$ES29/2,$EU29,TRUE)-NORMDIST((YEAR(EZ$24)-YEAR($EQ29))*12+MONTH(EZ$24)-MONTH($EQ29),$ES29/2,$EU29,TRUE))/(1-2*NORMDIST(0,$ES29/2,$EU29,TRUE))*$EP29 -> 0 | FA29: =AND($ET29="S-Curve",FA$24>=$EQ29,FA$24<=$ER29)*(NORMDIST((YEAR(FA$24)-YEAR($EQ29))*12+MONTH(FA$24)-MONTH($EQ29)+1,$ES29/2,$EU29,TRUE)-NORMDIST((YEAR(FA$24)-YEAR($EQ29))*12+MONTH(FA$24)-MONTH($EQ29),$ES29/2,$EU29,TRUE))/(1-2*NORMDIST(0,$ES29/2,$EU29,TRUE))*$EP29 -> 0 | FB29: =AND($ET29="S-Curve",FB$24>=$EQ29,FB$24<=$ER29)*(NORMDIST((YEAR(FB$24)-YEAR($EQ29))*12+MONTH(FB$24)-MONTH($EQ29)+1,$ES29/2,$EU29,TRUE)-NORMDIST((YEAR(FB$24)-YEAR($EQ29))*12+MONTH(FB$24)-MONTH($EQ29),$ES29/2,$EU29,TRUE))/(1-2*NORMDIST(0,$ES29/2,$EU29,TRUE))*$EP29 -> 0 | FC29: =AND($ET29="S-Curve",FC$24>=$EQ29,FC$24<=$ER29)*(NORMDIST((YEAR(FC$24)-YEAR($EQ29))*12+MONTH(FC$24)-MONTH($EQ29)+1,$ES29/2,$EU29,TRUE)-NORMDIST((YEAR(FC$24)-YEAR($EQ29))*12+MONTH(FC$24)-MONTH($EQ29),$ES29/2,$EU29,TRUE))/(1-2*NORMDIST(0,$ES29/2,$EU29,TRUE))*$EP29 -> 0 | ... JX29: =AND($ET29="S-Curve",JX$24>=$EQ29,JX$24<=$ER29)*(NORMDIST((YEAR(JX$24)-YEAR($EQ29))*12+MONTH(JX$24)-MONTH($EQ29)+1,$ES29/2,$EU29,TRUE)-NORMDIST((YEAR(JX$24)-YEAR($EQ29))*12+MONTH(JX$24)-MONTH($EQ29),$ES29/2,$EU29,TRUE))/(1-2*NORMDIST(0,$ES29/2,$EU29,TRUE))*$EP29 -> 0 | JZ29: =B29 -> Other acquisition costs | KB29: =D29 -> 0 | KC29: =E29 -> 0 | KD29: =KC29-KB29+1 -> 1 | KE29: =I29 -> 0 | KF29: =AND(KF$23>=$KB29,KF$23<=$KC29)*(IF($F29="Steady Growth",KF$23-$KB29,$KC29-KF$23)+1)/($KD29*($KD29+1)/2)*$KE29 -> 0 | KG29: =AND(KG$23>=$KB29,KG$23<=$KC29)*(IF($F29="Steady Growth",KG$23-$KB29,$KC29-KG$23)+1)/($KD29*($KD29+1)/2)*$KE29 -> 0 | KH29: =AND(KH$23>=$KB29,KH$23<=$KC29)*(IF($F29="Steady Growth",KH$23-$KB29,$KC29-KH$23)+1)/($KD29*($KD29+1)/2)*$KE29 -> 0 | KI29: =AND(KI$23>=$KB29,KI$23<=$KC29)*(IF($F29="Steady Growth",KI$23-$KB29,$KC29-KI$23)+1)/($KD29*($KD29+1)/2)*$KE29 -> 0 | KJ29: =AND(KJ$23>=$KB29,KJ$23<=$KC29)*(IF($F29="Steady Growth",KJ$23-$KB29,$KC29-KJ$23)+1)/($KD29*($KD29+1)/2)*$KE29 -> 0 | KK29: =AND(KK$23>=$KB29,KK$23<=$KC29)*(IF($F29="Steady Growth",KK$23-$KB29,$KC29-KK$23)+1)/($KD29*($KD29+1)/2)*$KE29 -> 0 | KL29: =AND(KL$23>=$KB29,KL$23<=$KC29)*(IF($F29="Steady Growth",KL$23-$KB29,$KC29-KL$23)+1)/($KD29*($KD29+1)/2)*$KE29 -> 0 | KM29: =AND(KM$23>=$KB29,KM$23<=$KC29)*(IF($F29="Steady Growth",KM$23-$KB29,$KC29-KM$23)+1)/($KD29*($KD29+1)/2)*$KE29 -> 0 | ... PH29: =AND(PH$23>=$KB29,PH$23<=$KC29)*(IF($F29="Steady Growth",PH$23-$KB29,$KC29-PH$23)+1)/($KD29*($KD29+1)/2)*$KE29 -> 0
B30: ARENA grant / development incentive (funding source; excluded from gross cost) | C30: 0 | E30: 0 | F30: Straight-Line | G30: =I30/Units_SF_M2 -> 0 | I30: =MAX(0,'URWLD COMPANY INPUTS'!$D$750*1000000) -> 0 | K30: =IF(ROUND(SUM(L30:EN30),0)=ROUND(I30,0),"","Incomplete") | L30: =AND(L$23>=$D30,L$23<=$E30)*(OR($F30="Straight-Line",$F30="Detail")*($I30/$ES30)+($F30="S-Curve")*EV30+OR($F30="Steady Growth",$F30="Steady Decline")*KF30) -> 0 | M30: =AND(M$23>=$D30,M$23<=$E30)*(OR($F30="Straight-Line",$F30="Detail")*($I30/$ES30)+($F30="S-Curve")*EW30+OR($F30="Steady Growth",$F30="Steady Decline")*KG30) -> 0 | N30: =AND(N$23>=$D30,N$23<=$E30)*(OR($F30="Straight-Line",$F30="Detail")*($I30/$ES30)+($F30="S-Curve")*EX30+OR($F30="Steady Growth",$F30="Steady Decline")*KH30) -> 0 | O30: =AND(O$23>=$D30,O$23<=$E30)*(OR($F30="Straight-Line",$F30="Detail")*($I30/$ES30)+($F30="S-Curve")*EY30+OR($F30="Steady Growth",$F30="Steady Decline")*KI30) -> 0 | P30: =AND(P$23>=$D30,P$23<=$E30)*(OR($F30="Straight-Line",$F30="Detail")*($I30/$ES30)+($F30="S-Curve")*EZ30+OR($F30="Steady Growth",$F30="Steady Decline")*KJ30) -> 0 | Q30: =AND(Q$23>=$D30,Q$23<=$E30)*(OR($F30="Straight-Line",$F30="Detail")*($I30/$ES30)+($F30="S-Curve")*FA30+OR($F30="Steady Growth",$F30="Steady Decline")*KK30) -> 0 | R30: =AND(R$23>=$D30,R$23<=$E30)*(OR($F30="Straight-Line",$F30="Detail")*($I30/$ES30)+($F30="S-Curve")*FB30+OR($F30="Steady Growth",$F30="Steady Decline")*KL30) -> 0 | S30: =AND(S$23>=$D30,S$23<=$E30)*(OR($F30="Straight-Line",$F30="Detail")*($I30/$ES30)+($F30="S-Curve")*FC30+OR($F30="Steady Growth",$F30="Steady Decline")*KM30) -> 0 | ... EN30: =AND(EN$23>=$D30,EN$23<=$E30)*(OR($F30="Straight-Line",$F30="Detail")*($I30/$ES30)+($F30="S-Curve")*JX30+OR($F30="Steady Growth",$F30="Steady Decline")*PH30) -> 0 | EP30: =I30 -> 0 | EQ30: =INDEX($L$24:$EN$24,1,$D30+1) -> 46203 | ER30: =INDEX($L$24:$EN$24,1,$E30+1) -> 46203 | ES30: =+E30-D30+1 -> 1 | ET30: =F30 -> Straight-Line | EU30: =ES30/Scurve_Dist -> 0.16666667 | EV30: =AND($ET30="S-Curve",EV$24>=$EQ30,EV$24<=$ER30)*(NORMDIST((YEAR(EV$24)-YEAR($EQ30))*12+MONTH(EV$24)-MONTH($EQ30)+1,$ES30/2,$EU30,TRUE)-NORMDIST((YEAR(EV$24)-YEAR($EQ30))*12+MONTH(EV$24)-MONTH($EQ30),$ES30/2,$EU30,TRUE))/(1-2*NORMDIST(0,$ES30/2,$EU30,TRUE))*$EP30 -> 0 | EW30: =AND($ET30="S-Curve",EW$24>=$EQ30,EW$24<=$ER30)*(NORMDIST((YEAR(EW$24)-YEAR($EQ30))*12+MONTH(EW$24)-MONTH($EQ30)+1,$ES30/2,$EU30,TRUE)-NORMDIST((YEAR(EW$24)-YEAR($EQ30))*12+MONTH(EW$24)-MONTH($EQ30),$ES30/2,$EU30,TRUE))/(1-2*NORMDIST(0,$ES30/2,$EU30,TRUE))*$EP30 -> 0 | EX30: =AND($ET30="S-Curve",EX$24>=$EQ30,EX$24<=$ER30)*(NORMDIST((YEAR(EX$24)-YEAR($EQ30))*12+MONTH(EX$24)-MONTH($EQ30)+1,$ES30/2,$EU30,TRUE)-NORMDIST((YEAR(EX$24)-YEAR($EQ30))*12+MONTH(EX$24)-MONTH($EQ30),$ES30/2,$EU30,TRUE))/(1-2*NORMDIST(0,$ES30/2,$EU30,TRUE))*$EP30 -> 0 | EY30: =AND($ET30="S-Curve",EY$24>=$EQ30,EY$24<=$ER30)*(NORMDIST((YEAR(EY$24)-YEAR($EQ30))*12+MONTH(EY$24)-MONTH($EQ30)+1,$ES30/2,$EU30,TRUE)-NORMDIST((YEAR(EY$24)-YEAR($EQ30))*12+MONTH(EY$24)-MONTH($EQ30),$ES30/2,$EU30,TRUE))/(1-2*NORMDIST(0,$ES30/2,$EU30,TRUE))*$EP30 -> 0 | EZ30: =AND($ET30="S-Curve",EZ$24>=$EQ30,EZ$24<=$ER30)*(NORMDIST((YEAR(EZ$24)-YEAR($EQ30))*12+MONTH(EZ$24)-MONTH($EQ30)+1,$ES30/2,$EU30,TRUE)-NORMDIST((YEAR(EZ$24)-YEAR($EQ30))*12+MONTH(EZ$24)-MONTH($EQ30),$ES30/2,$EU30,TRUE))/(1-2*NORMDIST(0,$ES30/2,$EU30,TRUE))*$EP30 -> 0 | FA30: =AND($ET30="S-Curve",FA$24>=$EQ30,FA$24<=$ER30)*(NORMDIST((YEAR(FA$24)-YEAR($EQ30))*12+MONTH(FA$24)-MONTH($EQ30)+1,$ES30/2,$EU30,TRUE)-NORMDIST((YEAR(FA$24)-YEAR($EQ30))*12+MONTH(FA$24)-MONTH($EQ30),$ES30/2,$EU30,TRUE))/(1-2*NORMDIST(0,$ES30/2,$EU30,TRUE))*$EP30 -> 0 | FB30: =AND($ET30="S-Curve",FB$24>=$EQ30,FB$24<=$ER30)*(NORMDIST((YEAR(FB$24)-YEAR($EQ30))*12+MONTH(FB$24)-MONTH($EQ30)+1,$ES30/2,$EU30,TRUE)-NORMDIST((YEAR(FB$24)-YEAR($EQ30))*12+MONTH(FB$24)-MONTH($EQ30),$ES30/2,$EU30,TRUE))/(1-2*NORMDIST(0,$ES30/2,$EU30,TRUE))*$EP30 -> 0 | FC30: =AND($ET30="S-Curve",FC$24>=$EQ30,FC$24<=$ER30)*(NORMDIST((YEAR(FC$24)-YEAR($EQ30))*12+MONTH(FC$24)-MONTH($EQ30)+1,$ES30/2,$EU30,TRUE)-NORMDIST((YEAR(FC$24)-YEAR($EQ30))*12+MONTH(FC$24)-MONTH($EQ30),$ES30/2,$EU30,TRUE))/(1-2*NORMDIST(0,$ES30/2,$EU30,TRUE))*$EP30 -> 0 | ... JX30: =AND($ET30="S-Curve",JX$24>=$EQ30,JX$24<=$ER30)*(NORMDIST((YEAR(JX$24)-YEAR($EQ30))*12+MONTH(JX$24)-MONTH($EQ30)+1,$ES30/2,$EU30,TRUE)-NORMDIST((YEAR(JX$24)-YEAR($EQ30))*12+MONTH(JX$24)-MONTH($EQ30),$ES30/2,$EU30,TRUE))/(1-2*NORMDIST(0,$ES30/2,$EU30,TRUE))*$EP30 -> 0 | JZ30: =B30 -> ARENA grant / development incentive (funding source; excluded from gross cost) | KB30: =D30 -> 0 | KC30: =E30 -> 0 | KD30: =KC30-KB30+1 -> 1 | KE30: =I30 -> 0 | KF30: =AND(KF$23>=$KB30,KF$23<=$KC30)*(IF($F30="Steady Growth",KF$23-$KB30,$KC30-KF$23)+1)/($KD30*($KD30+1)/2)*$KE30 -> 0 | KG30: =AND(KG$23>=$KB30,KG$23<=$KC30)*(IF($F30="Steady Growth",KG$23-$KB30,$KC30-KG$23)+1)/($KD30*($KD30+1)/2)*$KE30 -> 0 | KH30: =AND(KH$23>=$KB30,KH$23<=$KC30)*(IF($F30="Steady Growth",KH$23-$KB30,$KC30-KH$23)+1)/($KD30*($KD30+1)/2)*$KE30 -> 0 | KI30: =AND(KI$23>=$KB30,KI$23<=$KC30)*(IF($F30="Steady Growth",KI$23-$KB30,$KC30-KI$23)+1)/($KD30*($KD30+1)/2)*$KE30 -> 0 | KJ30: =AND(KJ$23>=$KB30,KJ$23<=$KC30)*(IF($F30="Steady Growth",KJ$23-$KB30,$KC30-KJ$23)+1)/($KD30*($KD30+1)/2)*$KE30 -> 0 | KK30: =AND(KK$23>=$KB30,KK$23<=$KC30)*(IF($F30="Steady Growth",KK$23-$KB30,$KC30-KK$23)+1)/($KD30*($KD30+1)/2)*$KE30 -> 0 | KL30: =AND(KL$23>=$KB30,KL$23<=$KC30)*(IF($F30="Steady Growth",KL$23-$KB30,$KC30-KL$23)+1)/($KD30*($KD30+1)/2)*$KE30 -> 0 | KM30: =AND(KM$23>=$KB30,KM$23<=$KC30)*(IF($F30="Steady Growth",KM$23-$KB30,$KC30-KM$23)+1)/($KD30*($KD30+1)/2)*$KE30 -> 0 | ... PH30: =AND(PH$23>=$KB30,PH$23<=$KC30)*(IF($F30="Steady Growth",PH$23-$KB30,$KC30-PH$23)+1)/($KD30*($KD30+1)/2)*$KE30 -> 0
B31: Total Land Costs | C31: =MIN(D27:D30) -> 0 | E31: =MAX(E27:E30) -> 0 | F31: =SUM(H27:H30) -> 0 | I31: =SUM(I27:I30) -> 92320000 | K31: =IF(ROUND(SUM(L31:EN31),0)=ROUND(I31,0),"","Incomplete") | L31: =SUM(L27:L30) -> 92320000 | M31: =SUM(M27:M30) -> 0 | N31: =SUM(N27:N30) -> 0 | O31: =SUM(O27:O30) -> 0 | P31: =SUM(P27:P30) -> 0 | Q31: =SUM(Q27:Q30) -> 0 | R31: =SUM(R27:R30) -> 0 | S31: =SUM(S27:S30) -> 0 | ... EN31: =SUM(EN27:EN30) -> 0 | EQ31: # of Land Cost Items | ER31: =COUNTA($B$27:$B$30) -> 3 | JZ31: =B31 -> Total Land Costs
JZ33: =B33 -> 0
C34: 1 | E34: =(VALUE(RIGHT('URWLD COMPANY INPUTS'!$F$46,4))-VALUE(RIGHT('URWLD COMPANY INPUTS'!$F$45,4)))*12+(VALUE(MID('URWLD COMPANY INPUTS'!$F$46,2,1))-VALUE(MID('URWLD COMPANY INPUTS'!$F$45,2,1)))*3+3 -> 36 | F34: S-Curve | G34: =I34/Units_SF_M2 -> 4363.7231 | I34: =('URWLD COMPANY INPUTS'!$E$192/'URWLD COMPANY INPUTS'!$E$53+'URWLD COMPANY INPUTS'!$F$194*'URWLD COMPANY INPUTS'!$E$52/'URWLD COMPANY INPUTS'!$E$53+'URWLD COMPANY INPUTS'!$F$197*'URWLD COMPANY INPUTS'!$E$52/'URWLD COMPANY INPUTS'!$E$53+'URWLD COMPANY INPUTS'!$F$198*'URWLD COMPANY INPUTS'!$E$52/'URWLD COMPANY INPUTS'!$E$53*25%+'URWLD COMPANY INPUTS'!$F$205*'URWLD COMPANY INPUTS'!$E$52/'URWLD COMPANY INPUTS'!$E$53)+SUM('URWLD COMPANY INPUTS'!$D$411:$D$414)+'URWLD COMPANY INPUTS'!$D$597+'URWLD COMPANY INPUTS'!$D$628*50%+'URWLD COMPANY INPUTS'!$D$404*1000000+1200000+SUM('URWLD COMPANY INPUTS'!$D$423:$D$425)+'URWLD COMPANY INPUTS'!$D$604*1000000+'URWLD COMPANY INPUTS'!$D$613*1000000+SUM('URWLD COMPANY INPUTS'!$D$657:$D$665)+SUM('URWLD COMPANY INPUTS'!$D$620:$D$621)*1000000+264000+'URWLD COMPANY INPUTS'!$D$636+'URWLD COMPANY INPUTS'!$D$638+SUM('URWLD COMPANY INPUTS'!$D$703:$D$706)*1000000+SUM('URWLD COMPANY INPUTS'!$D$709,'URWLD COMPANY INPUTS'!$D$712,'URWLD COMPANY INPUTS'!$D$714,'URWLD COMPANY INPUTS'!$D$715,'URWLD COMPANY INPUTS'!$D$718,'URWLD COMPANY INPUTS'!$D$720,'URWLD COMPANY INPUTS'!$D$722,'URWLD COMPANY INPUTS'!$D$724,'URWLD COMPANY INPUTS'!$D$727,'URWLD COMPANY INPUTS'!$D$729,'URWLD COMPANY INPUTS'!$D$731,'URWLD COMPANY INPUTS'!$D$733,'URWLD COMPANY INPUTS'!$D$628,'URWLD COMPANY INPUTS'!$D$736)+850000+1920000-'URWLD COMPANY INPUTS'!$D$703*1000000+18000000+N("Source schedule constants: Genesis C19 residual A$1.2m; convenience E21 A$0.264m; common N159 A$0.85m; common N166 A$1.92m; project management H25 A$18.0m.") -> 3.4242301e+08 | K34: =IF(ROUND(SUM(L34:EN34),0)=ROUND(I34,0),"","Incomplete") | L34: =AND(L$23>=$D34,L$23<=$E34)*(OR($F34="Straight-Line",$F34="Detail")*($I34/$ES34)+($F34="S-Curve")*EV34+OR($F34="Steady Growth",$F34="Steady Decline")*KF34) -> 316264.67 | M34: =AND(M$23>=$D34,M$23<=$E34)*(OR($F34="Straight-Line",$F34="Detail")*($I34/$ES34)+($F34="S-Curve")*EW34+OR($F34="Steady Growth",$F34="Steady Decline")*KG34) -> 500578.94 | N34: =AND(N$23>=$D34,N$23<=$E34)*(OR($F34="Straight-Line",$F34="Detail")*($I34/$ES34)+($F34="S-Curve")*EX34+OR($F34="Steady Growth",$F34="Steady Decline")*KH34) -> 771789.34 | O34: =AND(O$23>=$D34,O$23<=$E34)*(OR($F34="Straight-Line",$F34="Detail")*($I34/$ES34)+($F34="S-Curve")*EY34+OR($F34="Steady Growth",$F34="Steady Decline")*KI34) -> 1159122.4 | P34: =AND(P$23>=$D34,P$23<=$E34)*(OR($F34="Straight-Line",$F34="Detail")*($I34/$ES34)+($F34="S-Curve")*EZ34+OR($F34="Steady Growth",$F34="Steady Decline")*KJ34) -> 1695759.2 | Q34: =AND(Q$23>=$D34,Q$23<=$E34)*(OR($F34="Straight-Line",$F34="Detail")*($I34/$ES34)+($F34="S-Curve")*FA34+OR($F34="Steady Growth",$F34="Steady Decline")*KK34) -> 2416592.7 | R34: =AND(R$23>=$D34,R$23<=$E34)*(OR($F34="Straight-Line",$F34="Detail")*($I34/$ES34)+($F34="S-Curve")*FB34+OR($F34="Steady Growth",$F34="Steady Decline")*KL34) -> 3354649.4 | S34: =AND(S$23>=$D34,S$23<=$E34)*(OR($F34="Straight-Line",$F34="Detail")*($I34/$ES34)+($F34="S-Curve")*FC34+OR($F34="Steady Growth",$F34="Steady Decline")*KM34) -> 4536231.9 | ... EN34: =AND(EN$23>=$D34,EN$23<=$E34)*(OR($F34="Straight-Line",$F34="Detail")*($I34/$ES34)+($F34="S-Curve")*JX34+OR($F34="Steady Growth",$F34="Steady Decline")*PH34) -> 0 | EP34: =I34 -> 3.4242301e+08 | EQ34: =INDEX($L$24:$EN$24,1,$D34+1) -> 46203 | ER34: =INDEX($L$24:$EN$24,1,$E34+1) -> 47299 | ES34: =+E34-D34+1 -> 37 | ET34: =F34 -> S-Curve | EU34: =ES34/Scurve_Dist -> 6.1666667 | EV34: =AND($ET34="S-Curve",EV$24>=$EQ34,EV$24<=$ER34)*(NORMDIST((YEAR(EV$24)-YEAR($EQ34))*12+MONTH(EV$24)-MONTH($EQ34)+1,$ES34/2,$EU34,TRUE)-NORMDIST((YEAR(EV$24)-YEAR($EQ34))*12+MONTH(EV$24)-MONTH($EQ34),$ES34/2,$EU34,TRUE))/(1-2*NORMDIST(0,$ES34/2,$EU34,TRUE))*$EP34 -> 316264.67 | EW34: =AND($ET34="S-Curve",EW$24>=$EQ34,EW$24<=$ER34)*(NORMDIST((YEAR(EW$24)-YEAR($EQ34))*12+MONTH(EW$24)-MONTH($EQ34)+1,$ES34/2,$EU34,TRUE)-NORMDIST((YEAR(EW$24)-YEAR($EQ34))*12+MONTH(EW$24)-MONTH($EQ34),$ES34/2,$EU34,TRUE))/(1-2*NORMDIST(0,$ES34/2,$EU34,TRUE))*$EP34 -> 500578.94 | EX34: =AND($ET34="S-Curve",EX$24>=$EQ34,EX$24<=$ER34)*(NORMDIST((YEAR(EX$24)-YEAR($EQ34))*12+MONTH(EX$24)-MONTH($EQ34)+1,$ES34/2,$EU34,TRUE)-NORMDIST((YEAR(EX$24)-YEAR($EQ34))*12+MONTH(EX$24)-MONTH($EQ34),$ES34/2,$EU34,TRUE))/(1-2*NORMDIST(0,$ES34/2,$EU34,TRUE))*$EP34 -> 771789.34 | EY34: =AND($ET34="S-Curve",EY$24>=$EQ34,EY$24<=$ER34)*(NORMDIST((YEAR(EY$24)-YEAR($EQ34))*12+MONTH(EY$24)-MONTH($EQ34)+1,$ES34/2,$EU34,TRUE)-NORMDIST((YEAR(EY$24)-YEAR($EQ34))*12+MONTH(EY$24)-MONTH($EQ34),$ES34/2,$EU34,TRUE))/(1-2*NORMDIST(0,$ES34/2,$EU34,TRUE))*$EP34 -> 1159122.4 | EZ34: =AND($ET34="S-Curve",EZ$24>=$EQ34,EZ$24<=$ER34)*(NORMDIST((YEAR(EZ$24)-YEAR($EQ34))*12+MONTH(EZ$24)-MONTH($EQ34)+1,$ES34/2,$EU34,TRUE)-NORMDIST((YEAR(EZ$24)-YEAR($EQ34))*12+MONTH(EZ$24)-MONTH($EQ34),$ES34/2,$EU34,TRUE))/(1-2*NORMDIST(0,$ES34/2,$EU34,TRUE))*$EP34 -> 1695759.2 | FA34: =AND($ET34="S-Curve",FA$24>=$EQ34,FA$24<=$ER34)*(NORMDIST((YEAR(FA$24)-YEAR($EQ34))*12+MONTH(FA$24)-MONTH($EQ34)+1,$ES34/2,$EU34,TRUE)-NORMDIST((YEAR(FA$24)-YEAR($EQ34))*12+MONTH(FA$24)-MONTH($EQ34),$ES34/2,$EU34,TRUE))/(1-2*NORMDIST(0,$ES34/2,$EU34,TRUE))*$EP34 -> 2416592.7 | FB34: =AND($ET34="S-Curve",FB$24>=$EQ34,FB$24<=$ER34)*(NORMDIST((YEAR(FB$24)-YEAR($EQ34))*12+MONTH(FB$24)-MONTH($EQ34)+1,$ES34/2,$EU34,TRUE)-NORMDIST((YEAR(FB$24)-YEAR($EQ34))*12+MONTH(FB$24)-MONTH($EQ34),$ES34/2,$EU34,TRUE))/(1-2*NORMDIST(0,$ES34/2,$EU34,TRUE))*$EP34 -> 3354649.4 | FC34: =AND($ET34="S-Curve",FC$24>=$EQ34,FC$24<=$ER34)*(NORMDIST((YEAR(FC$24)-YEAR($EQ34))*12+MONTH(FC$24)-MONTH($EQ34)+1,$ES34/2,$EU34,TRUE)-NORMDIST((YEAR(FC$24)-YEAR($EQ34))*12+MONTH(FC$24)-MONTH($EQ34),$ES34/2,$EU34,TRUE))/(1-2*NORMDIST(0,$ES34/2,$EU34,TRUE))*$EP34 -> 4536231.9 | ... JX34: =AND($ET34="S-Curve",JX$24>=$EQ34,JX$24<=$ER34)*(NORMDIST((YEAR(JX$24)-YEAR($EQ34))*12+MONTH(JX$24)-MONTH($EQ34)+1,$ES34/2,$EU34,TRUE)-NORMDIST((YEAR(JX$24)-YEAR($EQ34))*12+MONTH(JX$24)-MONTH($EQ34),$ES34/2,$EU34,TRUE))/(1-2*NORMDIST(0,$ES34/2,$EU34,TRUE))*$EP34 -> 0 | JZ34: =B34 -> 0 | KB34: =D34 -> 0 | KC34: =E34 -> 36 | KD34: =KC34-KB34+1 -> 37 | KE34: =I34 -> 3.4242301e+08 | KF34: =AND(KF$23>=$KB34,KF$23<=$KC34)*(IF($F34="Steady Growth",KF$23-$KB34,$KC34-KF$23)+1)/($KD34*($KD34+1)/2)*$KE34 -> 18022263 | KG34: =AND(KG$23>=$KB34,KG$23<=$KC34)*(IF($F34="Steady Growth",KG$23-$KB34,$KC34-KG$23)+1)/($KD34*($KD34+1)/2)*$KE34 -> 17535175 | KH34: =AND(KH$23>=$KB34,KH$23<=$KC34)*(IF($F34="Steady Growth",KH$23-$KB34,$KC34-KH$23)+1)/($KD34*($KD34+1)/2)*$KE34 -> 17048087 | KI34: =AND(KI$23>=$KB34,KI$23<=$KC34)*(IF($F34="Steady Growth",KI$23-$KB34,$KC34-KI$23)+1)/($KD34*($KD34+1)/2)*$KE34 -> 16560999 | KJ34: =AND(KJ$23>=$KB34,KJ$23<=$KC34)*(IF($F34="Steady Growth",KJ$23-$KB34,$KC34-KJ$23)+1)/($KD34*($KD34+1)/2)*$KE34 -> 16073911 | KK34: =AND(KK$23>=$KB34,KK$23<=$KC34)*(IF($F34="Steady Growth",KK$23-$KB34,$KC34-KK$23)+1)/($KD34*($KD34+1)/2)*$KE34 -> 15586822 | KL34: =AND(KL$23>=$KB34,KL$23<=$KC34)*(IF($F34="Steady Growth",KL$23-$KB34,$KC34-KL$23)+1)/($KD34*($KD34+1)/2)*$KE34 -> 15099734 | KM34: =AND(KM$23>=$KB34,KM$23<=$KC34)*(IF($F34="Steady Growth",KM$23-$KB34,$KC34-KM$23)+1)/($KD34*($KD34+1)/2)*$KE34 -> 14612646 | ... PH34: =AND(PH$23>=$KB34,PH$23<=$KC34)*(IF($F34="Steady Growth",PH$23-$KB34,$KC34-PH$23)+1)/($KD34*($KD34+1)/2)*$KE34 -> 0
B35: Net infrastructure fund | C35: 1 | E35: =$E$34 -> 36 | F35: Straight-Line | G35: =I35/Units_SF_M2 -> 179.85931 | I35: =SUM('URWLD COMPANY INPUTS'!$D$125:$D$126)*1000000 -> 14113629 | K35: =IF(ROUND(SUM(L35:EN35),0)=ROUND(I35,0),"","Incomplete") | L35: =AND(L$23>=$D35,L$23<=$E35)*(OR($F35="Straight-Line",$F35="Detail")*($I35/$ES35)+($F35="S-Curve")*EV35+OR($F35="Steady Growth",$F35="Steady Decline")*KF35) -> 381449.42 | M35: =AND(M$23>=$D35,M$23<=$E35)*(OR($F35="Straight-Line",$F35="Detail")*($I35/$ES35)+($F35="S-Curve")*EW35+OR($F35="Steady Growth",$F35="Steady Decline")*KG35) -> 381449.42 | N35: =AND(N$23>=$D35,N$23<=$E35)*(OR($F35="Straight-Line",$F35="Detail")*($I35/$ES35)+($F35="S-Curve")*EX35+OR($F35="Steady Growth",$F35="Steady Decline")*KH35) -> 381449.42 | O35: =AND(O$23>=$D35,O$23<=$E35)*(OR($F35="Straight-Line",$F35="Detail")*($I35/$ES35)+($F35="S-Curve")*EY35+OR($F35="Steady Growth",$F35="Steady Decline")*KI35) -> 381449.42 | P35: =AND(P$23>=$D35,P$23<=$E35)*(OR($F35="Straight-Line",$F35="Detail")*($I35/$ES35)+($F35="S-Curve")*EZ35+OR($F35="Steady Growth",$F35="Steady Decline")*KJ35) -> 381449.42 | Q35: =AND(Q$23>=$D35,Q$23<=$E35)*(OR($F35="Straight-Line",$F35="Detail")*($I35/$ES35)+($F35="S-Curve")*FA35+OR($F35="Steady Growth",$F35="Steady Decline")*KK35) -> 381449.42 | R35: =AND(R$23>=$D35,R$23<=$E35)*(OR($F35="Straight-Line",$F35="Detail")*($I35/$ES35)+($F35="S-Curve")*FB35+OR($F35="Steady Growth",$F35="Steady Decline")*KL35) -> 381449.42 | S35: =AND(S$23>=$D35,S$23<=$E35)*(OR($F35="Straight-Line",$F35="Detail")*($I35/$ES35)+($F35="S-Curve")*FC35+OR($F35="Steady Growth",$F35="Steady Decline")*KM35) -> 381449.42 | ... EN35: =AND(EN$23>=$D35,EN$23<=$E35)*(OR($F35="Straight-Line",$F35="Detail")*($I35/$ES35)+($F35="S-Curve")*JX35+OR($F35="Steady Growth",$F35="Steady Decline")*PH35) -> 0 | EP35: =I35 -> 14113629 | EQ35: =INDEX($L$24:$EN$24,1,$D35+1) -> 46203 | ER35: =INDEX($L$24:$EN$24,1,$E35+1) -> 47299 | ES35: =+E35-D35+1 -> 37 | ET35: =F35 -> Straight-Line | EU35: =ES35/Scurve_Dist -> 6.1666667 | EV35: =AND($ET35="S-Curve",EV$24>=$EQ35,EV$24<=$ER35)*(NORMDIST((YEAR(EV$24)-YEAR($EQ35))*12+MONTH(EV$24)-MONTH($EQ35)+1,$ES35/2,$EU35,TRUE)-NORMDIST((YEAR(EV$24)-YEAR($EQ35))*12+MONTH(EV$24)-MONTH($EQ35),$ES35/2,$EU35,TRUE))/(1-2*NORMDIST(0,$ES35/2,$EU35,TRUE))*$EP35 -> 0 | EW35: =AND($ET35="S-Curve",EW$24>=$EQ35,EW$24<=$ER35)*(NORMDIST((YEAR(EW$24)-YEAR($EQ35))*12+MONTH(EW$24)-MONTH($EQ35)+1,$ES35/2,$EU35,TRUE)-NORMDIST((YEAR(EW$24)-YEAR($EQ35))*12+MONTH(EW$24)-MONTH($EQ35),$ES35/2,$EU35,TRUE))/(1-2*NORMDIST(0,$ES35/2,$EU35,TRUE))*$EP35 -> 0 | EX35: =AND($ET35="S-Curve",EX$24>=$EQ35,EX$24<=$ER35)*(NORMDIST((YEAR(EX$24)-YEAR($EQ35))*12+MONTH(EX$24)-MONTH($EQ35)+1,$ES35/2,$EU35,TRUE)-NORMDIST((YEAR(EX$24)-YEAR($EQ35))*12+MONTH(EX$24)-MONTH($EQ35),$ES35/2,$EU35,TRUE))/(1-2*NORMDIST(0,$ES35/2,$EU35,TRUE))*$EP35 -> 0 | EY35: =AND($ET35="S-Curve",EY$24>=$EQ35,EY$24<=$ER35)*(NORMDIST((YEAR(EY$24)-YEAR($EQ35))*12+MONTH(EY$24)-MONTH($EQ35)+1,$ES35/2,$EU35,TRUE)-NORMDIST((YEAR(EY$24)-YEAR($EQ35))*12+MONTH(EY$24)-MONTH($EQ35),$ES35/2,$EU35,TRUE))/(1-2*NORMDIST(0,$ES35/2,$EU35,TRUE))*$EP35 -> 0 | EZ35: =AND($ET35="S-Curve",EZ$24>=$EQ35,EZ$24<=$ER35)*(NORMDIST((YEAR(EZ$24)-YEAR($EQ35))*12+MONTH(EZ$24)-MONTH($EQ35)+1,$ES35/2,$EU35,TRUE)-NORMDIST((YEAR(EZ$24)-YEAR($EQ35))*12+MONTH(EZ$24)-MONTH($EQ35),$ES35/2,$EU35,TRUE))/(1-2*NORMDIST(0,$ES35/2,$EU35,TRUE))*$EP35 -> 0 | FA35: =AND($ET35="S-Curve",FA$24>=$EQ35,FA$24<=$ER35)*(NORMDIST((YEAR(FA$24)-YEAR($EQ35))*12+MONTH(FA$24)-MONTH($EQ35)+1,$ES35/2,$EU35,TRUE)-NORMDIST((YEAR(FA$24)-YEAR($EQ35))*12+MONTH(FA$24)-MONTH($EQ35),$ES35/2,$EU35,TRUE))/(1-2*NORMDIST(0,$ES35/2,$EU35,TRUE))*$EP35 -> 0 | FB35: =AND($ET35="S-Curve",FB$24>=$EQ35,FB$24<=$ER35)*(NORMDIST((YEAR(FB$24)-YEAR($EQ35))*12+MONTH(FB$24)-MONTH($EQ35)+1,$ES35/2,$EU35,TRUE)-NORMDIST((YEAR(FB$24)-YEAR($EQ35))*12+MONTH(FB$24)-MONTH($EQ35),$ES35/2,$EU35,TRUE))/(1-2*NORMDIST(0,$ES35/2,$EU35,TRUE))*$EP35 -> 0 | FC35: =AND($ET35="S-Curve",FC$24>=$EQ35,FC$24<=$ER35)*(NORMDIST((YEAR(FC$24)-YEAR($EQ35))*12+MONTH(FC$24)-MONTH($EQ35)+1,$ES35/2,$EU35,TRUE)-NORMDIST((YEAR(FC$24)-YEAR($EQ35))*12+MONTH(FC$24)-MONTH($EQ35),$ES35/2,$EU35,TRUE))/(1-2*NORMDIST(0,$ES35/2,$EU35,TRUE))*$EP35 -> 0 | ... JX35: =AND($ET35="S-Curve",JX$24>=$EQ35,JX$24<=$ER35)*(NORMDIST((YEAR(JX$24)-YEAR($EQ35))*12+MONTH(JX$24)-MONTH($EQ35)+1,$ES35/2,$EU35,TRUE)-NORMDIST((YEAR(JX$24)-YEAR($EQ35))*12+MONTH(JX$24)-MONTH($EQ35),$ES35/2,$EU35,TRUE))/(1-2*NORMDIST(0,$ES35/2,$EU35,TRUE))*$EP35 -> 0 | JZ35: =B35 -> Net infrastructure fund | KB35: =D35 -> 0 | KC35: =E35 -> 36 | KD35: =KC35-KB35+1 -> 37 | KE35: =I35 -> 14113629 | KF35: =AND(KF$23>=$KB35,KF$23<=$KC35)*(IF($F35="Steady Growth",KF$23-$KB35,$KC35-KF$23)+1)/($KD35*($KD35+1)/2)*$KE35 -> 742822.56 | KG35: =AND(KG$23>=$KB35,KG$23<=$KC35)*(IF($F35="Steady Growth",KG$23-$KB35,$KC35-KG$23)+1)/($KD35*($KD35+1)/2)*$KE35 -> 722746.28 | KH35: =AND(KH$23>=$KB35,KH$23<=$KC35)*(IF($F35="Steady Growth",KH$23-$KB35,$KC35-KH$23)+1)/($KD35*($KD35+1)/2)*$KE35 -> 702669.99 | KI35: =AND(KI$23>=$KB35,KI$23<=$KC35)*(IF($F35="Steady Growth",KI$23-$KB35,$KC35-KI$23)+1)/($KD35*($KD35+1)/2)*$KE35 -> 682593.71 | KJ35: =AND(KJ$23>=$KB35,KJ$23<=$KC35)*(IF($F35="Steady Growth",KJ$23-$KB35,$KC35-KJ$23)+1)/($KD35*($KD35+1)/2)*$KE35 -> 662517.42 | KK35: =AND(KK$23>=$KB35,KK$23<=$KC35)*(IF($F35="Steady Growth",KK$23-$KB35,$KC35-KK$23)+1)/($KD35*($KD35+1)/2)*$KE35 -> 642441.13 | KL35: =AND(KL$23>=$KB35,KL$23<=$KC35)*(IF($F35="Steady Growth",KL$23-$KB35,$KC35-KL$23)+1)/($KD35*($KD35+1)/2)*$KE35 -> 622364.85 | KM35: =AND(KM$23>=$KB35,KM$23<=$KC35)*(IF($F35="Steady Growth",KM$23-$KB35,$KC35-KM$23)+1)/($KD35*($KD35+1)/2)*$KE35 -> 602288.56 | ... PH35: =AND(PH$23>=$KB35,PH$23<=$KC35)*(IF($F35="Steady Growth",PH$23-$KB35,$KC35-PH$23)+1)/($KD35*($KD35+1)/2)*$KE35 -> 0
