Workbook
Name Curr_Unit: InpC!$F$62
Name SMU: InpC!$F$61

Sheet InpC
A1: =RIGHT(CELL("filename", A1), LEN(CELL("filename", A1)) - SEARCH("]", CELL("filename", A1))) -> InpC
F4: ='T&E'!F$12 -> constant | G4: ='T&E'!G$12 -> unit | H4: who | I4: source | J4: comments
A6: TIMING
E8: First date of time ruler | F8: 41639 | G8: date
E10: Financial close date | F10: 41698 | G10: EOM
E11: Length of construction period | F11: 22 | G11: months
E12: Construction period end / conversion date | F12: =EOMONTH(F10, F11) -> 42369 | G12: date
E14: Length of forecast period | F14: 30 | G14: years
E15: Last forecast date | F15: =EOMONTH( F12, 12 * F14 ) -> 53327 | G15: date
E17: Annual CPI inflation rate | F17: 0.025 | G17: p.a.
E18: Price and cost basis date - period ending | F18: 41820 | G18: date
A21: OPERATIONS ASSUMPTIONS
E23: Aircraft capacity - domestic charter | F23: 110 | G23: seats
E24: Aircraft capacity - domestic scheduled | F24: 140 | G24: seats
E25: Aircraft capacity - international chartered | F25: 250 | G25: seats
E26: Aircraft capacity - international scheduled | F26: 280 | G26: seats
E28: Passenger landing tax rate | F28: 22.75 | G28: =Curr_Unit & " / PAx" -> € / PAx
E30: Passenger retail purchases rate | F30: 10.5 | G30: =Curr_Unit & " / PAx" -> € / PAx
E31: Rental revenue sharing percentage | F31: 0.25 | G31: of sales
E33: Variable ground handling charge rate | F33: 340 | G33: =Curr_Unit & " / landing" -> € / landing
E34: Fixed ground handling costs | F34: 3600 | G34: =Curr_Unit & " 000s p.a." -> € 000s p.a.
E35: Airport terminal O&M contract costs | F35: 2400 | G35: =Curr_Unit & " 000s p.a." -> € 000s p.a.
A38: FINANCE, TAX, AND ACCOUNTING
E40: Senior debt coupon base rate | F40: 0.075 | G40: p.a. (semi)
E41: Senior principal repayment selection switch | F41: 5 | G41: switch
E43: =E$12 -> Construction period end / conversion date | F43: =F$12 -> 42369 | G43: =G$12 -> date
E44: Useful life input | F44: 25 | G44: years
E45: Last date of accounting depreciation | F45: =EOMONTH(F43, 12 * F44) -> 51501 | G45: date
E47: Reducing balance rate for tax | F47: 0.05 | G47: of basis
E49: Corporation tax rate | F49: 0.3 | G49: of TI
E50: [Effective P&L tax rate] | F50: 0.3 | G50: of PBT | J50: Presumption that over-life allowances for tax are equivalent to accounting expenses, so effective P&L tax rate should be equivalent to cash tax rate. Need to confirm with client and/or accounting advisor.
A52: EQUITY / RETURN ASSUMPTIONS
E54: Share capital investment requirement | F54: 1000 | G54: =SMU -> € 000s
E55: Shareholder discount rate | F55: 0.13 | G55: p.a. (365)
A59: MODEL CONTROL INPUTS
E61: Standard monetary unit | F61: € 000s | G61: Name
E62: Currency unit | F62: € | G62: Name

Sheet InpS
A1: =RIGHT(CELL("filename", A1), LEN(CELL("filename", A1)) - SEARCH("]", CELL("filename", A1))) -> InpS
E2: ='T&E'!E$24 -> Operating period flag | F2: ='T&E'!F$24 -> 0 | G2: ='T&E'!G$24 -> flag | H2: ='T&E'!H$24 -> 60 | I2: ='T&E'!I$24 -> 0 | J2: ='T&E'!J$24 -> 0 | K2: ='T&E'!K$24 -> 0 | L2: ='T&E'!L$24 -> 0 | ... CA2: ='T&E'!CA$24 -> 0
E3: ='T&E'!E$8 -> Model column counter | F3: ='T&E'!F$8 -> 0 | G3: ='T&E'!G$8 -> 0 | H3: ='T&E'!H$8 -> 0 | I3: ='T&E'!I$8 -> 0 | J3: ='T&E'!J$8 -> 1 | K3: ='T&E'!K$8 -> 2 | L3: ='T&E'!L$8 -> 3 | ... CA3: ='T&E'!CA$8 -> 70
E4: ='T&E'!E$12 -> Model period ending | F4: ='T&E'!F$12 -> constant | G4: ='T&E'!G$12 -> unit | H4: ='T&E'!H$12 -> total | I4: ='T&E'!I$12 -> 0 | J4: ='T&E'!J$12 -> 41639 | K4: ='T&E'!K$12 -> 41820 | L4: ='T&E'!L$12 -> 42004 | ... CA4: ='T&E'!CA$12 -> 54239
A6: ROUTE ASSUMPTIONS
E8: Routes - domestic charter | G8: planes | L8: 15 | M8: 15 | N8: 13 | O8: 13 | P8: 13 | Q8: 13 | R8: 11 | S8: 11 | T8: 11 | U8: 11 | V8: 9 | W8: 9 | X8: 9 | Y8: 9 | Z8: 9 | AA8: 9 | AB8: 9 | AC8: 9 | AD8: 9 | AE8: 9 | AF8: 9 | AG8: 9 | AH8: 9 | AI8: 9 | AJ8: 9 | AK8: 9 | AL8: 9 | AM8: 9 | AN8: 9 | AO8: 9 | AP8: 9 | AQ8: 9 | AR8: 9 | AS8: 9 | AT8: 9 | AU8: 9 | AV8: 9 | AW8: 9 | AX8: 9 | AY8: 9 | AZ8: 9 | BA8: 9 | BB8: 9 | BC8: 9 | BD8: 9 | BE8: 9 | BF8: 9 | BG8: 9 | BH8: 9 | BI8: 9 | BJ8: 9 | BK8: 9 | BL8: 9 | BM8: 9 | BN8: 9 | BO8: 9 | BP8: 9 | BQ8: 9 | BR8: 9 | BS8: 9 | BT8: 9 | BU8: 9 | BV8: 9
E9: Routes - domestic scheduled | G9: planes | L9: 28 | M9: 28 | N9: 24 | O9: 24 | P9: 24 | Q9: 24 | R9: 20 | S9: 20 | T9: 20 | U9: 20 | V9: 20 | W9: 20 | X9: 20 | Y9: 20 | Z9: 20 | AA9: 20 | AB9: 20 | AC9: 20 | AD9: 20 | AE9: 20 | AF9: 20 | AG9: 20 | AH9: 20 | AI9: 20 | AJ9: 20 | AK9: 20 | AL9: 20 | AM9: 20 | AN9: 20 | AO9: 20 | AP9: 20 | AQ9: 20 | AR9: 20 | AS9: 20 | AT9: 20 | AU9: 20 | AV9: 20 | AW9: 20 | AX9: 20 | AY9: 20 | AZ9: 20 | BA9: 20 | BB9: 20 | BC9: 20 | BD9: 20 | BE9: 20 | BF9: 20 | BG9: 20 | BH9: 20 | BI9: 20 | BJ9: 20 | BK9: 20 | BL9: 20 | BM9: 20 | BN9: 20 | BO9: 20 | BP9: 20 | BQ9: 20 | BR9: 20 | BS9: 20 | BT9: 20 | BU9: 20 | BV9: 20
E10: Routes - international charter | G10: planes | L10: 30 | M10: 30 | N10: 30 | O10: 30 | P10: 30 | Q10: 30 | R10: 30 | S10: 30 | T10: 30 | U10: 30 | V10: 30 | W10: 30 | X10: 30 | Y10: 30 | Z10: 30 | AA10: 30 | AB10: 30 | AC10: 30 | AD10: 30 | AE10: 30 | AF10: 30 | AG10: 30 | AH10: 30 | AI10: 30 | AJ10: 30 | AK10: 30 | AL10: 30 | AM10: 30 | AN10: 30 | AO10: 30 | AP10: 30 | AQ10: 30 | AR10: 30 | AS10: 30 | AT10: 30 | AU10: 30 | AV10: 30 | AW10: 30 | AX10: 30 | AY10: 30 | AZ10: 30 | BA10: 30 | BB10: 30 | BC10: 30 | BD10: 30 | BE10: 30 | BF10: 30 | BG10: 30 | BH10: 30 | BI10: 30 | BJ10: 30 | BK10: 30 | BL10: 30 | BM10: 30 | BN10: 30 | BO10: 30 | BP10: 30 | BQ10: 30 | BR10: 30 | BS10: 30 | BT10: 30 | BU10: 30 | BV10: 30
E11: Routes - international scheduled | G11: planes | L11: 12 | M11: 12 | N11: 14 | O11: 14 | P11: 16 | Q11: 16 | R11: 16 | S11: 16 | T11: 16 | U11: 16 | V11: 16 | W11: 16 | X11: 16 | Y11: 16 | Z11: 16 | AA11: 16 | AB11: 16 | AC11: 16 | AD11: 16 | AE11: 16 | AF11: 16 | AG11: 16 | AH11: 16 | AI11: 16 | AJ11: 16 | AK11: 16 | AL11: 16 | AM11: 16 | AN11: 16 | AO11: 16 | AP11: 16 | AQ11: 16 | AR11: 16 | AS11: 16 | AT11: 16 | AU11: 16 | AV11: 16 | AW11: 16 | AX11: 16 | AY11: 16 | AZ11: 16 | BA11: 16 | BB11: 16 | BC11: 16 | BD11: 16 | BE11: 16 | BF11: 16 | BG11: 16 | BH11: 16 | BI11: 16 | BJ11: 16 | BK11: 16 | BL11: 16 | BM11: 16 | BN11: 16 | BO11: 16 | BP11: 16 | BQ11: 16 | BR11: 16 | BS11: 16 | BT11: 16 | BU11: 16 | BV11: 16
E13: Landing frequency - domestic charter | G13: lands / plane | L13: 120 | M13: 120 | N13: 110 | O13: 110 | P13: 110 | Q13: 110 | R13: 100 | S13: 100 | T13: 100 | U13: 100 | V13: 90 | W13: 90 | X13: 90 | Y13: 90 | Z13: 80 | AA13: 80 | AB13: 80 | AC13: 80 | AD13: 80 | AE13: 80 | AF13: 80 | AG13: 80 | AH13: 80 | AI13: 80 | AJ13: 80 | AK13: 80 | AL13: 80 | AM13: 80 | AN13: 80 | AO13: 80 | AP13: 80 | AQ13: 80 | AR13: 80 | AS13: 80 | AT13: 80 | AU13: 80 | AV13: 80 | AW13: 80 | AX13: 80 | AY13: 80 | AZ13: 80 | BA13: 80 | BB13: 80 | BC13: 80 | BD13: 80 | BE13: 80 | BF13: 80 | BG13: 80 | BH13: 80 | BI13: 80 | BJ13: 80 | BK13: 80 | BL13: 80 | BM13: 80 | BN13: 80 | BO13: 80 | BP13: 80 | BQ13: 80 | BR13: 80 | BS13: 80 | BT13: 80 | BU13: 80 | BV13: 80
E14: Landing frequency - domestic scheduled | G14: lands / plane | L14: 250 | M14: 270 | N14: 250 | O14: 270 | P14: 250 | Q14: 270 | R14: 250 | S14: 270 | T14: 250 | U14: 270 | V14: 250 | W14: 270 | X14: 250 | Y14: 270 | Z14: 250 | AA14: 270 | AB14: 250 | AC14: 270 | AD14: 250 | AE14: 270 | AF14: 250 | AG14: 270 | AH14: 250 | AI14: 270 | AJ14: 250 | AK14: 270 | AL14: 250 | AM14: 270 | AN14: 250 | AO14: 270 | AP14: 250 | AQ14: 270 | AR14: 250 | AS14: 270 | AT14: 250 | AU14: 270 | AV14: 250 | AW14: 270 | AX14: 250 | AY14: 270 | AZ14: 250 | BA14: 270 | BB14: 250 | BC14: 270 | BD14: 250 | BE14: 270 | BF14: 250 | BG14: 270 | BH14: 250 | BI14: 250 | BJ14: 270 | BK14: 250 | BL14: 270 | BM14: 250 | BN14: 270 | BO14: 250 | BP14: 270 | BQ14: 250 | BR14: 250 | BS14: 270 | BT14: 270 | BU14: 270 | BV14: 270 | CB14: 270 | CC14: 168 | CD14: 84 | CE14: 168
E15: Landing frequency - international charter | G15: lands / plane | L15: 40 | M15: 40 | N15: 45 | O15: 45 | P15: 50 | Q15: 50 | R15: 55 | S15: 55 | T15: 60 | U15: 60 | V15: 65 | W15: 65 | X15: 70 | Y15: 70 | Z15: 70 | AA15: 70 | AB15: 70 | AC15: 70 | AD15: 70 | AE15: 70 | AF15: 70 | AG15: 70 | AH15: 70 | AI15: 70 | AJ15: 70 | AK15: 70 | AL15: 70 | AM15: 70 | AN15: 70 | AO15: 70 | AP15: 70 | AQ15: 70 | AR15: 70 | AS15: 70 | AT15: 70 | AU15: 70 | AV15: 70 | AW15: 70 | AX15: 70 | AY15: 70 | AZ15: 70 | BA15: 70 | BB15: 70 | BC15: 70 | BD15: 70 | BE15: 70 | BF15: 70 | BG15: 70 | BH15: 70 | BI15: 70 | BJ15: 70 | BK15: 70 | BL15: 70 | BM15: 70 | BN15: 70 | BO15: 70 | BP15: 70 | BQ15: 70 | BR15: 70 | BS15: 70 | BT15: 70 | BU15: 70 | BV15: 70
E16: Landing frequency - international scheduled | G16: lands / plane | L16: 35 | M16: 35 | N16: 45 | O16: 45 | P16: 45 | Q16: 45 | R16: 55 | S16: 55 | T16: 55 | U16: 55 | V16: 55 | W16: 55 | X16: 55 | Y16: 55 | Z16: 55 | AA16: 55 | AB16: 55 | AC16: 55 | AD16: 55 | AE16: 55 | AF16: 55 | AG16: 55 | AH16: 55 | AI16: 55 | AJ16: 55 | AK16: 55 | AL16: 55 | AM16: 55 | AN16: 55 | AO16: 55 | AP16: 55 | AQ16: 55 | AR16: 55 | AS16: 55 | AT16: 55 | AU16: 55 | AV16: 55 | AW16: 55 | AX16: 55 | AY16: 55 | AZ16: 55 | BA16: 55 | BB16: 55 | BC16: 55 | BD16: 55 | BE16: 55 | BF16: 55 | BG16: 55 | BH16: 55 | BI16: 55 | BJ16: 55 | BK16: 55 | BL16: 55 | BM16: 55 | BN16: 55 | BO16: 55 | BP16: 55 | BQ16: 55 | BR16: 55 | BS16: 55 | BT16: 55 | BU16: 55 | BV16: 55
E18: Load factor - domestic charter | G18: % | L18: 0.6 | M18: 0.6 | N18: 0.7 | O18: 0.7 | P18: 0.7 | Q18: 0.7 | R18: 0.7 | S18: 0.7 | T18: 0.7 | U18: 0.7 | V18: 0.7 | W18: 0.7 | X18: 0.7 | Y18: 0.7 | Z18: 0.7 | AA18: 0.7 | AB18: 0.7 | AC18: 0.7 | AD18: 0.79 | AE18: 0.79 | AF18: 0.79 | AG18: 0.79 | AH18: 0.79 | AI18: 0.79 | AJ18: 0.79 | AK18: 0.79 | AL18: 0.79 | AM18: 0.79 | AN18: 0.79 | AO18: 0.79 | AP18: 0.79 | AQ18: 0.79 | AR18: 0.79 | AS18: 0.79 | AT18: 0.79 | AU18: 0.79 | AV18: 0.79 | AW18: 0.79 | AX18: 0.7 | AY18: 0.7 | AZ18: 0.7 | BA18: 0.7 | BB18: 0.7 | BC18: 0.7 | BD18: 0.7 | BE18: 0.7 | BF18: 0.65 | BG18: 0.65 | BH18: 0.65 | BI18: 0.65 | BJ18: 0.6 | BK18: 0.6 | BL18: 0.6 | BM18: 0.6 | BN18: 0.6 | BO18: 0.6 | BP18: 0.6 | BQ18: 0.6 | BR18: 0.6 | BS18: 0.6 | BT18: 0.6 | BU18: 0.6 | BV18: 0.6
E19: Load factor - domestic scheduled | G19: % | L19: 0.7 | M19: 0.7 | N19: 0.7 | O19: 0.7 | P19: 0.7 | Q19: 0.7 | R19: 0.7 | S19: 0.7 | T19: 0.66 | U19: 0.66 | V19: 0.66 | W19: 0.66 | X19: 0.66 | Y19: 0.66 | Z19: 0.66 | AA19: 0.66 | AB19: 0.66 | AC19: 0.66 | AD19: 0.68 | AE19: 0.68 | AF19: 0.68 | AG19: 0.68 | AH19: 0.68 | AI19: 0.68 | AJ19: 0.68 | AK19: 0.68 | AL19: 0.68 | AM19: 0.68 | AN19: 0.7 | AO19: 0.7 | AP19: 0.7 | AQ19: 0.7 | AR19: 0.7 | AS19: 0.7 | AT19: 0.7 | AU19: 0.7 | AV19: 0.7 | AW19: 0.7 | AX19: 0.72 | AY19: 0.72 | AZ19: 0.72 | BA19: 0.72 | BB19: 0.72 | BC19: 0.72 | BD19: 0.72 | BE19: 0.72 | BF19: 0.72 | BG19: 0.72 | BH19: 0.72 | BI19: 0.72 | BJ19: 0.72 | BK19: 0.72 | BL19: 0.72 | BM19: 0.72 | BN19: 0.72 | BO19: 0.72 | BP19: 0.72 | BQ19: 0.72 | BR19: 0.72 | BS19: 0.72 | BT19: 0.72 | BU19: 0.72 | BV19: 0.72
E20: Load factor - international charter | G20: % | L20: 0.65 | M20: 0.6 | N20: 0.65 | O20: 0.6 | P20: 0.65 | Q20: 0.6 | R20: 0.65 | S20: 0.6 | T20: 0.65 | U20: 0.6 | V20: 0.65 | W20: 0.6 | X20: 0.65 | Y20: 0.6 | Z20: 0.65 | AA20: 0.6 | AB20: 0.65 | AC20: 0.6 | AD20: 0.65 | AE20: 0.6 | AF20: 0.65 | AG20: 0.6 | AH20: 0.65 | AI20: 0.6 | AJ20: 0.65 | AK20: 0.6 | AL20: 0.65 | AM20: 0.6 | AN20: 0.65 | AO20: 0.6 | AP20: 0.65 | AQ20: 0.6 | AR20: 0.65 | AS20: 0.6 | AT20: 0.65 | AU20: 0.6 | AV20: 0.65 | AW20: 0.6 | AX20: 0.65 | AY20: 0.6 | AZ20: 0.65 | BA20: 0.6 | BB20: 0.65 | BC20: 0.6 | BD20: 0.65 | BE20: 0.6 | BF20: 0.65 | BG20: 0.6 | BH20: 0.65 | BI20: 0.6 | BJ20: 0.65 | BK20: 0.6 | BL20: 0.65 | BM20: 0.6 | BN20: 0.65 | BO20: 0.6 | BP20: 0.65 | BQ20: 0.6 | BR20: 0.65 | BS20: 0.6 | BT20: 0.6 | BU20: 0.6 | BV20: 0.6 | CB20: 0.55 | CC20: 0.5 | CD20: 0.55 | CE20: 0.5 | CF20: 0.55 | CG20: 0.5 | CH20: 0.55 | CI20: 0.5 | CJ20: 0.55 | CK20: 0.5 | CL20: 0.55 | CM20: 0.5 | CN20: 0.55 | CO20: 0.5
E21: Load factor - international scheduled | G21: % | L21: 0.65 | M21: 0.65 | N21: 0.65 | O21: 0.65 | P21: 0.65 | Q21: 0.65 | R21: 0.65 | S21: 0.65 | T21: 0.65 | U21: 0.65 | V21: 0.65 | W21: 0.65 | X21: 0.65 | Y21: 0.65 | Z21: 0.65 | AA21: 0.65 | AB21: 0.65 | AC21: 0.65 | AD21: 0.65 | AE21: 0.65 | AF21: 0.65 | AG21: 0.65 | AH21: 0.65 | AI21: 0.65 | AJ21: 0.65 | AK21: 0.65 | AL21: 0.65 | AM21: 0.65 | AN21: 0.65 | AO21: 0.65 | AP21: 0.65 | AQ21: 0.65 | AR21: 0.65 | AS21: 0.65 | AT21: 0.65 | AU21: 0.65 | AV21: 0.65 | AW21: 0.65 | AX21: 0.7 | AY21: 0.7 | AZ21: 0.7 | BA21: 0.7 | BB21: 0.7 | BC21: 0.7 | BD21: 0.7 | BE21: 0.7 | BF21: 0.7 | BG21: 0.7 | BH21: 0.7 | BI21: 0.7 | BJ21: 0.7 | BK21: 0.7 | BL21: 0.7 | BM21: 0.7 | BN21: 0.7 | BO21: 0.7 | BP21: 0.7 | BQ21: 0.7 | BR21: 0.7 | BS21: 0.7 | BT21: 0.7 | BU21: 0.7 | BV21: 0.7
A24: DEBT REPAYMENT PROFILES
E26: ='T&E'!E$29 -> Senior debt term / ratio calc date flag | F26: ='T&E'!F$29 -> 0 | G26: ='T&E'!G$29 -> flag | H26: ='T&E'!H$29 -> 40 | I26: ='T&E'!I$29 -> 0 | J26: ='T&E'!J$29 -> 0 | K26: ='T&E'!K$29 -> 0 | L26: ='T&E'!L$29 -> 0 | ... CA26: ='T&E'!CA$29 -> 0
E28: =InpC!E$41 -> Senior principal repayment selection switch | F28: =InpC!F$41 -> 5 | G28: =InpC!G$41 -> switch
E29: Senior debt repayment - 20-year level | H29: =SUM(J29:CA29) -> 1 | O29: =1 / 40 -> 0.025 | P29: =1 / 40 -> 0.025 | Q29: =1 / 40 -> 0.025 | R29: =1 / 40 -> 0.025 | S29: =1 / 40 -> 0.025 | T29: =1 / 40 -> 0.025 | U29: =1 / 40 -> 0.025 | V29: =1 / 40 -> 0.025 | ... BB29: =1 / 40 -> 0.025
E30: Senior debt repayment - 2.0% / 3.0% | H30: =SUM(J30:CA30) -> 1 | O30: 0.02 | P30: 0.02 | Q30: 0.02 | R30: 0.02 | S30: 0.02 | T30: 0.02 | U30: 0.02 | V30: 0.02 | W30: 0.02 | X30: 0.02 | Y30: 0.02 | Z30: 0.02 | AA30: 0.02 | AB30: 0.02 | AC30: 0.02 | AD30: 0.02 | AE30: 0.02 | AF30: 0.02 | AG30: 0.02 | AH30: 0.02 | AI30: 0.03 | AJ30: 0.03 | AK30: 0.03 | AL30: 0.03 | AM30: 0.03 | AN30: 0.03 | AO30: 0.03 | AP30: 0.03 | AQ30: 0.03 | AR30: 0.03 | AS30: 0.03 | AT30: 0.03 | AU30: 0.03 | AV30: 0.03 | AW30: 0.03 | AX30: 0.03 | AY30: 0.03 | AZ30: 0.03 | BA30: 0.03 | BB30: 0.03
E31: Senior debt repayment - 20-year level w/ 3-year grace | H31: =SUM(J31:CA31) -> 1 | O31: 0 | P31: 0 | Q31: 0 | R31: 0 | S31: 0 | T31: 0 | U31: 0 | V31: 0 | W31: =1 / 32 -> 0.03125 | X31: =1 / 32 -> 0.03125 | Y31: =1 / 32 -> 0.03125 | Z31: =1 / 32 -> 0.03125 | AA31: =1 / 32 -> 0.03125 | AB31: =1 / 32 -> 0.03125 | AC31: =1 / 32 -> 0.03125 | AD31: =1 / 32 -> 0.03125 | ... BB31: =1 / 32 -> 0.03125
E32: 20 year - variable profile for ratio demo | H32: =SUM(J32:CA32) -> 1 | O32: 0.005 | P32: 0.005 | Q32: 0.04 | R32: 0.005 | T32: 0.035 | U32: 0.035 | V32: 0.035 | W32: 0.035 | X32: 0.025 | Y32: 0.025 | Z32: 0.025 | AA32: 0.025 | AD32: 0.015 | AE32: 0.015 | AF32: 0 | AG32: 0.025 | AH32: 0.025 | AI32: 0.06 | AJ32: 0.025 | AK32: 0.04 | AL32: 0.04 | AM32: 0.04 | AN32: 0.04 | AO32: 0.04 | AP32: 0.04 | AQ32: 0.025 | AR32: 0.025 | AS32: 0.025 | AT32: 0.025 | AU32: 0.025 | AV32: 0.025 | AW32: 0.025 | AX32: 0.025 | AY32: 0.025 | AZ32: 0.025 | BA32: 0.025 | BB32: 0.025
E33: 20-year sculpted senior debt repayment profile | H33: =SUM(J33:CA33) -> 1 | O33: 0.00941 | P33: 0.01009 | Q33: 0.0112 | R33: 0.00812 | S33: 0.00885 | T33: 0.00823 | U33: 0.00885 | V33: 0.0089 | W33: 0.00953 | X33: 0.01059 | Y33: 0.01305 | Z33: 0.01306 | AA33: 0.01386 | AB33: 0.01421 | AC33: 0.01511 | AD33: 0.01659 | AE33: 0.01769 | AF33: 0.01821 | AG33: 0.01942 | AH33: 0.02003 | AI33: 0.02282 | AJ33: 0.02353 | AK33: 0.02498 | AL33: 0.02579 | AM33: 0.02736 | AN33: 0.02907 | AO33: 0.03086 | AP33: 0.03187 | AQ33: 0.0338 | AR33: 0.03492 | AS33: 0.03699 | AT33: 0.03824 | AU33: 0.04047 | AV33: 0.04185 | AW33: 0.04424 | AX33: 0.04698 | AY33: 0.04967 | AZ33: 0.05133 | BA33: 0.0542 | BB33: 0.05603
E34: blank for insertion | J34: n/a | K34: n/a | L34: n/a | M34: n/a | N34: n/a | O34: n/a | P34: n/a | Q34: n/a | R34: n/a | S34: n/a | T34: n/a | U34: n/a | V34: n/a | W34: n/a | X34: n/a | Y34: n/a | Z34: n/a | AA34: n/a | AB34: n/a | AC34: n/a | AD34: n/a | AE34: n/a | AF34: n/a | AG34: n/a | AH34: n/a | AI34: n/a | AJ34: n/a | AK34: n/a | AL34: n/a | AM34: n/a | AN34: n/a | AO34: n/a | AP34: n/a | AQ34: n/a | AR34: n/a | AS34: n/a | AT34: n/a | AU34: n/a | AV34: n/a | AW34: n/a | AX34: n/a | AY34: n/a | AZ34: n/a | BA34: n/a | BB34: n/a | BC34: n/a | BD34: n/a | BE34: n/a | BF34: n/a | BG34: n/a | BH34: n/a | BI34: n/a | BJ34: n/a | BK34: n/a | BL34: n/a | BM34: n/a | BN34: n/a | BO34: n/a | BP34: n/a | BQ34: n/a | BR34: n/a | BS34: n/a | BT34: n/a | BU34: n/a | BV34: n/a | BW34: n/a | BX34: n/a | BY34: n/a | BZ34: n/a | CA34: n/a
E35: Senior debt repayment profile - saved selection | H35: =SUM(J35:CA35) -> 1 | J35: =INDEX(J29:J34, $F28) -> 0 | K35: =INDEX(K29:K34, $F28) -> 0 | L35: =INDEX(L29:L34, $F28) -> 0 | M35: =INDEX(M29:M34, $F28) -> 0 | N35: =INDEX(N29:N34, $F28) -> 0 | O35: =INDEX(O29:O34, $F28) -> 0.00941 | P35: =INDEX(P29:P34, $F28) -> 0.01009 | Q35: =INDEX(Q29:Q34, $F28) -> 0.0112 | ... CA35: =INDEX(CA29:CA34, $F28) -> 0
E37: =SrDebt!E$52 -> Sculpted repayment profile COPY TARGET | F37: =SrDebt!F$52 -> 0 | G37: =SrDebt!G$52 -> 0 | H37: =SrDebt!H$52 -> 1 | I37: =SrDebt!I$52 -> 0 | J37: =SrDebt!J$52 -> 0 | K37: =SrDebt!K$52 -> 0 | L37: =SrDebt!L$52 -> 0 | ... CA37: =SrDebt!CA$52 -> 0

Sheet ConTime
A1: =RIGHT(CELL("filename", A1), LEN(CELL("filename", A1)) - SEARCH("]", CELL("filename", A1))) -> ConTime
E2: =E$18 -> Construction / availability period flag | F2: =F$18 -> 0 | G2: =G$18 -> 0 | H2: =H$18 -> 22 | I2: =I$18 -> 0 | J2: =J$18 -> 0 | K2: =K$18 -> 1 | L2: =L$18 -> 1 | ... AZ2: =AZ$18 -> 0
E3: =E$8 -> Construction period counter | F3: =F$8 -> 0 | G3: =G$8 -> 0 | H3: =H$8 -> 0 | I3: =I$8 -> 0 | J3: =J$8 -> 1 | K3: =K$8 -> 2 | L3: =L$8 -> 3 | ... AZ3: =AZ$8 -> 43
E4: =E$13 -> Construction period month ending | F4: =F$13 -> 0 | G4: =G$13 -> 0 | H4: =H$13 -> 0 | I4: =I$13 -> 0 | J4: =J$13 -> 41698 | K4: =K$13 -> 41729 | L4: =L$13 -> 41759 | ... AZ4: =AZ$13 -> 42978
A6: BASIC TIMING COMPONENTS
E8: Construction period counter | J8: =I8 + 1 -> 1 | K8: =J8 + 1 -> 2 | L8: =K8 + 1 -> 3 | M8: =L8 + 1 -> 4 | N8: =M8 + 1 -> 5 | O8: =N8 + 1 -> 6 | P8: =O8 + 1 -> 7 | Q8: =P8 + 1 -> 8 | ... AZ8: =AY8 + 1 -> 43
E9: Construction period month no. | J9: =J8 - 1 -> 0 | K9: =K8 - 1 -> 1 | L9: =L8 - 1 -> 2 | M9: =M8 - 1 -> 3 | N9: =N8 - 1 -> 4 | O9: =O8 - 1 -> 5 | P9: =P8 - 1 -> 6 | Q9: =Q8 - 1 -> 7 | ... AZ9: =AZ8 - 1 -> 42
E11: =InpC!E$10 -> Financial close date | F11: =InpC!F$10 -> 41698 | G11: =InpC!G$10 -> EOM
E12: =E$9 -> Construction period month no. | F12: =F$9 -> 0 | G12: =G$9 -> 0 | H12: =H$9 -> 0 | I12: =I$9 -> 0 | J12: =J$9 -> 0 | K12: =K$9 -> 1 | L12: =L$9 -> 2 | ... AZ12: =AZ$9 -> 42
E13: Construction period month ending | J13: =IF( J12 = 0, $F11, EOMONTH(I13, 1)) -> 41698 | K13: =IF( K12 = 0, $F11, EOMONTH(J13, 1)) -> 41729 | L13: =IF( L12 = 0, $F11, EOMONTH(K13, 1)) -> 41759 | M13: =IF( M12 = 0, $F11, EOMONTH(L13, 1)) -> 41790 | N13: =IF( N12 = 0, $F11, EOMONTH(M13, 1)) -> 41820 | O13: =IF( O12 = 0, $F11, EOMONTH(N13, 1)) -> 41851 | P13: =IF( P12 = 0, $F11, EOMONTH(O13, 1)) -> 41882 | Q13: =IF( Q12 = 0, $F11, EOMONTH(P13, 1)) -> 41912 | ... AZ13: =IF( AZ12 = 0, $F11, EOMONTH(AY13, 1)) -> 42978
E15: =InpC!E$10 -> Financial close date | F15: =InpC!F$10 -> 41698 | G15: =InpC!G$10 -> EOM
E16: =InpC!E$12 -> Construction period end / conversion date | F16: =InpC!F$12 -> 42369 | G16: =InpC!G$12 -> date
E17: =E$13 -> Construction period month ending | F17: =F$13 -> 0 | G17: =G$13 -> 0 | H17: =H$13 -> 0 | I17: =I$13 -> 0 | J17: =J$13 -> 41698 | K17: =K$13 -> 41729 | L17: =L$13 -> 41759 | ... AZ17: =AZ$13 -> 42978
E18: Construction / availability period flag | H18: =SUM(J18:AZ18) -> 22 | J18: =IF( AND(J17 > $F15, J17 <= $F16), 1, 0) -> 0 | K18: =IF( AND(K17 > $F15, K17 <= $F16), 1, 0) -> 1 | L18: =IF( AND(L17 > $F15, L17 <= $F16), 1, 0) -> 1 | M18: =IF( AND(M17 > $F15, M17 <= $F16), 1, 0) -> 1 | N18: =IF( AND(N17 > $F15, N17 <= $F16), 1, 0) -> 1 | O18: =IF( AND(O17 > $F15, O17 <= $F16), 1, 0) -> 1 | P18: =IF( AND(P17 > $F15, P17 <= $F16), 1, 0) -> 1 | Q18: =IF( AND(Q17 > $F15, Q17 <= $F16), 1, 0) -> 1 | ... AZ18: =IF( AND(AZ17 > $F15, AZ17 <= $F16), 1, 0) -> 0
E20: =InpC!E$10 -> Financial close date | F20: =InpC!F$10 -> 41698 | G20: =InpC!G$10 -> EOM
E21: =E$13 -> Construction period month ending | F21: =F$13 -> 0 | G21: =G$13 -> 0 | H21: =H$13 -> 0 | I21: =I$13 -> 0 | J21: =J$13 -> 41698 | K21: =K$13 -> 41729 | L21: =L$13 -> 41759 | ... AZ21: =AZ$13 -> 42978
E22: Financial close date flag | H22: =SUM(J22:AZ22) -> 1 | J22: =IF(J21 = $F20, 1, 0) -> 1 | K22: =IF(K21 = $F20, 1, 0) -> 0 | L22: =IF(L21 = $F20, 1, 0) -> 0 | M22: =IF(M21 = $F20, 1, 0) -> 0 | N22: =IF(N21 = $F20, 1, 0) -> 0 | O22: =IF(O21 = $F20, 1, 0) -> 0 | P22: =IF(P21 = $F20, 1, 0) -> 0 | Q22: =IF(Q21 = $F20, 1, 0) -> 0 | ... AZ22: =IF(AZ21 = $F20, 1, 0) -> 0
E24: =InpC!E$12 -> Construction period end / conversion date | F24: =InpC!F$12 -> 42369 | G24: =InpC!G$12 -> date
E25: =E$13 -> Construction period month ending | F25: =F$13 -> 0 | G25: =G$13 -> 0 | H25: =H$13 -> 0 | I25: =I$13 -> 0 | J25: =J$13 -> 41698 | K25: =K$13 -> 41729 | L25: =L$13 -> 41759 | ... AZ25: =AZ$13 -> 42978
E26: Construction period end / conversion date flag | H26: =SUM(J26:AZ26) -> 1 | J26: =IF(J25 = $F24, 1, 0) -> 0 | K26: =IF(K25 = $F24, 1, 0) -> 0 | L26: =IF(L25 = $F24, 1, 0) -> 0 | M26: =IF(M25 = $F24, 1, 0) -> 0 | N26: =IF(N25 = $F24, 1, 0) -> 0 | O26: =IF(O25 = $F24, 1, 0) -> 0 | P26: =IF(P25 = $F24, 1, 0) -> 0 | Q26: =IF(Q25 = $F24, 1, 0) -> 0 | ... AZ26: =IF(AZ25 = $F24, 1, 0) -> 0
E28: =InpC!E$11 -> Length of construction period | F28: =InpC!F$11 -> 22 | G28: =InpC!G$11 -> months
E29: =E$18 -> Construction / availability period flag | F29: =F$18 -> 0 | G29: =G$18 -> 0 | H29: =H$18 -> 22 | I29: =I$18 -> 0 | J29: =J$18 -> 0 | K29: =K$18 -> 1 | L29: =L$18 -> 1 | ... AZ29: =AZ$18 -> 0
E30: Level construction period payment schedule | H30: =SUM(J30:AZ30) -> 1 | J30: =J29 / $F28 -> 0 | K30: =K29 / $F28 -> 0.045454545 | L30: =L29 / $F28 -> 0.045454545 | M30: =M29 / $F28 -> 0.045454545 | N30: =N29 / $F28 -> 0.045454545 | O30: =O29 / $F28 -> 0.045454545 | P30: =P29 / $F28 -> 0.045454545 | Q30: =Q29 / $F28 -> 0.045454545 | ... AZ30: =AZ29 / $F28 -> 0

Sheet ConCost
A1: =RIGHT(CELL("filename", A1), LEN(CELL("filename", A1)) - SEARCH("]", CELL("filename", A1))) -> ConCost
E2: =ConTime!E$18 -> Construction / availability period flag | F2: =ConTime!F$18 -> 0 | G2: =ConTime!G$18 -> 0 | H2: =ConTime!H$18 -> 22 | I2: =ConTime!I$18 -> 0 | J2: =ConTime!J$18 -> 0 | K2: =ConTime!K$18 -> 1 | L2: =ConTime!L$18 -> 1 | ... AZ2: =ConTime!AZ$18 -> 0
E3: =ConTime!E$8 -> Construction period counter | F3: =ConTime!F$8 -> 0 | G3: =ConTime!G$8 -> 0 | H3: =ConTime!H$8 -> 0 | I3: =ConTime!I$8 -> 0 | J3: =ConTime!J$8 -> 1 | K3: =ConTime!K$8 -> 2 | L3: =ConTime!L$8 -> 3 | ... AZ3: =ConTime!AZ$8 -> 43
E4: =ConTime!E$13 -> Construction period month ending | F4: =ConTime!F$13 -> 0 | G4: =ConTime!G$13 -> 0 | H4: =ConTime!H$13 -> 0 | I4: =ConTime!I$13 -> 0 | J4: =ConTime!J$13 -> 41698 | K4: =ConTime!K$13 -> 41729 | L4: =ConTime!L$13 -> 41759 | ... AZ4: =ConTime!AZ$13 -> 42978
A6: CONSTRUCTION COSTS
B8: Base construction costs
E10: EPC contract price | F10: 310000 | G10: =SMU -> € 000s
E11: EPC milestone payment schedule | H11: =SUM(J11:AZ11) -> 1 | J11: 0.15 | K11: 0.03 | L11: 0.03 | M11: 0.03 | N11: 0.03 | O11: 0.03 | P11: 0.03 | Q11: 0.03 | R11: 0.03 | S11: 0.03 | T11: 0.03 | U11: 0.03 | V11: 0.03 | W11: 0.03 | X11: 0.03 | Y11: 0.03 | Z11: 0.03 | AA11: 0.03 | AB11: 0.03 | AC11: 0.03 | AD11: 0.03 | AE11: 0.03 | AF11: =3% + 19% -> 0.22
E12: EPC contract costs | G12: =SMU -> € 000s | H12: =SUM(J12:AZ12) -> 310000 | J12: =$F10 * J11 -> 46500 | K12: =$F10 * K11 -> 9300 | L12: =$F10 * L11 -> 9300 | M12: =$F10 * M11 -> 9300 | N12: =$F10 * N11 -> 9300 | O12: =$F10 * O11 -> 9300 | P12: =$F10 * P11 -> 9300 | Q12: =$F10 * Q11 -> 9300 | ... AZ12: =$F10 * AZ11 -> 0
E14: Development cost reimbursement | F14: 12000 | G14: =SMU -> € 000s
E15: =ConTime!E$22 -> Financial close date flag | F15: =ConTime!F$22 -> 0 | G15: =ConTime!G$22 -> 0 | H15: =ConTime!H$22 -> 1 | I15: =ConTime!I$22 -> 0 | J15: =ConTime!J$22 -> 1 | K15: =ConTime!K$22 -> 0 | L15: =ConTime!L$22 -> 0 | ... AZ15: =ConTime!AZ$22 -> 0
E16: Development cost | G16: =SMU -> € 000s | H16: =SUM(J16:AZ16) -> 12000 | J16: =$F14 * J15 -> 12000 | K16: =$F14 * K15 -> 0 | L16: =$F14 * L15 -> 0 | M16: =$F14 * M15 -> 0 | N16: =$F14 * N15 -> 0 | O16: =$F14 * O15 -> 0 | P16: =$F14 * P15 -> 0 | Q16: =$F14 * Q15 -> 0 | ... AZ16: =$F14 * AZ15 -> 0
E18: O&M mobilization costs input | F18: 8000 | G18: =SMU -> € 000s
E19: =ConTime!E$26 -> Construction period end / conversion date flag | F19: =ConTime!F$26 -> 0 | G19: =ConTime!G$26 -> 0 | H19: =ConTime!H$26 -> 1 | I19: =ConTime!I$26 -> 0 | J19: =ConTime!J$26 -> 0 | K19: =ConTime!K$26 -> 0 | L19: =ConTime!L$26 -> 0 | ... AZ19: =ConTime!AZ$26 -> 0
E20: O&M mobilization costs | G20: =SMU -> € 000s | H20: =SUM(J20:AZ20) -> 8000 | J20: =$F18 * J19 -> 0 | K20: =$F18 * K19 -> 0 | L20: =$F18 * L19 -> 0 | M20: =$F18 * M19 -> 0 | N20: =$F18 * N19 -> 0 | O20: =$F18 * O19 -> 0 | P20: =$F18 * P19 -> 0 | Q20: =$F18 * Q19 -> 0 | ... AZ20: =$F18 * AZ19 -> 0
E22: Owners G&A costs DC input | F22: 5000 | G22: =SMU -> € 000s
E23: =ConTime!E$30 -> Level construction period payment schedule | F23: =ConTime!F$30 -> 0 | G23: =ConTime!G$30 -> 0 | H23: =ConTime!H$30 -> 1 | I23: =ConTime!I$30 -> 0 | J23: =ConTime!J$30 -> 0 | K23: =ConTime!K$30 -> 0.045454545 | L23: =ConTime!L$30 -> 0.045454545 | ... AZ23: =ConTime!AZ$30 -> 0
E24: Owners G&A costs DC | G24: =SMU -> € 000s | H24: =SUM(J24:AZ24) -> 5000 | J24: =$F22 * J23 -> 0 | K24: =$F22 * K23 -> 227.27273 | L24: =$F22 * L23 -> 227.27273 | M24: =$F22 * M23 -> 227.27273 | N24: =$F22 * N23 -> 227.27273 | O24: =$F22 * O23 -> 227.27273 | P24: =$F22 * P23 -> 227.27273 | Q24: =$F22 * Q23 -> 227.27273 | ... AZ24: =$F22 * AZ23 -> 0
E26: =E$12 -> EPC contract costs | F26: =F$12 -> 0 | G26: =G$12 -> € 000s | H26: =H$12 -> 310000 | I26: =I$12 -> 0 | J26: =J$12 -> 46500 | K26: =K$12 -> 9300 | L26: =L$12 -> 9300 | ... AZ26: =AZ$12 -> 0
E27: =E$16 -> Development cost | F27: =F$16 -> 0 | G27: =G$16 -> € 000s | H27: =H$16 -> 12000 | I27: =I$16 -> 0 | J27: =J$16 -> 12000 | K27: =K$16 -> 0 | L27: =L$16 -> 0 | ... AZ27: =AZ$16 -> 0
E28: =E$20 -> O&M mobilization costs | F28: =F$20 -> 0 | G28: =G$20 -> € 000s | H28: =H$20 -> 8000 | I28: =I$20 -> 0 | J28: =J$20 -> 0 | K28: =K$20 -> 0 | L28: =L$20 -> 0 | ... AZ28: =AZ$20 -> 0
E29: =E$24 -> Owners G&A costs DC | F29: =F$24 -> 0 | G29: =G$24 -> € 000s | H29: =H$24 -> 5000 | I29: =I$24 -> 0 | J29: =J$24 -> 0 | K29: =K$24 -> 227.27273 | L29: =L$24 -> 227.27273 | ... AZ29: =AZ$24 -> 0
E30: Base construction costs | G30: =SMU -> € 000s | H30: =SUM(J30:AZ30) -> 335000 | J30: =SUM(J26:J29) -> 58500 | K30: =SUM(K26:K29) -> 9527.2727 | L30: =SUM(L26:L29) -> 9527.2727 | M30: =SUM(M26:M29) -> 9527.2727 | N30: =SUM(N26:N29) -> 9527.2727 | O30: =SUM(O26:O29) -> 9527.2727 | P30: =SUM(P26:P29) -> 9527.2727 | Q30: =SUM(Q26:Q29) -> 9527.2727 | ... AZ30: =SUM(AZ26:AZ29) -> 0
B33: Construction cost contingency
E35: Construction cost contingency | F35: 0.1 | G35: of BCC
E36: =E$30 -> Base construction costs | F36: =F$30 -> 0 | G36: =G$30 -> € 000s | H36: =H$30 -> 335000 | I36: =I$30 -> 0 | J36: =J$30 -> 58500 | K36: =K$30 -> 9527.2727 | L36: =L$30 -> 9527.2727 | ... AZ36: =AZ$30 -> 0
E37: Construction cost contingency | H37: =SUM(J37:AZ37) -> 33500 | J37: =$F35 * J36 -> 5850 | K37: =$F35 * K36 -> 952.72727 | L37: =$F35 * L36 -> 952.72727 | M37: =$F35 * M36 -> 952.72727 | N37: =$F35 * N36 -> 952.72727 | O37: =$F35 * O36 -> 952.72727 | P37: =$F35 * P36 -> 952.72727 | Q37: =$F35 * Q36 -> 952.72727 | ... AZ37: =$F35 * AZ36 -> 0
E39: =E$30 -> Base construction costs | F39: =F$30 -> 0 | G39: =G$30 -> € 000s | H39: =H$30 -> 335000 | I39: =I$30 -> 0 | J39: =J$30 -> 58500 | K39: =K$30 -> 9527.2727 | L39: =L$30 -> 9527.2727 | ... AZ39: =AZ$30 -> 0
E40: =E$37 -> Construction cost contingency | F40: =F$37 -> 0 | G40: =G$37 -> 0 | H40: =H$37 -> 33500 | I40: =I$37 -> 0 | J40: =J$37 -> 5850 | K40: =K$37 -> 952.72727 | L40: =L$37 -> 952.72727 | ... AZ40: =AZ$37 -> 0
E41: Construction costs | G41: =SMU -> € 000s | H41: =SUM(J41:AZ41) -> 368500 | J41: =SUM(J39:J40) -> 64350 | K41: =SUM(K39:K40) -> 10480 | L41: =SUM(L39:L40) -> 10480 | M41: =SUM(M39:M40) -> 10480 | N41: =SUM(N39:N40) -> 10480 | O41: =SUM(O39:O40) -> 10480 | P41: =SUM(P39:P40) -> 10480 | Q41: =SUM(Q39:Q40) -> 10480 | ... AZ41: =SUM(AZ39:AZ40) -> 0
E43: =E$41 -> Construction costs | F43: =F$41 -> 0 | G43: =G$41 -> € 000s | H43: =H$41 -> 368500 | I43: =I$41 -> 0 | J43: =J$41 -> 64350 | K43: =K$41 -> 10480 | L43: =L$41 -> 10480 | ... AZ43: =AZ$41 -> 0
E44: =E43 & " NEG (for XIRR)" -> Construction costs NEG (for XIRR) | G44: =G43 -> € 000s | H44: =SUM(J44:AZ44) -> -368500 | J44: =-1 * J43 -> -64350 | K44: =-1 * K43 -> -10480 | L44: =-1 * L43 -> -10480 | M44: =-1 * M43 -> -10480 | N44: =-1 * N43 -> -10480 | O44: =-1 * O43 -> -10480 | P44: =-1 * P43 -> -10480 | Q44: =-1 * Q43 -> -10480 | ... AZ44: =-1 * AZ43 -> 0

Sheet ConFin
A1: =RIGHT(CELL("filename", A1), LEN(CELL("filename", A1)) - SEARCH("]", CELL("filename", A1))) -> ConFin
E2: =ConTime!E$18 -> Construction / availability period flag | F2: =ConTime!F$18 -> 0 | G2: =ConTime!G$18 -> 0 | H2: =ConTime!H$18 -> 22 | I2: =ConTime!I$18 -> 0 | J2: =ConTime!J$18 -> 0 | K2: =ConTime!K$18 -> 1 | L2: =ConTime!L$18 -> 1 | ... AZ2: =ConTime!AZ$18 -> 0
E3: =ConTime!E$8 -> Construction period counter | F3: =ConTime!F$8 -> 0 | G3: =ConTime!G$8 -> 0 | H3: =ConTime!H$8 -> 0 | I3: =ConTime!I$8 -> 0 | J3: =ConTime!J$8 -> 1 | K3: =ConTime!K$8 -> 2 | L3: =ConTime!L$8 -> 3 | ... AZ3: =ConTime!AZ$8 -> 43
E4: =ConTime!E$13 -> Construction period month ending | F4: =ConTime!F$13 -> 0 | G4: =ConTime!G$13 -> 0 | H4: =ConTime!H$13 -> 0 | I4: =ConTime!I$13 -> 0 | J4: =ConTime!J$13 -> 41698 | K4: =ConTime!K$13 -> 41729 | L4: =ConTime!L$13 -> 41759 | ... AZ4: =ConTime!AZ$13 -> 42978
A6: FINANCE COSTS DC
E8: Arrangement fee rate | F8: 0.02 | G8: of comm
E9: Commitment amount | F9: 390000 | G9: =SMU -> € 000s
E10: =ConTime!E$22 -> Financial close date flag | F10: =ConTime!F$22 -> 0 | G10: =ConTime!G$22 -> 0 | H10: =ConTime!H$22 -> 1 | I10: =ConTime!I$22 -> 0 | J10: =ConTime!J$22 -> 1 | K10: =ConTime!K$22 -> 0 | L10: =ConTime!L$22 -> 0 | ... AZ10: =ConTime!AZ$22 -> 0
E11: Arrangement fees | H11: =SUM(J11:AZ11) -> 7800 | J11: =$F8 * $F9 * J10 -> 7800 | K11: =$F8 * $F9 * K10 -> 0 | L11: =$F8 * $F9 * L10 -> 0 | M11: =$F8 * $F9 * M10 -> 0 | N11: =$F8 * $F9 * N10 -> 0 | O11: =$F8 * $F9 * O10 -> 0 | P11: =$F8 * $F9 * P10 -> 0 | Q11: =$F8 * $F9 * Q10 -> 0 | ... AZ11: =$F8 * $F9 * AZ10 -> 0
E13: Agent bank fee monthly rate | F13: 30 | G13: =SMU & " pcm" -> € 000s pcm
E14: =ConTime!E$18 -> Construction / availability period flag | F14: =ConTime!F$18 -> 0 | G14: =ConTime!G$18 -> 0 | H14: =ConTime!H$18 -> 22 | I14: =ConTime!I$18 -> 0 | J14: =ConTime!J$18 -> 0 | K14: =ConTime!K$18 -> 1 | L14: =ConTime!L$18 -> 1 | ... AZ14: =ConTime!AZ$18 -> 0
E15: [Indexation factor DC] | J15: 1 | K15: 1 | L15: 1 | M15: 1 | N15: 1 | O15: 1 | P15: 1 | Q15: 1 | R15: 1 | S15: 1 | T15: 1 | U15: 1 | V15: 1 | W15: 1 | X15: 1 | Y15: 1 | Z15: 1 | AA15: 1 | AB15: 1 | AC15: 1 | AD15: 1 | AE15: 1 | AF15: 1 | AG15: 1 | AH15: 1 | AI15: 1 | AJ15: 1 | AK15: 1 | AL15: 1 | AM15: 1 | AN15: 1 | AO15: 1 | AP15: 1 | AQ15: 1 | AR15: 1 | AS15: 1 | AT15: 1 | AU15: 1 | AV15: 1 | AW15: 1 | AX15: 1 | AY15: 1 | AZ15: 1
E16: Agent bank fees DC | H16: =SUM(J16:AZ16) -> 660 | J16: =$F13 * J14 * J15 -> 0 | K16: =$F13 * K14 * K15 -> 30 | L16: =$F13 * L14 * L15 -> 30 | M16: =$F13 * M14 * M15 -> 30 | N16: =$F13 * N14 * N15 -> 30 | O16: =$F13 * O14 * O15 -> 30 | P16: =$F13 * P14 * P15 -> 30 | Q16: =$F13 * Q14 * Q15 -> 30 | ... AZ16: =$F13 * AZ14 * AZ15 -> 0
B19: Interest during construction (IDC)
E21: LIBOR + MLA debt base rate | F21: 0.03 | G21: p.a. (360-day)
E22: Construction debt margin | F22: 0.0275 | G22: p.a. (360-day)
E23: [Swap counter-party risk premium] | G23: few basis point
E24: [Contingency for interest rate movements] | G24: 50 bps?
E25: Nominal annual interest rate DC | F25: =SUM(F21:F24) -> 0.0575 | G25: p.a. (360-day)
E27: Days in LIBOR year | F27: 360 | G27: days
E28: Construction debt daily interest rate | F28: =F25 / F27 -> 0.00015972222 | G28: per day
E30: =ConTime!E$13 -> Construction period month ending | F30: =ConTime!F$13 -> 0 | G30: =ConTime!G$13 -> 0 | H30: =ConTime!H$13 -> 0 | I30: =ConTime!I$13 -> 0 | J30: =ConTime!J$13 -> 41698 | K30: =ConTime!K$13 -> 41729 | L30: =ConTime!L$13 -> 41759 | ... AZ30: =ConTime!AZ$13 -> 42978
E31: =ConTime!E$18 -> Construction / availability period flag | F31: =ConTime!F$18 -> 0 | G31: =ConTime!G$18 -> 0 | H31: =ConTime!H$18 -> 22 | I31: =ConTime!I$18 -> 0 | J31: =ConTime!J$18 -> 0 | K31: =ConTime!K$18 -> 1 | L31: =ConTime!L$18 -> 1 | ... AZ31: =ConTime!AZ$18 -> 0
E32: Number of days in period DC | J32: =(J30 - I30) * J31 -> 0 | K32: =(K30 - J30) * K31 -> 31 | L32: =(L30 - K30) * L31 -> 30 | M32: =(M30 - L30) * M31 -> 31 | N32: =(N30 - M30) * N31 -> 30 | O32: =(O30 - N30) * O31 -> 31 | P32: =(P30 - O30) * P31 -> 31 | Q32: =(Q30 - P30) * Q31 -> 30 | ... AZ32: =(AZ30 - AY30) * AZ31 -> 0
E34: =E$28 -> Construction debt daily interest rate | F34: =F$28 -> 0.00015972222 | G34: =G$28 -> per day
E35: =E$86 -> Construction debt balance BEG | F35: =F$86 -> 0 | G35: =G$86 -> 0 | H35: =H$86 -> 0 | I35: =I$86 -> 0 | J35: =J$86 -> 0 | K35: =K$86 -> 57720 | L35: =L$86 -> 66467.395 | ... AZ35: =AZ$86 -> 0
E36: =E$32 -> Number of days in period DC | F36: =F$32 -> 0 | G36: =G$32 -> 0 | H36: =H$32 -> 0 | I36: =I$32 -> 0 | J36: =J$32 -> 0 | K36: =K$32 -> 31 | L36: =L$32 -> 30 | ... AZ36: =AZ$32 -> 0
E37: Interest during construction | H37: =SUM(J37:AZ37) -> 16260.924 | J37: =$F34 * J35 * J36 -> 0 | K37: =$F34 * K35 * K36 -> 285.79417 | L37: =$F34 * L35 * L36 -> 318.4896 | M37: =$F34 * M35 * M36 -> 372.53275 | N37: =$F34 * N35 * N36 -> 402.73469 | O37: =$F34 * O35 * O36 -> 459.89069 | P37: =$F34 * P35 * P36 -> 503.83403 | Q37: =$F34 * Q35 * Q36 -> 530.26141 | ... AZ37: =$F34 * AZ35 * AZ36 -> 0
E39: Interest during construction PASTE before FC hook-up | H39: 15645.761 | J39: 0 | K39: 285.79417 | L39: 316.86333 | M39: 369.05672 | N39: 397.44 | O39: 452.31928 | P39: 493.95056 | Q39: 518.305 | R39: 577.21311 | S39: 598.88167 | T39: 660.47567 | U39: 702.10694 | V39: 671.76356 | W39: 785.3695 | X39: 800.32333 | Y39: 868.63206 | Z39: 880.9 | AA39: 951.89461 | AB39: 993.52589 | AC39: 1001.765 | AD39: 1076.7884 | AE39: 1082.3417 | AF39: 1160.051 | AG39: 0 | AH39: 0 | AI39: 0 | AJ39: 0 | AK39: 0 | AL39: 0 | AM39: 0 | AN39: 0 | AO39: 0 | AP39: 0 | AQ39: 0 | AR39: 0 | AS39: 0 | AT39: 0 | AU39: 0 | AV39: 0 | AW39: 0 | AX39: 0 | AY39: 0 | AZ39: 0
E40: Difference | H40: =SUM(J40:AZ40) -> 615.16233 | J40: =J37 - J39 -> 0 | K40: =K37 - K39 -> 0 | L40: =L37 - L39 -> 1.6262693 | M40: =M37 - M39 -> 3.4760296 | N40: =N37 - N39 -> 5.2946866 | O40: =O37 - O39 -> 7.5714138 | P40: =P37 - P39 -> 9.8834756 | Q40: =Q37 - Q39 -> 11.956407 | ... AZ40: =AZ37 - AZ39 -> 0
B43: Commitement fees
E45: Commitment amount | F45: 390000 | G45: =SMU -> € 000s
E46: =E$86 -> Construction debt balance BEG | F46: =F$86 -> 0 | G46: =G$86 -> 0 | H46: =H$86 -> 0 | I46: =I$86 -> 0 | J46: =J$86 -> 0 | K46: =K$86 -> 57720 | L46: =L$86 -> 66467.395 | ... AZ46: =AZ$86 -> 0
E47: Undrawn construction debt commitment balance | J47: =$F45 - J46 -> 390000 | K47: =$F45 - K46 -> 332280 | L47: =$F45 - L46 -> 323532.6 | M47: =$F45 - M46 -> 314761.97 | N47: =$F45 - N46 -> 305951.02 | O47: =$F45 - O46 -> 297118.85 | P47: =$F45 - P46 -> 288243.9 | Q47: =$F45 - Q46 -> 279336.75 | ... AZ47: =$F45 - AZ46 -> 390000
E49: Commitment fee rate | F49: 0.005 | G49: p.a.
E50: =E$47 -> Undrawn construction debt commitment balance | F50: =F$47 -> 0 | G50: =G$47 -> 0 | H50: =H$47 -> 0 | I50: =I$47 -> 0 | J50: =J$47 -> 390000 | K50: =K$47 -> 332280 | L50: =L$47 -> 323532.6 | ... AZ50: =AZ$47 -> 390000
E51: =ConTime!E$18 -> Construction / availability period flag | F51: =ConTime!F$18 -> 0 | G51: =ConTime!G$18 -> 0 | H51: =ConTime!H$18 -> 22 | I51: =ConTime!I$18 -> 0 | J51: =ConTime!J$18 -> 0 | K51: =ConTime!K$18 -> 1 | L51: =ConTime!L$18 -> 1 | ... AZ51: =ConTime!AZ$18 -> 0
E52: Commitment fees | H52: =SUM(J52:AZ52) -> 2184.0209 | J52: =($F49 / 12) * J50 * J51 -> 0 | K52: =($F49 / 12) * K50 * K51 -> 138.45 | L52: =($F49 / 12) * L50 * L51 -> 134.80525 | M52: =($F49 / 12) * M50 * M51 -> 131.15082 | N52: =($F49 / 12) * N50 * N51 -> 127.47959 | O52: =($F49 / 12) * O50 * O51 -> 123.79952 | P52: =($F49 / 12) * P50 * P51 -> 120.10162 | Q52: =($F49 / 12) * Q50 * Q51 -> 116.39031 | ... AZ52: =($F49 / 12) * AZ50 * AZ51 -> 0
E54: Senior DSRA - Initial balance | F54: 8000 | G54: =SMU -> € 000s
E55: =ConTime!E$26 -> Construction period end / conversion date flag | F55: =ConTime!F$26 -> 0 | G55: =ConTime!G$26 -> 0 | H55: =ConTime!H$26 -> 1 | I55: =ConTime!I$26 -> 0 | J55: =ConTime!J$26 -> 0 | K55: =ConTime!K$26 -> 0 | L55: =ConTime!L$26 -> 0 | ... AZ55: =ConTime!AZ$26 -> 0
...

Sheet T&E
A1: =RIGHT(CELL("filename", A1), LEN(CELL("filename", A1)) - SEARCH("]", CELL("filename", A1))) -> T&E
E2: =E$24 -> Operating period flag | F2: =F$24 -> 0 | G2: =G$24 -> flag | H2: =H$24 -> 60 | I2: =I$24 -> 0 | J2: =J$24 -> 0 | K2: =K$24 -> 0 | L2: =L$24 -> 0 | ... CA2: =CA$24 -> 0
E3: ='T&E'!E$8 -> Model column counter | F3: ='T&E'!F$8 -> 0 | G3: ='T&E'!G$8 -> 0 | H3: ='T&E'!H$8 -> 0 | I3: ='T&E'!I$8 -> 0 | J3: ='T&E'!J$8 -> 1 | K3: ='T&E'!K$8 -> 2 | L3: ='T&E'!L$8 -> 3 | ... CA3: ='T&E'!CA$8 -> 70
E4: =E$12 -> Model period ending | F4: =F$12 -> constant | G4: =G$12 -> unit | H4: =H$12 -> total | I4: =I$12 -> 0 | J4: =J$12 -> 41639 | K4: =K$12 -> 41820 | L4: =L$12 -> 42004 | ... CA4: =CA$12 -> 54239
A6: TIME RULER
E8: Model column counter | J8: =I8 + 1 -> 1 | K8: =J8 + 1 -> 2 | L8: =K8 + 1 -> 3 | M8: =L8 + 1 -> 4 | N8: =M8 + 1 -> 5 | O8: =N8 + 1 -> 6 | P8: =O8 + 1 -> 7 | Q8: =P8 + 1 -> 8 | ... CA8: =BZ8 + 1 -> 70
E10: =InpC!E$8 -> First date of time ruler | F10: =InpC!F$8 -> 41639 | G10: =InpC!G$8 -> date
E11: =E$8 -> Model column counter | F11: =F$8 -> 0 | G11: integer | H11: =H$8 -> 0 | I11: =I$8 -> 0 | J11: =J$8 -> 1 | K11: =K$8 -> 2 | L11: =L$8 -> 3 | M11: =M$8 -> 4 | N11: =N$8 -> 5 | O11: =O$8 -> 6 | ... CA11: =CA$8 -> 70
E12: Model period ending | F12: constant | G12: unit | H12: total | J12: =IF( J11 = 1, $F10,EOMONTH( I12, 6 ) ) -> 41639 | K12: =IF( K11 = 1, $F10,EOMONTH( J12, 6 ) ) -> 41820 | L12: =IF( L11 = 1, $F10,EOMONTH( K12, 6 ) ) -> 42004 | M12: =IF( M11 = 1, $F10,EOMONTH( L12, 6 ) ) -> 42185 | N12: =IF( N11 = 1, $F10,EOMONTH( M12, 6 ) ) -> 42369 | O12: =IF( O11 = 1, $F10,EOMONTH( N12, 6 ) ) -> 42551 | P12: =IF( P11 = 1, $F10,EOMONTH( O12, 6 ) ) -> 42735 | Q12: =IF( Q11 = 1, $F10,EOMONTH( P12, 6 ) ) -> 42916 | ... CA12: =IF( CA11 = 1, $F10,EOMONTH( BZ12, 6 ) ) -> 54239
A15: FLAGS
E17: =InpC!E$12 -> Construction period end / conversion date | F17: =InpC!F$12 -> 42369 | G17: =InpC!G$12 -> date
E18: =E$12 -> Model period ending | F18: =F$12 -> constant | G18: =G$12 -> unit | H18: =H$12 -> total | I18: =I$12 -> 0 | J18: =J$12 -> 41639 | K18: =K$12 -> 41820 | L18: =L$12 -> 42004 | ... CA18: =CA$12 -> 54239
E19: Initial operations date flag | G19: flag | H19: =SUM(J19:CA19) -> 1 | J19: =IF(J18 = $F17, 1, 0) -> 0 | K19: =IF(K18 = $F17, 1, 0) -> 0 | L19: =IF(L18 = $F17, 1, 0) -> 0 | M19: =IF(M18 = $F17, 1, 0) -> 0 | N19: =IF(N18 = $F17, 1, 0) -> 1 | O19: =IF(O18 = $F17, 1, 0) -> 0 | P19: =IF(P18 = $F17, 1, 0) -> 0 | Q19: =IF(Q18 = $F17, 1, 0) -> 0 | ... CA19: =IF(CA18 = $F17, 1, 0) -> 0
E21: =InpC!E$12 -> Construction period end / conversion date | F21: =InpC!F$12 -> 42369 | G21: =InpC!G$12 -> date
E22: =InpC!E$15 -> Last forecast date | F22: =InpC!F$15 -> 53327 | G22: =InpC!G$15 -> date
E23: =E$12 -> Model period ending | F23: =F$12 -> constant | G23: =G$12 -> unit | H23: =H$12 -> total | I23: =I$12 -> 0 | J23: =J$12 -> 41639 | K23: =K$12 -> 41820 | L23: =L$12 -> 42004 | ... CA23: =CA$12 -> 54239
E24: Operating period flag | G24: flag | H24: =SUM(J24:CA24) -> 60 | J24: =IF( AND(J23 > $F21, J23 <= $F22), 1, 0) -> 0 | K24: =IF( AND(K23 > $F21, K23 <= $F22), 1, 0) -> 0 | L24: =IF( AND(L23 > $F21, L23 <= $F22), 1, 0) -> 0 | M24: =IF( AND(M23 > $F21, M23 <= $F22), 1, 0) -> 0 | N24: =IF( AND(N23 > $F21, N23 <= $F22), 1, 0) -> 0 | O24: =IF( AND(O23 > $F21, O23 <= $F22), 1, 0) -> 1 | P24: =IF( AND(P23 > $F21, P23 <= $F22), 1, 0) -> 1 | Q24: =IF( AND(Q23 > $F21, Q23 <= $F22), 1, 0) -> 1 | ... CA24: =IF( AND(CA23 > $F21, CA23 <= $F22), 1, 0) -> 0
E26: =InpC!E$12 -> Construction period end / conversion date | F26: =InpC!F$12 -> 42369 | G26: =InpC!G$12 -> date
E27: [Last senior debt repayment date] | F27: 49674 | G27: date
E28: =E$12 -> Model period ending | F28: =F$12 -> constant | G28: =G$12 -> unit | H28: =H$12 -> total | I28: =I$12 -> 0 | J28: =J$12 -> 41639 | K28: =K$12 -> 41820 | L28: =L$12 -> 42004 | ... CA28: =CA$12 -> 54239
E29: Senior debt term / ratio calc date flag | G29: flag | H29: =SUM(J29:CA29) -> 40 | J29: =IF( AND(J28 > $F26, J28 <= $F27), 1, 0) -> 0 | K29: =IF( AND(K28 > $F26, K28 <= $F27), 1, 0) -> 0 | L29: =IF( AND(L28 > $F26, L28 <= $F27), 1, 0) -> 0 | M29: =IF( AND(M28 > $F26, M28 <= $F27), 1, 0) -> 0 | N29: =IF( AND(N28 > $F26, N28 <= $F27), 1, 0) -> 0 | O29: =IF( AND(O28 > $F26, O28 <= $F27), 1, 0) -> 1 | P29: =IF( AND(P28 > $F26, P28 <= $F27), 1, 0) -> 1 | Q29: =IF( AND(Q28 > $F26, Q28 <= $F27), 1, 0) -> 1 | ... CA29: =IF( AND(CA28 > $F26, CA28 <= $F27), 1, 0) -> 0
E31: =InpC!E$12 -> Construction period end / conversion date | F31: =InpC!F$12 -> 42369 | G31: =InpC!G$12 -> date
E32: =InpC!E$45 -> Last date of accounting depreciation | F32: =InpC!F$45 -> 51501 | G32: =InpC!G$45 -> date
E33: =E$12 -> Model period ending | F33: =F$12 -> constant | G33: =G$12 -> unit | H33: =H$12 -> total | I33: =I$12 -> 0 | J33: =J$12 -> 41639 | K33: =K$12 -> 41820 | L33: =L$12 -> 42004 | ... CA33: =CA$12 -> 54239
E34: Accounting useful life period flag | G34: flag | H34: =SUM(J34:CA34) -> 50 | J34: =IF( AND(J33 > $F31, J33 <= $F32), 1, 0) -> 0 | K34: =IF( AND(K33 > $F31, K33 <= $F32), 1, 0) -> 0 | L34: =IF( AND(L33 > $F31, L33 <= $F32), 1, 0) -> 0 | M34: =IF( AND(M33 > $F31, M33 <= $F32), 1, 0) -> 0 | N34: =IF( AND(N33 > $F31, N33 <= $F32), 1, 0) -> 0 | O34: =IF( AND(O33 > $F31, O33 <= $F32), 1, 0) -> 1 | P34: =IF( AND(P33 > $F31, P33 <= $F32), 1, 0) -> 1 | Q34: =IF( AND(Q33 > $F31, Q33 <= $F32), 1, 0) -> 1 | ... CA34: =IF( AND(CA33 > $F31, CA33 <= $F32), 1, 0) -> 0
E36: =InpC!E$15 -> Last forecast date | F36: =InpC!F$15 -> 53327 | G36: =InpC!G$15 -> date
E37: =E$12 -> Model period ending | F37: =F$12 -> constant | G37: =G$12 -> unit | H37: =H$12 -> total | I37: =I$12 -> 0 | J37: =J$12 -> 41639 | K37: =K$12 -> 41820 | L37: =L$12 -> 42004 | ... CA37: =CA$12 -> 54239
E38: Last forecast period flag | G38: flag | H38: =SUM(J38:CA38) -> 1 | J38: =IF(J37 = $F36, 1, 0) -> 0 | K38: =IF(K37 = $F36, 1, 0) -> 0 | L38: =IF(L37 = $F36, 1, 0) -> 0 | M38: =IF(M37 = $F36, 1, 0) -> 0 | N38: =IF(N37 = $F36, 1, 0) -> 0 | O38: =IF(O37 = $F36, 1, 0) -> 0 | P38: =IF(P37 = $F36, 1, 0) -> 0 | Q38: =IF(Q37 = $F36, 1, 0) -> 0 | ... CA38: =IF(CA37 = $F36, 1, 0) -> 0
A41: CPI ESCALATION FACTOR
E43: =InpC!E$17 -> Annual CPI inflation rate | F43: =InpC!F$17 -> 0.025 | G43: =InpC!G$17 -> p.a.
E44: Period CPI inflation rate | F44: =(1 + F43) ^ (1/2) - 1 -> 0.012422837 | G44: per period
E46: =E$44 -> Period CPI inflation rate | F46: =F$44 -> 0.012422837 | G46: =G$44 -> per period
E47: =InpC!E$18 -> Price and cost basis date - period ending | F47: =InpC!F$18 -> 41820 | G47: =InpC!G$18 -> date
E48: =E$12 -> Model period ending | F48: =F$12 -> constant | G48: =G$12 -> unit | H48: =H$12 -> total | I48: =I$12 -> 0 | J48: =J$12 -> 41639 | K48: =K$12 -> 41820 | L48: =L$12 -> 42004 | ... CA48: =CA$12 -> 54239
E49: CPI esc factor | G49: factor | J49: =IF(J48 = $F47, 1, I49 * (1 + $F46)) -> 0 | K49: =IF(K48 = $F47, 1, J49 * (1 + $F46)) -> 1 | L49: =IF(L48 = $F47, 1, K49 * (1 + $F46)) -> 1.0124228 | M49: =IF(M48 = $F47, 1, L49 * (1 + $F46)) -> 1.025 | N49: =IF(N48 = $F47, 1, M49 * (1 + $F46)) -> 1.0377334 | O49: =IF(O48 = $F47, 1, N49 * (1 + $F46)) -> 1.050625 | P49: =IF(P48 = $F47, 1, O49 * (1 + $F46)) -> 1.0636767 | Q49: =IF(Q48 = $F47, 1, P49 * (1 + $F46)) -> 1.0768906 | ... CA49: =IF(CA48 = $F47, 1, BZ49 * (1 + $F46)) -> 2.3153221

Sheet Rev
A1: =RIGHT(CELL("filename", A1), LEN(CELL("filename", A1)) - SEARCH("]", CELL("filename", A1))) -> Rev
E2: ='T&E'!E$24 -> Operating period flag | F2: ='T&E'!F$24 -> 0 | G2: ='T&E'!G$24 -> flag | H2: ='T&E'!H$24 -> 60 | I2: ='T&E'!I$24 -> 0 | J2: ='T&E'!J$24 -> 0 | K2: ='T&E'!K$24 -> 0 | L2: ='T&E'!L$24 -> 0 | ... CA2: ='T&E'!CA$24 -> 0
E3: ='T&E'!E$8 -> Model column counter | F3: ='T&E'!F$8 -> 0 | G3: ='T&E'!G$8 -> 0 | H3: ='T&E'!H$8 -> 0 | I3: ='T&E'!I$8 -> 0 | J3: ='T&E'!J$8 -> 1 | K3: ='T&E'!K$8 -> 2 | L3: ='T&E'!L$8 -> 3 | ... CA3: ='T&E'!CA$8 -> 70
E4: ='T&E'!E$12 -> Model period ending | F4: ='T&E'!F$12 -> constant | G4: ='T&E'!G$12 -> unit | H4: ='T&E'!H$12 -> total | I4: ='T&E'!I$12 -> 0 | J4: ='T&E'!J$12 -> 41639 | K4: ='T&E'!K$12 -> 41820 | L4: ='T&E'!L$12 -> 42004 | ... CA4: ='T&E'!CA$12 -> 54239
A6: PASSENGER LANDING TAX
C8: Landings
E10: =InpS!E$8 -> Routes - domestic charter | F10: =InpS!F$8 -> 0 | G10: =InpS!G$8 -> planes | H10: =InpS!H$8 -> 0 | I10: =InpS!I$8 -> 0 | J10: =InpS!J$8 -> 0 | K10: =InpS!K$8 -> 0 | L10: =InpS!L$8 -> 15 | ... CA10: =InpS!CA$8 -> 0
E11: =InpS!E$13 -> Landing frequency - domestic charter | F11: =InpS!F$13 -> 0 | G11: =InpS!G$13 -> lands / plane | H11: =InpS!H$13 -> 0 | I11: =InpS!I$13 -> 0 | J11: =InpS!J$13 -> 0 | K11: =InpS!K$13 -> 0 | L11: =InpS!L$13 -> 120 | ... CA11: =InpS!CA$13 -> 0
E12: ='T&E'!E$24 -> Operating period flag | F12: ='T&E'!F$24 -> 0 | G12: ='T&E'!G$24 -> flag | H12: ='T&E'!H$24 -> 60 | I12: ='T&E'!I$24 -> 0 | J12: ='T&E'!J$24 -> 0 | K12: ='T&E'!K$24 -> 0 | L12: ='T&E'!L$24 -> 0 | ... CA12: ='T&E'!CA$24 -> 0
E13: Landings - domestic charter | G13: landings | H13: =SUM(J13:CA13) -> 47210 | J13: =J10 * J11 * J12 -> 0 | K13: =K10 * K11 * K12 -> 0 | L13: =L10 * L11 * L12 -> 0 | M13: =M10 * M11 * M12 -> 0 | N13: =N10 * N11 * N12 -> 0 | O13: =O10 * O11 * O12 -> 1430 | P13: =P10 * P11 * P12 -> 1430 | Q13: =Q10 * Q11 * Q12 -> 1430 | ... CA13: =CA10 * CA11 * CA12 -> 0
E15: =InpS!E$9 -> Routes - domestic scheduled | F15: =InpS!F$9 -> 0 | G15: =InpS!G$9 -> planes | H15: =InpS!H$9 -> 0 | I15: =InpS!I$9 -> 0 | J15: =InpS!J$9 -> 0 | K15: =InpS!K$9 -> 0 | L15: =InpS!L$9 -> 28 | ... CA15: =InpS!CA$9 -> 0
E16: =InpS!E$14 -> Landing frequency - domestic scheduled | F16: =InpS!F$14 -> 0 | G16: =InpS!G$14 -> lands / plane | H16: =InpS!H$14 -> 0 | I16: =InpS!I$14 -> 0 | J16: =InpS!J$14 -> 0 | K16: =InpS!K$14 -> 0 | L16: =InpS!L$14 -> 250 | ... CA16: =InpS!CA$14 -> 0 | CB16: 270 | CC16: 168 | CD16: 84 | CE16: 168
E17: ='T&E'!E$24 -> Operating period flag | F17: ='T&E'!F$24 -> 0 | G17: ='T&E'!G$24 -> flag | H17: ='T&E'!H$24 -> 60 | I17: ='T&E'!I$24 -> 0 | J17: ='T&E'!J$24 -> 0 | K17: ='T&E'!K$24 -> 0 | L17: ='T&E'!L$24 -> 0 | ... CA17: ='T&E'!CA$24 -> 0
E18: Landings - domestic scheduled | G18: landings | H18: =SUM(J18:CA18) -> 315560 | J18: =J15 * J16 * J17 -> 0 | K18: =K15 * K16 * K17 -> 0 | L18: =L15 * L16 * L17 -> 0 | M18: =M15 * M16 * M17 -> 0 | N18: =N15 * N16 * N17 -> 0 | O18: =O15 * O16 * O17 -> 6480 | P18: =P15 * P16 * P17 -> 6000 | Q18: =Q15 * Q16 * Q17 -> 6480 | ... CA18: =CA15 * CA16 * CA17 -> 0
E20: =InpS!E$10 -> Routes - international charter | F20: =InpS!F$10 -> 0 | G20: =InpS!G$10 -> planes | H20: =InpS!H$10 -> 0 | I20: =InpS!I$10 -> 0 | J20: =InpS!J$10 -> 0 | K20: =InpS!K$10 -> 0 | L20: =InpS!L$10 -> 30 | ... CA20: =InpS!CA$10 -> 0
E21: =InpS!E$15 -> Landing frequency - international charter | F21: =InpS!F$15 -> 0 | G21: =InpS!G$15 -> lands / plane | H21: =InpS!H$15 -> 0 | I21: =InpS!I$15 -> 0 | J21: =InpS!J$15 -> 0 | K21: =InpS!K$15 -> 0 | L21: =InpS!L$15 -> 40 | ... CA21: =InpS!CA$15 -> 0
E22: ='T&E'!E$24 -> Operating period flag | F22: ='T&E'!F$24 -> 0 | G22: ='T&E'!G$24 -> flag | H22: ='T&E'!H$24 -> 60 | I22: ='T&E'!I$24 -> 0 | J22: ='T&E'!J$24 -> 0 | K22: ='T&E'!K$24 -> 0 | L22: ='T&E'!L$24 -> 0 | ... CA22: ='T&E'!CA$24 -> 0
E23: Landings - international charter | G23: landings | H23: =SUM(J23:CA23) -> 122250 | J23: =J20 * J21 * J22 -> 0 | K23: =K20 * K21 * K22 -> 0 | L23: =L20 * L21 * L22 -> 0 | M23: =M20 * M21 * M22 -> 0 | N23: =N20 * N21 * N22 -> 0 | O23: =O20 * O21 * O22 -> 1350 | P23: =P20 * P21 * P22 -> 1500 | Q23: =Q20 * Q21 * Q22 -> 1500 | ... CA23: =CA20 * CA21 * CA22 -> 0
E25: =InpS!E$11 -> Routes - international scheduled | F25: =InpS!F$11 -> 0 | G25: =InpS!G$11 -> planes | H25: =InpS!H$11 -> 0 | I25: =InpS!I$11 -> 0 | J25: =InpS!J$11 -> 0 | K25: =InpS!K$11 -> 0 | L25: =InpS!L$11 -> 12 | ... CA25: =InpS!CA$11 -> 0
E26: =InpS!E$16 -> Landing frequency - international scheduled | F26: =InpS!F$16 -> 0 | G26: =InpS!G$16 -> lands / plane | H26: =InpS!H$16 -> 0 | I26: =InpS!I$16 -> 0 | J26: =InpS!J$16 -> 0 | K26: =InpS!K$16 -> 0 | L26: =InpS!L$16 -> 35 | ... CA26: =InpS!CA$16 -> 0
E27: ='T&E'!E$24 -> Operating period flag | F27: ='T&E'!F$24 -> 0 | G27: ='T&E'!G$24 -> flag | H27: ='T&E'!H$24 -> 60 | I27: ='T&E'!I$24 -> 0 | J27: ='T&E'!J$24 -> 0 | K27: ='T&E'!K$24 -> 0 | L27: ='T&E'!L$24 -> 0 | ... CA27: ='T&E'!CA$24 -> 0
E28: Landings - international scheduled | G28: landings | H28: =SUM(J28:CA28) -> 52230 | J28: =J25 * J26 * J27 -> 0 | K28: =K25 * K26 * K27 -> 0 | L28: =L25 * L26 * L27 -> 0 | M28: =M25 * M26 * M27 -> 0 | N28: =N25 * N26 * N27 -> 0 | O28: =O25 * O26 * O27 -> 630 | P28: =P25 * P26 * P27 -> 720 | Q28: =Q25 * Q26 * Q27 -> 720 | ... CA28: =CA25 * CA26 * CA27 -> 0
E31: =E$13 -> Landings - domestic charter | F31: =F$13 -> 0 | G31: =G$13 -> landings | H31: =H$13 -> 47210 | I31: =I$13 -> 0 | J31: =J$13 -> 0 | K31: =K$13 -> 0 | L31: =L$13 -> 0 | ... CA31: =CA$13 -> 0
E32: =E$18 -> Landings - domestic scheduled | F32: =F$18 -> 0 | G32: =G$18 -> landings | H32: =H$18 -> 315560 | I32: =I$18 -> 0 | J32: =J$18 -> 0 | K32: =K$18 -> 0 | L32: =L$18 -> 0 | ... CA32: =CA$18 -> 0
E33: =E$23 -> Landings - international charter | F33: =F$23 -> 0 | G33: =G$23 -> landings | H33: =H$23 -> 122250 | I33: =I$23 -> 0 | J33: =J$23 -> 0 | K33: =K$23 -> 0 | L33: =L$23 -> 0 | ... CA33: =CA$23 -> 0
E34: =E$28 -> Landings - international scheduled | F34: =F$28 -> 0 | G34: =G$28 -> landings | H34: =H$28 -> 52230 | I34: =I$28 -> 0 | J34: =J$28 -> 0 | K34: =K$28 -> 0 | L34: =L$28 -> 0 | ... CA34: =CA$28 -> 0
E35: Total landings | G35: landings | H35: =SUM(J35:CA35) -> 537250 | J35: =SUM(J31:J34) -> 0 | K35: =SUM(K31:K34) -> 0 | L35: =SUM(L31:L34) -> 0 | M35: =SUM(M31:M34) -> 0 | N35: =SUM(N31:N34) -> 0 | O35: =SUM(O31:O34) -> 9890 | P35: =SUM(P31:P34) -> 9650 | Q35: =SUM(Q31:Q34) -> 10130 | ... CA35: =SUM(CA31:CA34) -> 0
C38: Passengers per landing
E40: =InpC!E$23 -> Aircraft capacity - domestic charter | F40: =InpC!F$23 -> 110 | G40: =InpC!G$23 -> seats
E41: =InpS!E$18 -> Load factor - domestic charter | F41: =InpS!F$18 -> 0 | G41: =InpS!G$18 -> % | H41: =InpS!H$18 -> 0 | I41: =InpS!I$18 -> 0 | J41: =InpS!J$18 -> 0 | K41: =InpS!K$18 -> 0 | L41: =InpS!L$18 -> 0.6 | ... CA41: =InpS!CA$18 -> 0
E42: ='T&E'!E$24 -> Operating period flag | F42: ='T&E'!F$24 -> 0 | G42: ='T&E'!G$24 -> flag | H42: ='T&E'!H$24 -> 60 | I42: ='T&E'!I$24 -> 0 | J42: ='T&E'!J$24 -> 0 | K42: ='T&E'!K$24 -> 0 | L42: ='T&E'!L$24 -> 0 | ... CA42: ='T&E'!CA$24 -> 0
E43: PAx per landing - domestic charter | G43: PAx / land | J43: =$F40 * J41 * J42 -> 0 | K43: =$F40 * K41 * K42 -> 0 | L43: =$F40 * L41 * L42 -> 0 | M43: =$F40 * M41 * M42 -> 0 | N43: =$F40 * N41 * N42 -> 0 | O43: =$F40 * O41 * O42 -> 77 | P43: =$F40 * P41 * P42 -> 77 | Q43: =$F40 * Q41 * Q42 -> 77 | ... CA43: =$F40 * CA41 * CA42 -> 0
E45: =InpC!E$24 -> Aircraft capacity - domestic scheduled | F45: =InpC!F$24 -> 140 | G45: =InpC!G$24 -> seats
E46: =InpS!E$19 -> Load factor - domestic scheduled | F46: =InpS!F$19 -> 0 | G46: =InpS!G$19 -> % | H46: =InpS!H$19 -> 0 | I46: =InpS!I$19 -> 0 | J46: =InpS!J$19 -> 0 | K46: =InpS!K$19 -> 0 | L46: =InpS!L$19 -> 0.7 | ... CA46: =InpS!CA$19 -> 0
E47: ='T&E'!E$24 -> Operating period flag | F47: ='T&E'!F$24 -> 0 | G47: ='T&E'!G$24 -> flag | H47: ='T&E'!H$24 -> 60 | I47: ='T&E'!I$24 -> 0 | J47: ='T&E'!J$24 -> 0 | K47: ='T&E'!K$24 -> 0 | L47: ='T&E'!L$24 -> 0 | ... CA47: ='T&E'!CA$24 -> 0
E48: PAx per landing - domestic scheduled | G48: PAx / land | J48: =$F45 * J46 * J47 -> 0 | K48: =$F45 * K46 * K47 -> 0 | L48: =$F45 * L46 * L47 -> 0 | M48: =$F45 * M46 * M47 -> 0 | N48: =$F45 * N46 * N47 -> 0 | O48: =$F45 * O46 * O47 -> 98 | P48: =$F45 * P46 * P47 -> 98 | Q48: =$F45 * Q46 * Q47 -> 98 | ... CA48: =$F45 * CA46 * CA47 -> 0
E50: =InpC!E$25 -> Aircraft capacity - international chartered | F50: =InpC!F$25 -> 250 | G50: =InpC!G$25 -> seats
E51: =InpS!E$20 -> Load factor - international charter | F51: =InpS!F$20 -> 0 | G51: =InpS!G$20 -> % | H51: =InpS!H$20 -> 0 | I51: =InpS!I$20 -> 0 | J51: =InpS!J$20 -> 0 | K51: =InpS!K$20 -> 0 | L51: =InpS!L$20 -> 0.65 | ... CA51: =InpS!CA$20 -> 0 | CB51: 0.55 | CC51: 0.5 | CD51: 0.55 | CE51: 0.5 | CF51: 0.55 | CG51: 0.5 | CH51: 0.55 | CI51: 0.5 | CJ51: 0.55 | CK51: 0.5 | CL51: 0.55 | CM51: 0.5 | CN51: 0.55 | CO51: 0.5
E52: ='T&E'!E$24 -> Operating period flag | F52: ='T&E'!F$24 -> 0 | G52: ='T&E'!G$24 -> flag | H52: ='T&E'!H$24 -> 60 | I52: ='T&E'!I$24 -> 0 | J52: ='T&E'!J$24 -> 0 | K52: ='T&E'!K$24 -> 0 | L52: ='T&E'!L$24 -> 0 | ... CA52: ='T&E'!CA$24 -> 0
E53: PAx per landing - international chartered | G53: PAx / land | J53: =$F50 * J51 * J52 -> 0 | K53: =$F50 * K51 * K52 -> 0 | L53: =$F50 * L51 * L52 -> 0 | M53: =$F50 * M51 * M52 -> 0 | N53: =$F50 * N51 * N52 -> 0 | O53: =$F50 * O51 * O52 -> 150 | P53: =$F50 * P51 * P52 -> 162.5 | Q53: =$F50 * Q51 * Q52 -> 150 | ... CA53: =$F50 * CA51 * CA52 -> 0
...

Sheet Opex
A1: =RIGHT(CELL("filename", A1), LEN(CELL("filename", A1)) - SEARCH("]", CELL("filename", A1))) -> Opex
E2: ='T&E'!E$24 -> Operating period flag | F2: ='T&E'!F$24 -> 0 | G2: ='T&E'!G$24 -> flag | H2: ='T&E'!H$24 -> 60 | I2: ='T&E'!I$24 -> 0 | J2: ='T&E'!J$24 -> 0 | K2: ='T&E'!K$24 -> 0 | L2: ='T&E'!L$24 -> 0 | ... CA2: ='T&E'!CA$24 -> 0
E3: ='T&E'!E$8 -> Model column counter | F3: ='T&E'!F$8 -> 0 | G3: ='T&E'!G$8 -> 0 | H3: ='T&E'!H$8 -> 0 | I3: ='T&E'!I$8 -> 0 | J3: ='T&E'!J$8 -> 1 | K3: ='T&E'!K$8 -> 2 | L3: ='T&E'!L$8 -> 3 | ... CA3: ='T&E'!CA$8 -> 70
E4: ='T&E'!E$12 -> Model period ending | F4: ='T&E'!F$12 -> constant | G4: ='T&E'!G$12 -> unit | H4: ='T&E'!H$12 -> total | I4: ='T&E'!I$12 -> 0 | J4: ='T&E'!J$12 -> 41639 | K4: ='T&E'!K$12 -> 41820 | L4: ='T&E'!L$12 -> 42004 | ... CA4: ='T&E'!CA$12 -> 54239
A6: GROUND HANDLING
E8: =InpC!E$33 -> Variable ground handling charge rate | F8: =InpC!F$33 -> 340 | G8: =InpC!G$33 -> € / landing
E9: =Rev!E$35 -> Total landings | F9: =Rev!F$35 -> 0 | G9: =Rev!G$35 -> landings | H9: =Rev!H$35 -> 537250 | I9: =Rev!I$35 -> 0 | J9: =Rev!J$35 -> 0 | K9: =Rev!K$35 -> 0 | L9: =Rev!L$35 -> 0 | ... CA9: =Rev!CA$35 -> 0
E10: ='T&E'!E$49 -> CPI esc factor | F10: ='T&E'!F$49 -> 0 | G10: ='T&E'!G$49 -> factor | H10: ='T&E'!H$49 -> 0 | I10: ='T&E'!I$49 -> 0 | J10: ='T&E'!J$49 -> 0 | K10: ='T&E'!K$49 -> 1 | L10: ='T&E'!L$49 -> 1.0124228 | ... CA10: ='T&E'!CA$49 -> 2.3153221
E11: Variable ground handling costs | G11: =SMU -> € 000s | H11: =SUM(J11:CA11) -> 282201.8 | J11: =$F8 * J9 * J10 / 1000 -> 0 | K11: =$F8 * K9 * K10 / 1000 -> 0 | L11: =$F8 * L9 * L10 / 1000 -> 0 | M11: =$F8 * M9 * M10 / 1000 -> 0 | N11: =$F8 * N9 * N10 / 1000 -> 0 | O11: =$F8 * O9 * O10 / 1000 -> 3532.8316 | P11: =$F8 * P9 * P10 / 1000 -> 3489.9234 | Q11: =$F8 * Q9 * Q10 / 1000 -> 3709.0267 | ... CA11: =$F8 * CA9 * CA10 / 1000 -> 0
E14: =InpC!E$34 -> Fixed ground handling costs | F14: =InpC!F$34 -> 3600 | G14: =InpC!G$34 -> € 000s p.a.
E15: ='T&E'!E$49 -> CPI esc factor | F15: ='T&E'!F$49 -> 0 | G15: ='T&E'!G$49 -> factor | H15: ='T&E'!H$49 -> 0 | I15: ='T&E'!I$49 -> 0 | J15: ='T&E'!J$49 -> 0 | K15: ='T&E'!K$49 -> 1 | L15: ='T&E'!L$49 -> 1.0124228 | ... CA15: ='T&E'!CA$49 -> 2.3153221
E16: ='T&E'!E$24 -> Operating period flag | F16: ='T&E'!F$24 -> 0 | G16: ='T&E'!G$24 -> flag | H16: ='T&E'!H$24 -> 60 | I16: ='T&E'!I$24 -> 0 | J16: ='T&E'!J$24 -> 0 | K16: ='T&E'!K$24 -> 0 | L16: ='T&E'!L$24 -> 0 | ... CA16: ='T&E'!CA$24 -> 0
E17: Fixed ground handling costs | G17: =SMU -> € 000s | H17: =SUM(J17:CA17) -> 167082.41 | J17: =($F14 / 2) * J15 * J16 -> 0 | K17: =($F14 / 2) * K15 * K16 -> 0 | L17: =($F14 / 2) * L15 * L16 -> 0 | M17: =($F14 / 2) * M15 * M16 -> 0 | N17: =($F14 / 2) * N15 * N16 -> 0 | O17: =($F14 / 2) * O15 * O16 -> 1891.125 | P17: =($F14 / 2) * P15 * P16 -> 1914.6181 | Q17: =($F14 / 2) * Q15 * Q16 -> 1938.4031 | ... CA17: =($F14 / 2) * CA15 * CA16 -> 0
A20: O&M CONTRACT
E22: =InpC!E$35 -> Airport terminal O&M contract costs | F22: =InpC!F$35 -> 2400 | G22: =InpC!G$35 -> € 000s p.a.
E23: ='T&E'!E$49 -> CPI esc factor | F23: ='T&E'!F$49 -> 0 | G23: ='T&E'!G$49 -> factor | H23: ='T&E'!H$49 -> 0 | I23: ='T&E'!I$49 -> 0 | J23: ='T&E'!J$49 -> 0 | K23: ='T&E'!K$49 -> 1 | L23: ='T&E'!L$49 -> 1.0124228 | ... CA23: ='T&E'!CA$49 -> 2.3153221
E24: ='T&E'!E$24 -> Operating period flag | F24: ='T&E'!F$24 -> 0 | G24: ='T&E'!G$24 -> flag | H24: ='T&E'!H$24 -> 60 | I24: ='T&E'!I$24 -> 0 | J24: ='T&E'!J$24 -> 0 | K24: ='T&E'!K$24 -> 0 | L24: ='T&E'!L$24 -> 0 | ... CA24: ='T&E'!CA$24 -> 0
E25: O&M contract costs | G25: =SMU -> € 000s | H25: =SUM(J25:CA25) -> 111388.27 | J25: =($F22 / 2) * J23 * J24 -> 0 | K25: =($F22 / 2) * K23 * K24 -> 0 | L25: =($F22 / 2) * L23 * L24 -> 0 | M25: =($F22 / 2) * M23 * M24 -> 0 | N25: =($F22 / 2) * N23 * N24 -> 0 | O25: =($F22 / 2) * O23 * O24 -> 1260.75 | P25: =($F22 / 2) * P23 * P24 -> 1276.4121 | Q25: =($F22 / 2) * Q23 * Q24 -> 1292.2687 | ... CA25: =($F22 / 2) * CA23 * CA24 -> 0
A28: SUMMARY
E30: =E$11 -> Variable ground handling costs | F30: =F$11 -> 0 | G30: =G$11 -> € 000s | H30: =H$11 -> 282201.8 | I30: =I$11 -> 0 | J30: =J$11 -> 0 | K30: =K$11 -> 0 | L30: =L$11 -> 0 | ... CA30: =CA$11 -> 0
E31: =E$17 -> Fixed ground handling costs | F31: =F$17 -> 0 | G31: =G$17 -> € 000s | H31: =H$17 -> 167082.41 | I31: =I$17 -> 0 | J31: =J$17 -> 0 | K31: =K$17 -> 0 | L31: =L$17 -> 0 | ... CA31: =CA$17 -> 0
E32: =E$25 -> O&M contract costs | F32: =F$25 -> 0 | G32: =G$25 -> € 000s | H32: =H$25 -> 111388.27 | I32: =I$25 -> 0 | J32: =J$25 -> 0 | K32: =K$25 -> 0 | L32: =L$25 -> 0 | ... CA32: =CA$25 -> 0
E33: Operating costs POS | G33: =SMU -> € 000s | H33: =SUM(J33:CA33) -> 560672.48 | J33: =SUM(J30:J32) -> 0 | K33: =SUM(K30:K32) -> 0 | L33: =SUM(L30:L32) -> 0 | M33: =SUM(M30:M32) -> 0 | N33: =SUM(N30:N32) -> 0 | O33: =SUM(O30:O32) -> 6684.7066 | P33: =SUM(P30:P32) -> 6680.9536 | Q33: =SUM(Q30:Q32) -> 6939.6986 | ... CA33: =SUM(CA30:CA32) -> 0
E34: =LEFT(E33, LEN(E33) - 4) -> Operating costs | G34: =G33 -> € 000s | H34: =SUM(J34:CA34) -> -560672.48 | J34: =-1 * J33 -> 0 | K34: =-1 * K33 -> 0 | L34: =-1 * L33 -> 0 | M34: =-1 * M33 -> 0 | N34: =-1 * N33 -> 0 | O34: =-1 * O33 -> -6684.7066 | P34: =-1 * P33 -> -6680.9536 | Q34: =-1 * Q33 -> -6939.6986 | ... CA34: =-1 * CA33 -> 0

Sheet FixAsst
A1: =RIGHT(CELL("filename", A1), LEN(CELL("filename", A1)) - SEARCH("]", CELL("filename", A1))) -> FixAsst
E2: ='T&E'!E$24 -> Operating period flag | F2: ='T&E'!F$24 -> 0 | G2: ='T&E'!G$24 -> flag | H2: ='T&E'!H$24 -> 60 | I2: ='T&E'!I$24 -> 0 | J2: ='T&E'!J$24 -> 0 | K2: ='T&E'!K$24 -> 0 | L2: ='T&E'!L$24 -> 0 | ... CA2: ='T&E'!CA$24 -> 0
